Workbook

Sheet Plant
A1: group | B1: entity | C1: plant | D1: period | E1: nameplate_tph | F1: calendar_hours | G1: planned_op_hours | H1: run_hours | I1: unplanned_downtime_hours | J1: ideal_output_t | K1: installed_capacity_t | L1: planned_production_t | M1: gross_output_t | N1: good_output_t | O1: feed_input_t | P1: feed_contained_t | Q1: recovered_contained_t | R1: prod_loss_downtime_t | S1: failures | T1: repair_hours | U1: pm_scheduled | V1: pm_completed | W1: variable_cost_k | X1: fuel_cost_k | Y1: fixed_cost_k | Z1: water_m3 | AA1: emissions_tco2e | AB1: energy_gj | AC1: production_at_risk_t | AD1: critical_plant_alerts | AE1: hours_worked | AF1: recordable_injuries | AG1: severity_incidents | AH1: near_misses | AI1: critical_safety_incidents | AJ1: env_excursions | AK1: env_violations | AL1: ehs_ca_open | AM1: ehs_ca_overdue | AN1: investigations_due | AO1: investigations_completed | AP1: critical_material_risks | AQ1: dispatches_total | AR1: dispatches_delayed | AS1: permit_days_to_expiry | AT1: OPS-001 | AU1: OPS-003 | AV1: PLT-001 | AW1: PLT-002 | AX1: PLT-004 | AY1: PLT-005 | AZ1: REL-001 | BA1: REL-002 | BB1: REL-003 | BC1: REL-004 | BD1: REL-005 | BE1: CST-001 | BF1: CST-002 | BG1: CST-003 | BH1: SUS-001 | BI1: SUS-002 | BJ1: SUS-003 | BK1: SIG-007 | BL1: SIG-008 | BM1: SIG-009 | BN1: SIG-012 | BO1: SIG-021 | BP1: EHS-001 | BQ1: EHS-002 | BR1: EHS-003 | BS1: EHS-004 | BT1: EHS-005 | BU1: EHS-006 | BV1: EHS-007 | BW1: EHS-009 | BX1: REG-006
A2: Group | B2: Entity A1 | C2: Plant 01 | D2: 2026-04 | E2: 137.1 | F2: 720 | G2: 714 | H2: 692.3 | I2: 13.3 | J2: 97889 | K2: 98712 | L2: 88515 | M2: 89648 | N2: 87087 | O2: 95600 | P2: 19579 | Q2: 17553 | R2: 1823 | S2: 2 | T2: 7.1 | U2: 37 | V2: 36 | W2: 251985.8 | X2: 62832 | Y2: 1091.7 | Z2: 167244 | AA2: 61316 | AB2: 311042 | AC2: 3223 | AD2: 1 | AE2: 79000 | AF2: 0 | AG2: 1 | AH2: 10 | AI2: 0 | AJ2: 0 | AK2: 0 | AL2: 14 | AM2: 4 | AN2: 0 | AO2: 0 | AP2: 0 | AQ2: 158 | AR2: 9 | AS2: 311 | AT2: =IFERROR(100*N2/L2,0) | AU2: =IFERROR(100*N2/K2,0) | AV2: =IFERROR(100*H2/F2,0) | AW2: =IFERROR(100*N2/J2,0) | AX2: =IFERROR(100*Q2/P2,0) | AY2: =IFERROR(100*N2/O2,0) | AZ2: =IFERROR(H2/S2,0) | BA2: =IFERROR(T2/S2,0) | BB2: =I2 | BC2: =R2 | BD2: =IFERROR(100*V2/U2,0) | BE2: =IFERROR(1000*(W2+Y2)/N2,0) | BF2: =W2 | BG2: =X2 | BH2: =Z2 | BI2: =AA2 | BJ2: =IFERROR(AB2/N2,0) | BK2: =AC2 | BL2: =AD2 | BM2: =AP2 | BN2: =IFERROR(100*AR2/AQ2,0) | BO2: =AK2 | BP2: =IFERROR(200000*AF2/AE2,0) | BQ2: =AG2 | BR2: =AH2 | BS2: =AI2 | BT2: =AJ2 | BU2: =AL2 | BV2: =AM2 | BW2: =IF(AN2=0,100,100*AO2/AN2) | BX2: =AS2
A3: Group | B3: Entity A1 | C3: Plant 01 | D3: 2026-05 | E3: 137.1 | F3: 744 | G3: 744 | H3: 702.5 | I3: 19.6 | J3: 102002 | K3: 102002 | L3: 88139 | M3: 84940 | N3: 80872 | O3: 86252 | P3: 17739 | Q3: 15002 | R3: 2687 | S3: 3 | T3: 15.5 | U3: 48 | V3: 47 | W3: 272778.7 | X3: 79959.6 | Y3: 1465.4 | Z3: 205726 | AA3: 53724 | AB3: 252523 | AC3: 5217 | AD3: 1 | AE3: 66000 | AF3: 0 | AG3: 0 | AH3: 4 | AI3: 0 | AJ3: 0 | AK3: 0 | AL3: 11 | AM3: 2 | AN3: 3 | AO3: 3 | AP3: 0 | AQ3: 256 | AR3: 10 | AS3: 281 | AT3: =IFERROR(100*N3/L3,0) | AU3: =IFERROR(100*N3/K3,0) | AV3: =IFERROR(100*H3/F3,0) | AW3: =IFERROR(100*N3/J3,0) | AX3: =IFERROR(100*Q3/P3,0) | AY3: =IFERROR(100*N3/O3,0) | AZ3: =IFERROR(H3/S3,0) | BA3: =IFERROR(T3/S3,0) | BB3: =I3 | BC3: =R3 | BD3: =IFERROR(100*V3/U3,0) | BE3: =IFERROR(1000*(W3+Y3)/N3,0) | BF3: =W3 | BG3: =X3 | BH3: =Z3 | BI3: =AA3 | BJ3: =IFERROR(AB3/N3,0) | BK3: =AC3 | BL3: =AD3 | BM3: =AP3 | BN3: =IFERROR(100*AR3/AQ3,0) | BO3: =AK3 | BP3: =IFERROR(200000*AF3/AE3,0) | BQ3: =AG3 | BR3: =AH3 | BS3: =AI3 | BT3: =AJ3 | BU3: =AL3 | BV3: =AM3 | BW3: =IF(AN3=0,100,100*AO3/AN3) | BX3: =AS3
A4: Group | B4: Entity A1 | C4: Plant 01 | D4: 2026-06 | E4: 137.1 | F4: 720 | G4: 720 | H4: 681.5 | I4: 18.6 | J4: 98712 | K4: 98712 | L4: 88801 | M4: 84328 | N4: 81129 | O4: 86263 | P4: 18895 | Q4: 16380 | R4: 2550 | S4: 2 | T4: 14.7 | U4: 48 | V4: 45 | W4: 269800.1 | X4: 63241.6 | Y4: 1103.4 | Z4: 166424 | AA4: 60010 | AB4: 243788 | AC4: 7297 | AD4: 2 | AE4: 91000 | AF4: 1 | AG4: 0 | AH4: 10 | AI4: 0 | AJ4: 1 | AK4: 0 | AL4: 5 | AM4: 1 | AN4: 0 | AO4: 0 | AP4: 0 | AQ4: 148 | AR4: 11 | AS4: 251 | AT4: =IFERROR(100*N4/L4,0) | AU4: =IFERROR(100*N4/K4,0) | AV4: =IFERROR(100*H4/F4,0) | AW4: =IFERROR(100*N4/J4,0) | AX4: =IFERROR(100*Q4/P4,0) | AY4: =IFERROR(100*N4/O4,0) | AZ4: =IFERROR(H4/S4,0) | BA4: =IFERROR(T4/S4,0) | BB4: =I4 | BC4: =R4 | BD4: =IFERROR(100*V4/U4,0) | BE4: =IFERROR(1000*(W4+Y4)/N4,0) | BF4: =W4 | BG4: =X4 | BH4: =Z4 | BI4: =AA4 | BJ4: =IFERROR(AB4/N4,0) | BK4: =AC4 | BL4: =AD4 | BM4: =AP4 | BN4: =IFERROR(100*AR4/AQ4,0) | BO4: =AK4 | BP4: =IFERROR(200000*AF4/AE4,0) | BQ4: =AG4 | BR4: =AH4 | BS4: =AI4 | BT4: =AJ4 | BU4: =AL4 | BV4: =AM4 | BW4: =IF(AN4=0,100,100*AO4/AN4) | BX4: =AS4
A5: Group | B5: Entity A1 | C5: Plant 01 | D5: 2026-07 | E5: 137.1 | F5: 744 | G5: 741 | H5: 701.6 | I5: 27.2 | J5: 101591 | K5: 102002 | L5: 88152 | M5: 86711 | N5: 83254 | O5: 94209 | P5: 21264 | Q5: 19441 | R5: 3729 | S5: 4 | T5: 21.3 | U5: 55 | V5: 52 | W5: 221284.2 | X5: 64810.6 | Y5: 1144.9 | Z5: 180484 | AA5: 54600 | AB5: 243753 | AC5: 5312 | AD5: 0 | AE5: 76000 | AF5: 1 | AG5: 0 | AH5: 9 | AI5: 0 | AJ5: 1 | AK5: 0 | AL5: 4 | AM5: 1 | AN5: 3 | AO5: 3 | AP5: 1 | AQ5: 198 | AR5: 9 | AS5: 221 | AT5: =IFERROR(100*N5/L5,0) | AU5: =IFERROR(100*N5/K5,0) | AV5: =IFERROR(100*H5/F5,0) | AW5: =IFERROR(100*N5/J5,0) | AX5: =IFERROR(100*Q5/P5,0) | AY5: =IFERROR(100*N5/O5,0) | AZ5: =IFERROR(H5/S5,0) | BA5: =IFERROR(T5/S5,0) | BB5: =I5 | BC5: =R5 | BD5: =IFERROR(100*V5/U5,0) | BE5: =IFERROR(1000*(W5+Y5)/N5,0) | BF5: =W5 | BG5: =X5 | BH5: =Z5 | BI5: =AA5 | BJ5: =IFERROR(AB5/N5,0) | BK5: =AC5 | BL5: =AD5 | BM5: =AP5 | BN5: =IFERROR(100*AR5/AQ5,0) | BO5: =AK5 | BP5: =IFERROR(200000*AF5/AE5,0) | BQ5: =AG5 | BR5: =AH5 | BS5: =AI5 | BT5: =AJ5 | BU5: =AL5 | BV5: =AM5 | BW5: =IF(AN5=0,100,100*AO5/AN5) | BX5: =AS5
A6: Group | B6: Entity A1 | C6: Plant 01 | D6: 2026-08 | E6: 137.1 | F6: 744 | G6: 744 | H6: 710.7 | I6: 19.1 | J6: 102002 | K6: 102002 | L6: 91424 | M6: 90032 | N6: 87527 | O6: 94670 | P6: 19426 | Q6: 17234 | R6: 2619 | S6: 2 | T6: 14 | U6: 32 | V6: 31 | W6: 268254.7 | X6: 78893.9 | Y6: 1065.3 | Z6: 192091 | AA6: 54889 | AB6: 306311 | AC6: 1480 | AD6: 2 | AE6: 56000 | AF6: 1 | AG6: 0 | AH6: 6 | AI6: 0 | AJ6: 0 | AK6: 0 | AL6: 5 | AM6: 0 | AN6: 1 | AO6: 1 | AP6: 2 | AQ6: 121 | AR6: 10 | AS6: 191 | AT6: =IFERROR(100*N6/L6,0) | AU6: =IFERROR(100*N6/K6,0) | AV6: =IFERROR(100*H6/F6,0) | AW6: =IFERROR(100*N6/J6,0) | AX6: =IFERROR(100*Q6/P6,0) | AY6: =IFERROR(100*N6/O6,0) | AZ6: =IFERROR(H6/S6,0) | BA6: =IFERROR(T6/S6,0) | BB6: =I6 | BC6: =R6 | BD6: =IFERROR(100*V6/U6,0) | BE6: =IFERROR(1000*(W6+Y6)/N6,0) | BF6: =W6 | BG6: =X6 | BH6: =Z6 | BI6: =AA6 | BJ6: =IFERROR(AB6/N6,0) | BK6: =AC6 | BL6: =AD6 | BM6: =AP6 | BN6: =IFERROR(100*AR6/AQ6,0) | BO6: =AK6 | BP6: =IFERROR(200000*AF6/AE6,0) | BQ6: =AG6 | BR6: =AH6 | BS6: =AI6 | BT6: =AJ6 | BU6: =AL6 | BV6: =AM6 | BW6: =IF(AN6=0,100,100*AO6/AN6) | BX6: =AS6
A7: Group | B7: Entity A1 | C7: Plant 01 | D7: 2026-09 | E7: 137.1 | F7: 720 | G7: 711 | H7: 664.5 | I7: 30.2 | J7: 97478 | K7: 98712 | L7: 85234 | M7: 84182 | N7: 81854 | O7: 89479 | P7: 19996 | Q7: 18334 | R7: 4140 | S7: 4 | T7: 21.6 | U7: 46 | V7: 43 | W7: 226098.2 | X7: 50616 | Y7: 1375.5 | Z7: 148807 | AA7: 59115 | AB7: 289576 | AC7: 3669 | AD7: 0 | AE7: 55000 | AF7: 0 | AG7: 1 | AH7: 9 | AI7: 0 | AJ7: 0 | AK7: 0 | AL7: 14 | AM7: 4 | AN7: 2 | AO7: 2 | AP7: 2 | AQ7: 120 | AR7: 9 | AS7: 161 | AT7: =IFERROR(100*N7/L7,0) | AU7: =IFERROR(100*N7/K7,0) | AV7: =IFERROR(100*H7/F7,0) | AW7: =IFERROR(100*N7/J7,0) | AX7: =IFERROR(100*Q7/P7,0) | AY7: =IFERROR(100*N7/O7,0) | AZ7: =IFERROR(H7/S7,0) | BA7: =IFERROR(T7/S7,0) | BB7: =I7 | BC7: =R7 | BD7: =IFERROR(100*V7/U7,0) | BE7: =IFERROR(1000*(W7+Y7)/N7,0) | BF7: =W7 | BG7: =X7 | BH7: =Z7 | BI7: =AA7 | BJ7: =IFERROR(AB7/N7,0) | BK7: =AC7 | BL7: =AD7 | BM7: =AP7 | BN7: =IFERROR(100*AR7/AQ7,0) | BO7: =AK7 | BP7: =IFERROR(200000*AF7/AE7,0) | BQ7: =AG7 | BR7: =AH7 | BS7: =AI7 | BT7: =AJ7 | BU7: =AL7 | BV7: =AM7 | BW7: =IF(AN7=0,100,100*AO7/AN7) | BX7: =AS7
A8: Group | B8: Entity A1 | C8: Plant 02 | D8: 2026-04 | E8: 188.9 | F8: 720 | G8: 718 | H8: 675.1 | I8: 31 | J8: 135630 | K8: 136008 | L8: 117160 | M8: 101595 | N8: 98478 | O8: 110890 | P8: 24227 | Q8: 19946 | R8: 5856 | S8: 5 | T8: 28.6 | U8: 40 | V8: 34 | W8: 293950 | X8: 67780.4 | Y8: 1112.1 | Z8: 202909 | AA8: 69227 | AB8: 349419 | AC8: 17173 | AD8: 2 | AE8: 61000 | AF8: 0 | AG8: 0 | AH8: 6 | AI8: 0 | AJ8: 0 | AK8: 0 | AL8: 6 | AM8: 2 | AN8: 3 | AO8: 3 | AP8: 1 | AQ8: 187 | AR8: 11 | AS8: 215 | AT8: =IFERROR(100*N8/L8,0) | AU8: =IFERROR(100*N8/K8,0) | AV8: =IFERROR(100*H8/F8,0) | AW8: =IFERROR(100*N8/J8,0) | AX8: =IFERROR(100*Q8/P8,0) | AY8: =IFERROR(100*N8/O8,0) | AZ8: =IFERROR(H8/S8,0) | BA8: =IFERROR(T8/S8,0) | BB8: =I8 | BC8: =R8 | BD8: =IFERROR(100*V8/U8,0) | BE8: =IFERROR(1000*(W8+Y8)/N8,0) | BF8: =W8 | BG8: =X8 | BH8: =Z8 | BI8: =AA8 | BJ8: =IFERROR(AB8/N8,0) | BK8: =AC8 | BL8: =AD8 | BM8: =AP8 | BN8: =IFERROR(100*AR8/AQ8,0) | BO8: =AK8 | BP8: =IFERROR(200000*AF8/AE8,0) | BQ8: =AG8 | BR8: =AH8 | BS8: =AI8 | BT8: =AJ8 | BU8: =AL8 | BV8: =AM8 | BW8: =IF(AN8=0,100,100*AO8/AN8) | BX8: =AS8
A9: Group | B9: Entity A1 | C9: Plant 02 | D9: 2026-05 | E9: 188.9 | F9: 744 | G9: 690 | H9: 630.7 | I9: 45.8 | J9: 130341 | K9: 140542 | L9: 118660 | M9: 98372 | N9: 96839 | O9: 102676 | P9: 19541 | Q9: 16926 | R9: 8652 | S9: 5 | T9: 40.5 | U9: 44 | V9: 33 | W9: 350205.1 | X9: 97181.8 | Y9: 1212.1 | Z9: 176546 | AA9: 62330 | AB9: 375349 | AC9: 20499 | AD9: 4 | AE9: 69000 | AF9: 1 | AG9: 0 | AH9: 4 | AI9: 0 | AJ9: 0 | AK9: 0 | AL9: 5 | AM9: 1 | AN9: 0 | AO9: 0 | AP9: 0 | AQ9: 197 | AR9: 21 | AS9: 185 | AT9: =IFERROR(100*N9/L9,0) | AU9: =IFERROR(100*N9/K9,0) | AV9: =IFERROR(100*H9/F9,0) | AW9: =IFERROR(100*N9/J9,0) | AX9: =IFERROR(100*Q9/P9,0) | AY9: =IFERROR(100*N9/O9,0) | AZ9: =IFERROR(H9/S9,0) | BA9: =IFERROR(T9/S9,0) | BB9: =I9 | BC9: =R9 | BD9: =IFERROR(100*V9/U9,0) | BE9: =IFERROR(1000*(W9+Y9)/N9,0) | BF9: =W9 | BG9: =X9 | BH9: =Z9 | BI9: =AA9 | BJ9: =IFERROR(AB9/N9,0) | BK9: =AC9 | BL9: =AD9 | BM9: =AP9 | BN9: =IFERROR(100*AR9/AQ9,0) | BO9: =AK9 | BP9: =IFERROR(200000*AF9/AE9,0) | BQ9: =AG9 | BR9: =AH9 | BS9: =AI9 | BT9: =AJ9 | BU9: =AL9 | BV9: =AM9 | BW9: =IF(AN9=0,100,100*AO9/AN9) | BX9: =AS9
A10: Group | B10: Entity A1 | C10: Plant 02 | D10: 2026-06 | E10: 188.9 | F10: 720 | G10: 718 | H10: 669.9 | I10: 37.1 | J10: 135630 | K10: 136008 | L10: 120521 | M10: 96232 | N10: 91848 | O10: 97224 | P10: 21417 | Q10: 17596 | R10: 7008 | S10: 4 | T10: 32.6 | U10: 36 | V10: 31 | W10: 321487.9 | X10: 71503.8 | Y10: 1098.9 | Z10: 174177 | AA10: 54970 | AB10: 368624 | AC10: 28075 | AD10: 2 | AE10: 62000 | AF10: 1 | AG10: 0 | AH10: 4 | AI10: 0 | AJ10: 0 | AK10: 0 | AL10: 5 | AM10: 0 | AN10: 2 | AO10: 1 | AP10: 1 | AQ10: 194 | AR10: 21 | AS10: 155 | AT10: =IFERROR(100*N10/L10,0) | AU10: =IFERROR(100*N10/K10,0) | AV10: =IFERROR(100*H10/F10,0) | AW10: =IFERROR(100*N10/J10,0) | AX10: =IFERROR(100*Q10/P10,0) | AY10: =IFERROR(100*N10/O10,0) | AZ10: =IFERROR(H10/S10,0) | BA10: =IFERROR(T10/S10,0) | BB10: =I10 | BC10: =R10 | BD10: =IFERROR(100*V10/U10,0) | BE10: =IFERROR(1000*(W10+Y10)/N10,0) | BF10: =W10 | BG10: =X10 | BH10: =Z10 | BI10: =AA10 | BJ10: =IFERROR(AB10/N10,0) | BK10: =AC10 | BL10: =AD10 | BM10: =AP10 | BN10: =IFERROR(100*AR10/AQ10,0) | BO10: =AK10 | BP10: =IFERROR(200000*AF10/AE10,0) | BQ10: =AG10 | BR10: =AH10 | BS10: =AI10 | BT10: =AJ10 | BU10: =AL10 | BV10: =AM10 | BW10: =IF(AN10=0,100,100*AO10/AN10) | BX10: =AS10
A11: Group | B11: Entity A1 | C11: Plant 02 | D11: 2026-07 | E11: 188.9 | F11: 744 | G11: 737 | H11: 655.4 | I11: 69.3 | J11: 139219 | K11: 140542 | L11: 122135 | M11: 101413 | N11: 97731 | O11: 108037 | P11: 20571 | Q11: 17916 | R11: 13091 | S11: 6 | T11: 65.7 | U11: 56 | V11: 44 | W11: 350472.9 | X11: 93258.3 | Y11: 1434.2 | Z11: 204288 | AA11: 57701 | AB11: 356252 | AC11: 22870 | AD11: 2 | AE11: 68000 | AF11: 0 | AG11: 1 | AH11: 6 | AI11: 0 | AJ11: 1 | AK11: 0 | AL11: 7 | AM11: 0 | AN11: 1 | AO11: 1 | AP11: 0 | AQ11: 129 | AR11: 15 | AS11: 125 | AT11: =IFERROR(100*N11/L11,0) | AU11: =IFERROR(100*N11/K11,0) | AV11: =IFERROR(100*H11/F11,0) | AW11: =IFERROR(100*N11/J11,0) | AX11: =IFERROR(100*Q11/P11,0) | AY11: =IFERROR(100*N11/O11,0) | AZ11: =IFERROR(H11/S11,0) | BA11: =IFERROR(T11/S11,0) | BB11: =I11 | BC11: =R11 | BD11: =IFERROR(100*V11/U11,0) | BE11: =IFERROR(1000*(W11+Y11)/N11,0) | BF11: =W11 | BG11: =X11 | BH11: =Z11 | BI11: =AA11 | BJ11: =IFERROR(AB11/N11,0) | BK11: =AC11 | BL11: =AD11 | BM11: =AP11 | BN11: =IFERROR(100*AR11/AQ11,0) | BO11: =AK11 | BP11: =IFERROR(200000*AF11/AE11,0) | BQ11: =AG11 | BR11: =AH11 | BS11: =AI11 | BT11: =AJ11 | BU11: =AL11 | BV11: =AM11 | BW11: =IF(AN11=0,100,100*AO11/AN11) | BX11: =AS11
A12: Group | B12: Entity A1 | C12: Plant 02 | D12: 2026-08 | E12: 188.9 | F12: 744 | G12: 674 | H12: 603.4 | I12: 53.5 | J12: 127319 | K12: 140542 | L12: 109907 | M12: 90236 | N12: 86596 | O12: 97767 | P12: 22655 | Q12: 18611 | R12: 10106 | S12: 4 | T12: 46.8 | U12: 39 | V12: 37 | W12: 293787.6 | X12: 89718.1 | Y12: 1404.1 | Z12: 164589 | AA12: 62319 | AB12: 347920 | AC12: 23073 | AD12: 3 | AE12: 69000 | AF12: 0 | AG12: 1 | AH12: 5 | AI12: 1 | AJ12: 0 | AK12: 0 | AL12: 8 | AM12: 1 | AN12: 0 | AO12: 0 | AP12: 0 | AQ12: 212 | AR12: 32 | AS12: 95 | AT12: =IFERROR(100*N12/L12,0) | AU12: =IFERROR(100*N12/K12,0) | AV12: =IFERROR(100*H12/F12,0) | AW12: =IFERROR(100*N12/J12,0) | AX12: =IFERROR(100*Q12/P12,0) | AY12: =IFERROR(100*N12/O12,0) | AZ12: =IFERROR(H12/S12,0) | BA12: =IFERROR(T12/S12,0) | BB12: =I12 | BC12: =R12 | BD12: =IFERROR(100*V12/U12,0) | BE12: =IFERROR(1000*(W12+Y12)/N12,0) | BF12: =W12 | BG12: =X12 | BH12: =Z12 | BI12: =AA12 | BJ12: =IFERROR(AB12/N12,0) | BK12: =AC12 | BL12: =AD12 | BM12: =AP12 | BN12: =IFERROR(100*AR12/AQ12,0) | BO12: =AK12 | BP12: =IFERROR(200000*AF12/AE12,0) | BQ12: =AG12 | BR12: =AH12 | BS12: =AI12 | BT12: =AJ12 | BU12: =AL12 | BV12: =AM12 | BW12: =IF(AN12=0,100,100*AO12/AN12) | BX12: =AS12
A13: Group | B13: Entity A1 | C13: Plant 02 | D13: 2026-09 | E13: 188.9 | F13: 720 | G13: 717 | H13: 624.3 | I13: 78.2 | J13: 135441 | K13: 136008 | L13: 121475 | M13: 97250 | N13: 95233 | O13: 102279 | P13: 20791 | Q13: 17994 | R13: 14772 | S13: 6 | T13: 68.5 | U13: 33 | V13: 27 | W13: 308111 | X13: 70784.4 | Y13: 940.2 | Z13: 245659 | AA13: 68824 | AB13: 358135 | AC13: 24322 | AD13: 4 | AE13: 95000 | AF13: 0 | AG13: 0 | AH13: 2 | AI13: 0 | AJ13: 1 | AK13: 0 | AL13: 6 | AM13: 1 | AN13: 2 | AO13: 1 | AP13: 1 | AQ13: 225 | AR13: 36 | AS13: 65 | AT13: =IFERROR(100*N13/L13,0) | AU13: =IFERROR(100*N13/K13,0) | AV13: =IFERROR(100*H13/F13,0) | AW13: =IFERROR(100*N13/J13,0) | AX13: =IFERROR(100*Q13/P13,0) | AY13: =IFERROR(100*N13/O13,0) | AZ13: =IFERROR(H13/S13,0) | BA13: =IFERROR(T13/S13,0) | BB13: =I13 | BC13: =R13 | BD13: =IFERROR(100*V13/U13,0) | BE13: =IFERROR(1000*(W13+Y13)/N13,0) | BF13: =W13 | BG13: =X13 | BH13: =Z13 | BI13: =AA13 | BJ13: =IFERROR(AB13/N13,0) | BK13: =AC13 | BL13: =AD13 | BM13: =AP13 | BN13: =IFERROR(100*AR13/AQ13,0) | BO13: =AK13 | BP13: =IFERROR(200000*AF13/AE13,0) | BQ13: =AG13 | BR13: =AH13 | BS13: =AI13 | BT13: =AJ13 | BU13: =AL13 | BV13: =AM13 | BW13: =IF(AN13=0,100,100*AO13/AN13) | BX13: =AS13
... A37: Group | B37: Entity A2 | C37: Plant 06 | D37: 2026-09 | E37: 158.2 | F37: 720 | G37: 712 | H37: 680.7 | I37: 13.4 | J37: 112638 | K37: 113904 | L37: 98037 | M37: 97437 | N37: 94388 | O37: 101633 | P37: 20587 | Q37: 17410 | R37: 2120 | S37: 1 | T37: 6.5 | U37: 36 | V37: 34 | W37: 262617.2 | X37: 65862.8 | Y37: 1573 | Z37: 230619 | AA37: 63239 | AB37: 287280 | AC37: 5880 | AD37: 1 | AE37: 89000 | AF37: 0 | AG37: 1 | AH37: 9 | AI37: 0 | AJ37: 0 | AK37: 0 | AL37: 5 | AM37: 1 | AN37: 0 | AO37: 0 | AP37: 1 | AQ37: 125 | AR37: 3 | AS37: 110 | AT37: =IFERROR(100*N37/L37,0) | AU37: =IFERROR(100*N37/K37,0) | AV37: =IFERROR(100*H37/F37,0) | AW37: =IFERROR(100*N37/J37,0) | AX37: =IFERROR(100*Q37/P37,0) | AY37: =IFERROR(100*N37/O37,0) | AZ37: =IFERROR(H37/S37,0) | BA37: =IFERROR(T37/S37,0) | BB37: =I37 | BC37: =R37 | BD37: =IFERROR(100*V37/U37,0) | BE37: =IFERROR(1000*(W37+Y37)/N37,0) | BF37: =W37 | BG37: =X37 | BH37: =Z37 | BI37: =AA37 | BJ37: =IFERROR(AB37/N37,0) | BK37: =AC37 | BL37: =AD37 | BM37: =AP37 | BN37: =IFERROR(100*AR37/AQ37,0) | BO37: =AK37 | BP37: =IFERROR(200000*AF37/AE37,0) | BQ37: =AG37 | BR37: =AH37 | BS37: =AI37 | BT37: =AJ37 | BU37: =AL37 | BV37: =AM37 | BW37: =IF(AN37=0,100,100*AO37/AN37) | BX37: =AS37

Sheet Entity
A1: group | B1: entity | C1: period | D1: calendar_hours | E1: planned_op_hours | F1: run_hours | G1: unplanned_downtime_hours | H1: ideal_output_t | I1: installed_capacity_t | J1: planned_production_t | K1: gross_output_t | L1: good_output_t | M1: feed_input_t | N1: feed_contained_t | O1: recovered_contained_t | P1: prod_loss_downtime_t | Q1: failures | R1: repair_hours | S1: pm_scheduled | T1: pm_completed | U1: variable_cost_k | V1: fuel_cost_k | W1: fixed_cost_k | X1: water_m3 | Y1: emissions_tco2e | Z1: energy_gj | AA1: production_at_risk_t | AB1: critical_plant_alerts | AC1: hours_worked | AD1: recordable_injuries | AE1: severity_incidents | AF1: near_misses | AG1: critical_safety_incidents | AH1: env_excursions | AI1: env_violations | AJ1: ehs_ca_open | AK1: ehs_ca_overdue | AL1: investigations_due | AM1: investigations_completed | AN1: critical_material_risks | AO1: dispatches_total | AP1: dispatches_delayed | AQ1: permit_days_to_expiry | AR1: OPS-001 | AS1: OPS-003 | AT1: PLT-001 | AU1: PLT-002 | AV1: PLT-004 | AW1: PLT-005 | AX1: REL-001 | AY1: REL-002 | AZ1: REL-003 | BA1: REL-004 | BB1: REL-005 | BC1: CST-001 | BD1: CST-002 | BE1: CST-003 | BF1: SUS-001 | BG1: SUS-002 | BH1: SUS-003 | BI1: SIG-007 | BJ1: SIG-008 | BK1: SIG-009 | BL1: SIG-012 | BM1: SIG-021 | BN1: EHS-001 | BO1: EHS-002 | BP1: EHS-003 | BQ1: EHS-004 | BR1: EHS-005 | BS1: EHS-006 | BT1: EHS-007 | BU1: EHS-009 | BV1: REG-006
A2: Group | B2: Entity A1 | C2: 2026-04 | D2: =SUMIFS('Plant'!$F$2:$F$37,'Plant'!$B$2:$B$37,$B2,'Plant'!$D$2:$D$37,$C2) | E2: =SUMIFS('Plant'!$G$2:$G$37,'Plant'!$B$2:$B$37,$B2,'Plant'!$D$2:$D$37,$C2) | F2: =SUMIFS('Plant'!$H$2:$H$37,'Plant'!$B$2:$B$37,$B2,'Plant'!$D$2:$D$37,$C2) | G2: =SUMIFS('Plant'!$I$2:$I$37,'Plant'!$B$2:$B$37,$B2,'Plant'!$D$2:$D$37,$C2) | H2: =SUMIFS('Plant'!$J$2:$J$37,'Plant'!$B$2:$B$37,$B2,'Plant'!$D$2:$D$37,$C2) | I2: =SUMIFS('Plant'!$K$2:$K$37,'Plant'!$B$2:$B$37,$B2,'Plant'!$D$2:$D$37,$C2) | J2: =SUMIFS('Plant'!$L$2:$L$37,'Plant'!$B$2:$B$37,$B2,'Plant'!$D$2:$D$37,$C2) | K2: =SUMIFS('Plant'!$M$2:$M$37,'Plant'!$B$2:$B$37,$B2,'Plant'!$D$2:$D$37,$C2) | L2: =SUMIFS('Plant'!$N$2:$N$37,'Plant'!$B$2:$B$37,$B2,'Plant'!$D$2:$D$37,$C2) | M2: =SUMIFS('Plant'!$O$2:$O$37,'Plant'!$B$2:$B$37,$B2,'Plant'!$D$2:$D$37,$C2) | N2: =SUMIFS('Plant'!$P$2:$P$37,'Plant'!$B$2:$B$37,$B2,'Plant'!$D$2:$D$37,$C2) | O2: =SUMIFS('Plant'!$Q$2:$Q$37,'Plant'!$B$2:$B$37,$B2,'Plant'!$D$2:$D$37,$C2) | P2: =SUMIFS('Plant'!$R$2:$R$37,'Plant'!$B$2:$B$37,$B2,'Plant'!$D$2:$D$37,$C2) | Q2: =SUMIFS('Plant'!$S$2:$S$37,'Plant'!$B$2:$B$37,$B2,'Plant'!$D$2:$D$37,$C2) | R2: =SUMIFS('Plant'!$T$2:$T$37,'Plant'!$B$2:$B$37,$B2,'Plant'!$D$2:$D$37,$C2) | S2: =SUMIFS('Plant'!$U$2:$U$37,'Plant'!$B$2:$B$37,$B2,'Plant'!$D$2:$D$37,$C2) | T2: =SUMIFS('Plant'!$V$2:$V$37,'Plant'!$B$2:$B$37,$B2,'Plant'!$D$2:$D$37,$C2) | U2: =SUMIFS('Plant'!$W$2:$W$37,'Plant'!$B$2:$B$37,$B2,'Plant'!$D$2:$D$37,$C2) | V2: =SUMIFS('Plant'!$X$2:$X$37,'Plant'!$B$2:$B$37,$B2,'Plant'!$D$2:$D$37,$C2) | W2: =SUMIFS('Plant'!$Y$2:$Y$37,'Plant'!$B$2:$B$37,$B2,'Plant'!$D$2:$D$37,$C2) | X2: =SUMIFS('Plant'!$Z$2:$Z$37,'Plant'!$B$2:$B$37,$B2,'Plant'!$D$2:$D$37,$C2) | Y2: =SUMIFS('Plant'!$AA$2:$AA$37,'Plant'!$B$2:$B$37,$B2,'Plant'!$D$2:$D$37,$C2) | Z2: =SUMIFS('Plant'!$AB$2:$AB$37,'Plant'!$B$2:$B$37,$B2,'Plant'!$D$2:$D$37,$C2) | AA2: =SUMIFS('Plant'!$AC$2:$AC$37,'Plant'!$B$2:$B$37,$B2,'Plant'!$D$2:$D$37,$C2) | AB2: =SUMIFS('Plant'!$AD$2:$AD$37,'Plant'!$B$2:$B$37,$B2,'Plant'!$D$2:$D$37,$C2) | AC2: =SUMIFS('Plant'!$AE$2:$AE$37,'Plant'!$B$2:$B$37,$B2,'Plant'!$D$2:$D$37,$C2) | AD2: =SUMIFS('Plant'!$AF$2:$AF$37,'Plant'!$B$2:$B$37,$B2,'Plant'!$D$2:$D$37,$C2) | AE2: =SUMIFS('Plant'!$AG$2:$AG$37,'Plant'!$B$2:$B$37,$B2,'Plant'!$D$2:$D$37,$C2) | AF2: =SUMIFS('Plant'!$AH$2:$AH$37,'Plant'!$B$2:$B$37,$B2,'Plant'!$D$2:$D$37,$C2) | AG2: =SUMIFS('Plant'!$AI$2:$AI$37,'Plant'!$B$2:$B$37,$B2,'Plant'!$D$2:$D$37,$C2) | AH2: =SUMIFS('Plant'!$AJ$2:$AJ$37,'Plant'!$B$2:$B$37,$B2,'Plant'!$D$2:$D$37,$C2) | AI2: =SUMIFS('Plant'!$AK$2:$AK$37,'Plant'!$B$2:$B$37,$B2,'Plant'!$D$2:$D$37,$C2) | AJ2: =SUMIFS('Plant'!$AL$2:$AL$37,'Plant'!$B$2:$B$37,$B2,'Plant'!$D$2:$D$37,$C2) | AK2: =SUMIFS('Plant'!$AM$2:$AM$37,'Plant'!$B$2:$B$37,$B2,'Plant'!$D$2:$D$37,$C2) | AL2: =SUMIFS('Plant'!$AN$2:$AN$37,'Plant'!$B$2:$B$37,$B2,'Plant'!$D$2:$D$37,$C2) | AM2: =SUMIFS('Plant'!$AO$2:$AO$37,'Plant'!$B$2:$B$37,$B2,'Plant'!$D$2:$D$37,$C2) | AN2: =SUMIFS('Plant'!$AP$2:$AP$37,'Plant'!$B$2:$B$37,$B2,'Plant'!$D$2:$D$37,$C2) | AO2: =SUMIFS('Plant'!$AQ$2:$AQ$37,'Plant'!$B$2:$B$37,$B2,'Plant'!$D$2:$D$37,$C2) | AP2: =SUMIFS('Plant'!$AR$2:$AR$37,'Plant'!$B$2:$B$37,$B2,'Plant'!$D$2:$D$37,$C2) | AQ2: =MINIFS('Plant'!$AS$2:$AS$37,'Plant'!$B$2:$B$37,$B2,'Plant'!$D$2:$D$37,$C2) | AR2: =IFERROR(100*L2/J2,0) | AS2: =IFERROR(100*L2/I2,0) | AT2: =IFERROR(100*F2/D2,0) | AU2: =IFERROR(100*L2/H2,0) | AV2: =IFERROR(100*O2/N2,0) | AW2: =IFERROR(100*L2/M2,0) | AX2: =IFERROR(F2/Q2,0) | AY2: =IFERROR(R2/Q2,0) | AZ2: =G2 | BA2: =P2 | BB2: =IFERROR(100*T2/S2,0) | BC2: =IFERROR(1000*(U2+W2)/L2,0) | BD2: =U2 | BE2: =V2 | BF2: =X2 | BG2: =Y2 | BH2: =IFERROR(Z2/L2,0) | BI2: =AA2 | BJ2: =AB2 | BK2: =AN2 | BL2: =IFERROR(100*AP2/AO2,0) | BM2: =AI2 | BN2: =IFERROR(200000*AD2/AC2,0) | BO2: =AE2 | BP2: =AF2 | BQ2: =AG2 | BR2: =AH2 | BS2: =AJ2 | BT2: =AK2 | BU2: =IF(AL2=0,100,100*AM2/AL2) | BV2: =AQ2
A3: Group | B3: Entity A1 | C3: 2026-05 | D3: =SUMIFS('Plant'!$F$2:$F$37,'Plant'!$B$2:$B$37,$B3,'Plant'!$D$2:$D$37,$C3) | E3: =SUMIFS('Plant'!$G$2:$G$37,'Plant'!$B$2:$B$37,$B3,'Plant'!$D$2:$D$37,$C3) | F3: =SUMIFS('Plant'!$H$2:$H$37,'Plant'!$B$2:$B$37,$B3,'Plant'!$D$2:$D$37,$C3) | G3: =SUMIFS('Plant'!$I$2:$I$37,'Plant'!$B$2:$B$37,$B3,'Plant'!$D$2:$D$37,$C3) | H3: =SUMIFS('Plant'!$J$2:$J$37,'Plant'!$B$2:$B$37,$B3,'Plant'!$D$2:$D$37,$C3) | I3: =SUMIFS('Plant'!$K$2:$K$37,'Plant'!$B$2:$B$37,$B3,'Plant'!$D$2:$D$37,$C3) | J3: =SUMIFS('Plant'!$L$2:$L$37,'Plant'!$B$2:$B$37,$B3,'Plant'!$D$2:$D$37,$C3) | K3: =SUMIFS('Plant'!$M$2:$M$37,'Plant'!$B$2:$B$37,$B3,'Plant'!$D$2:$D$37,$C3) | L3: =SUMIFS('Plant'!$N$2:$N$37,'Plant'!$B$2:$B$37,$B3,'Plant'!$D$2:$D$37,$C3) | M3: =SUMIFS('Plant'!$O$2:$O$37,'Plant'!$B$2:$B$37,$B3,'Plant'!$D$2:$D$37,$C3) | N3: =SUMIFS('Plant'!$P$2:$P$37,'Plant'!$B$2:$B$37,$B3,'Plant'!$D$2:$D$37,$C3) | O3: =SUMIFS('Plant'!$Q$2:$Q$37,'Plant'!$B$2:$B$37,$B3,'Plant'!$D$2:$D$37,$C3) | P3: =SUMIFS('Plant'!$R$2:$R$37,'Plant'!$B$2:$B$37,$B3,'Plant'!$D$2:$D$37,$C3) | Q3: =SUMIFS('Plant'!$S$2:$S$37,'Plant'!$B$2:$B$37,$B3,'Plant'!$D$2:$D$37,$C3) | R3: =SUMIFS('Plant'!$T$2:$T$37,'Plant'!$B$2:$B$37,$B3,'Plant'!$D$2:$D$37,$C3) | S3: =SUMIFS('Plant'!$U$2:$U$37,'Plant'!$B$2:$B$37,$B3,'Plant'!$D$2:$D$37,$C3) | T3: =SUMIFS('Plant'!$V$2:$V$37,'Plant'!$B$2:$B$37,$B3,'Plant'!$D$2:$D$37,$C3) | U3: =SUMIFS('Plant'!$W$2:$W$37,'Plant'!$B$2:$B$37,$B3,'Plant'!$D$2:$D$37,$C3) | V3: =SUMIFS('Plant'!$X$2:$X$37,'Plant'!$B$2:$B$37,$B3,'Plant'!$D$2:$D$37,$C3) | W3: =SUMIFS('Plant'!$Y$2:$Y$37,'Plant'!$B$2:$B$37,$B3,'Plant'!$D$2:$D$37,$C3) | X3: =SUMIFS('Plant'!$Z$2:$Z$37,'Plant'!$B$2:$B$37,$B3,'Plant'!$D$2:$D$37,$C3) | Y3: =SUMIFS('Plant'!$AA$2:$AA$37,'Plant'!$B$2:$B$37,$B3,'Plant'!$D$2:$D$37,$C3) | Z3: =SUMIFS('Plant'!$AB$2:$AB$37,'Plant'!$B$2:$B$37,$B3,'Plant'!$D$2:$D$37,$C3) | AA3: =SUMIFS('Plant'!$AC$2:$AC$37,'Plant'!$B$2:$B$37,$B3,'Plant'!$D$2:$D$37,$C3) | AB3: =SUMIFS('Plant'!$AD$2:$AD$37,'Plant'!$B$2:$B$37,$B3,'Plant'!$D$2:$D$37,$C3) | AC3: =SUMIFS('Plant'!$AE$2:$AE$37,'Plant'!$B$2:$B$37,$B3,'Plant'!$D$2:$D$37,$C3) | AD3: =SUMIFS('Plant'!$AF$2:$AF$37,'Plant'!$B$2:$B$37,$B3,'Plant'!$D$2:$D$37,$C3) | AE3: =SUMIFS('Plant'!$AG$2:$AG$37,'Plant'!$B$2:$B$37,$B3,'Plant'!$D$2:$D$37,$C3) | AF3: =SUMIFS('Plant'!$AH$2:$AH$37,'Plant'!$B$2:$B$37,$B3,'Plant'!$D$2:$D$37,$C3) | AG3: =SUMIFS('Plant'!$AI$2:$AI$37,'Plant'!$B$2:$B$37,$B3,'Plant'!$D$2:$D$37,$C3) | AH3: =SUMIFS('Plant'!$AJ$2:$AJ$37,'Plant'!$B$2:$B$37,$B3,'Plant'!$D$2:$D$37,$C3) | AI3: =SUMIFS('Plant'!$AK$2:$AK$37,'Plant'!$B$2:$B$37,$B3,'Plant'!$D$2:$D$37,$C3) | AJ3: =SUMIFS('Plant'!$AL$2:$AL$37,'Plant'!$B$2:$B$37,$B3,'Plant'!$D$2:$D$37,$C3) | AK3: =SUMIFS('Plant'!$AM$2:$AM$37,'Plant'!$B$2:$B$37,$B3,'Plant'!$D$2:$D$37,$C3) | AL3: =SUMIFS('Plant'!$AN$2:$AN$37,'Plant'!$B$2:$B$37,$B3,'Plant'!$D$2:$D$37,$C3) | AM3: =SUMIFS('Plant'!$AO$2:$AO$37,'Plant'!$B$2:$B$37,$B3,'Plant'!$D$2:$D$37,$C3) | AN3: =SUMIFS('Plant'!$AP$2:$AP$37,'Plant'!$B$2:$B$37,$B3,'Plant'!$D$2:$D$37,$C3) | AO3: =SUMIFS('Plant'!$AQ$2:$AQ$37,'Plant'!$B$2:$B$37,$B3,'Plant'!$D$2:$D$37,$C3) | AP3: =SUMIFS('Plant'!$AR$2:$AR$37,'Plant'!$B$2:$B$37,$B3,'Plant'!$D$2:$D$37,$C3) | AQ3: =MINIFS('Plant'!$AS$2:$AS$37,'Plant'!$B$2:$B$37,$B3,'Plant'!$D$2:$D$37,$C3) | AR3: =IFERROR(100*L3/J3,0) | AS3: =IFERROR(100*L3/I3,0) | AT3: =IFERROR(100*F3/D3,0) | AU3: =IFERROR(100*L3/H3,0) | AV3: =IFERROR(100*O3/N3,0) | AW3: =IFERROR(100*L3/M3,0) | AX3: =IFERROR(F3/Q3,0) | AY3: =IFERROR(R3/Q3,0) | AZ3: =G3 | BA3: =P3 | BB3: =IFERROR(100*T3/S3,0) | BC3: =IFERROR(1000*(U3+W3)/L3,0) | BD3: =U3 | BE3: =V3 | BF3: =X3 | BG3: =Y3 | BH3: =IFERROR(Z3/L3,0) | BI3: =AA3 | BJ3: =AB3 | BK3: =AN3 | BL3: =IFERROR(100*AP3/AO3,0) | BM3: =AI3 | BN3: =IFERROR(200000*AD3/AC3,0) | BO3: =AE3 | BP3: =AF3 | BQ3: =AG3 | BR3: =AH3 | BS3: =AJ3 | BT3: =AK3 | BU3: =IF(AL3=0,100,100*AM3/AL3) | BV3: =AQ3
A4: Group | B4: Entity A1 | C4: 2026-06 | D4: =SUMIFS('Plant'!$F$2:$F$37,'Plant'!$B$2:$B$37,$B4,'Plant'!$D$2:$D$37,$C4) | E4: =SUMIFS('Plant'!$G$2:$G$37,'Plant'!$B$2:$B$37,$B4,'Plant'!$D$2:$D$37,$C4) | F4: =SUMIFS('Plant'!$H$2:$H$37,'Plant'!$B$2:$B$37,$B4,'Plant'!$D$2:$D$37,$C4) | G4: =SUMIFS('Plant'!$I$2:$I$37,'Plant'!$B$2:$B$37,$B4,'Plant'!$D$2:$D$37,$C4) | H4: =SUMIFS('Plant'!$J$2:$J$37,'Plant'!$B$2:$B$37,$B4,'Plant'!$D$2:$D$37,$C4) | I4: =SUMIFS('Plant'!$K$2:$K$37,'Plant'!$B$2:$B$37,$B4,'Plant'!$D$2:$D$37,$C4) | J4: =SUMIFS('Plant'!$L$2:$L$37,'Plant'!$B$2:$B$37,$B4,'Plant'!$D$2:$D$37,$C4) | K4: =SUMIFS('Plant'!$M$2:$M$37,'Plant'!$B$2:$B$37,$B4,'Plant'!$D$2:$D$37,$C4) | L4: =SUMIFS('Plant'!$N$2:$N$37,'Plant'!$B$2:$B$37,$B4,'Plant'!$D$2:$D$37,$C4) | M4: =SUMIFS('Plant'!$O$2:$O$37,'Plant'!$B$2:$B$37,$B4,'Plant'!$D$2:$D$37,$C4) | N4: =SUMIFS('Plant'!$P$2:$P$37,'Plant'!$B$2:$B$37,$B4,'Plant'!$D$2:$D$37,$C4) | O4: =SUMIFS('Plant'!$Q$2:$Q$37,'Plant'!$B$2:$B$37,$B4,'Plant'!$D$2:$D$37,$C4) | P4: =SUMIFS('Plant'!$R$2:$R$37,'Plant'!$B$2:$B$37,$B4,'Plant'!$D$2:$D$37,$C4) | Q4: =SUMIFS('Plant'!$S$2:$S$37,'Plant'!$B$2:$B$37,$B4,'Plant'!$D$2:$D$37,$C4) | R4: =SUMIFS('Plant'!$T$2:$T$37,'Plant'!$B$2:$B$37,$B4,'Plant'!$D$2:$D$37,$C4) | S4: =SUMIFS('Plant'!$U$2:$U$37,'Plant'!$B$2:$B$37,$B4,'Plant'!$D$2:$D$37,$C4) | T4: =SUMIFS('Plant'!$V$2:$V$37,'Plant'!$B$2:$B$37,$B4,'Plant'!$D$2:$D$37,$C4) | U4: =SUMIFS('Plant'!$W$2:$W$37,'Plant'!$B$2:$B$37,$B4,'Plant'!$D$2:$D$37,$C4) | V4: =SUMIFS('Plant'!$X$2:$X$37,'Plant'!$B$2:$B$37,$B4,'Plant'!$D$2:$D$37,$C4) | W4: =SUMIFS('Plant'!$Y$2:$Y$37,'Plant'!$B$2:$B$37,$B4,'Plant'!$D$2:$D$37,$C4) | X4: =SUMIFS('Plant'!$Z$2:$Z$37,'Plant'!$B$2:$B$37,$B4,'Plant'!$D$2:$D$37,$C4) | Y4: =SUMIFS('Plant'!$AA$2:$AA$37,'Plant'!$B$2:$B$37,$B4,'Plant'!$D$2:$D$37,$C4) | Z4: =SUMIFS('Plant'!$AB$2:$AB$37,'Plant'!$B$2:$B$37,$B4,'Plant'!$D$2:$D$37,$C4) | AA4: =SUMIFS('Plant'!$AC$2:$AC$37,'Plant'!$B$2:$B$37,$B4,'Plant'!$D$2:$D$37,$C4) | AB4: =SUMIFS('Plant'!$AD$2:$AD$37,'Plant'!$B$2:$B$37,$B4,'Plant'!$D$2:$D$37,$C4) | AC4: =SUMIFS('Plant'!$AE$2:$AE$37,'Plant'!$B$2:$B$37,$B4,'Plant'!$D$2:$D$37,$C4) | AD4: =SUMIFS('Plant'!$AF$2:$AF$37,'Plant'!$B$2:$B$37,$B4,'Plant'!$D$2:$D$37,$C4) | AE4: =SUMIFS('Plant'!$AG$2:$AG$37,'Plant'!$B$2:$B$37,$B4,'Plant'!$D$2:$D$37,$C4) | AF4: =SUMIFS('Plant'!$AH$2:$AH$37,'Plant'!$B$2:$B$37,$B4,'Plant'!$D$2:$D$37,$C4) | AG4: =SUMIFS('Plant'!$AI$2:$AI$37,'Plant'!$B$2:$B$37,$B4,'Plant'!$D$2:$D$37,$C4) | AH4: =SUMIFS('Plant'!$AJ$2:$AJ$37,'Plant'!$B$2:$B$37,$B4,'Plant'!$D$2:$D$37,$C4) | AI4: =SUMIFS('Plant'!$AK$2:$AK$37,'Plant'!$B$2:$B$37,$B4,'Plant'!$D$2:$D$37,$C4) | AJ4: =SUMIFS('Plant'!$AL$2:$AL$37,'Plant'!$B$2:$B$37,$B4,'Plant'!$D$2:$D$37,$C4) | AK4: =SUMIFS('Plant'!$AM$2:$AM$37,'Plant'!$B$2:$B$37,$B4,'Plant'!$D$2:$D$37,$C4) | AL4: =SUMIFS('Plant'!$AN$2:$AN$37,'Plant'!$B$2:$B$37,$B4,'Plant'!$D$2:$D$37,$C4) | AM4: =SUMIFS('Plant'!$AO$2:$AO$37,'Plant'!$B$2:$B$37,$B4,'Plant'!$D$2:$D$37,$C4) | AN4: =SUMIFS('Plant'!$AP$2:$AP$37,'Plant'!$B$2:$B$37,$B4,'Plant'!$D$2:$D$37,$C4) | AO4: =SUMIFS('Plant'!$AQ$2:$AQ$37,'Plant'!$B$2:$B$37,$B4,'Plant'!$D$2:$D$37,$C4) | AP4: =SUMIFS('Plant'!$AR$2:$AR$37,'Plant'!$B$2:$B$37,$B4,'Plant'!$D$2:$D$37,$C4) | AQ4: =MINIFS('Plant'!$AS$2:$AS$37,'Plant'!$B$2:$B$37,$B4,'Plant'!$D$2:$D$37,$C4) | AR4: =IFERROR(100*L4/J4,0) | AS4: =IFERROR(100*L4/I4,0) | AT4: =IFERROR(100*F4/D4,0) | AU4: =IFERROR(100*L4/H4,0) | AV4: =IFERROR(100*O4/N4,0) | AW4: =IFERROR(100*L4/M4,0) | AX4: =IFERROR(F4/Q4,0) | AY4: =IFERROR(R4/Q4,0) | AZ4: =G4 | BA4: =P4 | BB4: =IFERROR(100*T4/S4,0) | BC4: =IFERROR(1000*(U4+W4)/L4,0) | BD4: =U4 | BE4: =V4 | BF4: =X4 | BG4: =Y4 | BH4: =IFERROR(Z4/L4,0) | BI4: =AA4 | BJ4: =AB4 | BK4: =AN4 | BL4: =IFERROR(100*AP4/AO4,0) | BM4: =AI4 | BN4: =IFERROR(200000*AD4/AC4,0) | BO4: =AE4 | BP4: =AF4 | BQ4: =AG4 | BR4: =AH4 | BS4: =AJ4 | BT4: =AK4 | BU4: =IF(AL4=0,100,100*AM4/AL4) | BV4: =AQ4
A5: Group | B5: Entity A1 | C5: 2026-07 | D5: =SUMIFS('Plant'!$F$2:$F$37,'Plant'!$B$2:$B$37,$B5,'Plant'!$D$2:$D$37,$C5) | E5: =SUMIFS('Plant'!$G$2:$G$37,'Plant'!$B$2:$B$37,$B5,'Plant'!$D$2:$D$37,$C5) | F5: =SUMIFS('Plant'!$H$2:$H$37,'Plant'!$B$2:$B$37,$B5,'Plant'!$D$2:$D$37,$C5) | G5: =SUMIFS('Plant'!$I$2:$I$37,'Plant'!$B$2:$B$37,$B5,'Plant'!$D$2:$D$37,$C5) | H5: =SUMIFS('Plant'!$J$2:$J$37,'Plant'!$B$2:$B$37,$B5,'Plant'!$D$2:$D$37,$C5) | I5: =SUMIFS('Plant'!$K$2:$K$37,'Plant'!$B$2:$B$37,$B5,'Plant'!$D$2:$D$37,$C5) | J5: =SUMIFS('Plant'!$L$2:$L$37,'Plant'!$B$2:$B$37,$B5,'Plant'!$D$2:$D$37,$C5) | K5: =SUMIFS('Plant'!$M$2:$M$37,'Plant'!$B$2:$B$37,$B5,'Plant'!$D$2:$D$37,$C5) | L5: =SUMIFS('Plant'!$N$2:$N$37,'Plant'!$B$2:$B$37,$B5,'Plant'!$D$2:$D$37,$C5) | M5: =SUMIFS('Plant'!$O$2:$O$37,'Plant'!$B$2:$B$37,$B5,'Plant'!$D$2:$D$37,$C5) | N5: =SUMIFS('Plant'!$P$2:$P$37,'Plant'!$B$2:$B$37,$B5,'Plant'!$D$2:$D$37,$C5) | O5: =SUMIFS('Plant'!$Q$2:$Q$37,'Plant'!$B$2:$B$37,$B5,'Plant'!$D$2:$D$37,$C5) | P5: =SUMIFS('Plant'!$R$2:$R$37,'Plant'!$B$2:$B$37,$B5,'Plant'!$D$2:$D$37,$C5) | Q5: =SUMIFS('Plant'!$S$2:$S$37,'Plant'!$B$2:$B$37,$B5,'Plant'!$D$2:$D$37,$C5) | R5: =SUMIFS('Plant'!$T$2:$T$37,'Plant'!$B$2:$B$37,$B5,'Plant'!$D$2:$D$37,$C5) | S5: =SUMIFS('Plant'!$U$2:$U$37,'Plant'!$B$2:$B$37,$B5,'Plant'!$D$2:$D$37,$C5) | T5: =SUMIFS('Plant'!$V$2:$V$37,'Plant'!$B$2:$B$37,$B5,'Plant'!$D$2:$D$37,$C5) | U5: =SUMIFS('Plant'!$W$2:$W$37,'Plant'!$B$2:$B$37,$B5,'Plant'!$D$2:$D$37,$C5) | V5: =SUMIFS('Plant'!$X$2:$X$37,'Plant'!$B$2:$B$37,$B5,'Plant'!$D$2:$D$37,$C5) | W5: =SUMIFS('Plant'!$Y$2:$Y$37,'Plant'!$B$2:$B$37,$B5,'Plant'!$D$2:$D$37,$C5) | X5: =SUMIFS('Plant'!$Z$2:$Z$37,'Plant'!$B$2:$B$37,$B5,'Plant'!$D$2:$D$37,$C5) | Y5: =SUMIFS('Plant'!$AA$2:$AA$37,'Plant'!$B$2:$B$37,$B5,'Plant'!$D$2:$D$37,$C5) | Z5: =SUMIFS('Plant'!$AB$2:$AB$37,'Plant'!$B$2:$B$37,$B5,'Plant'!$D$2:$D$37,$C5) | AA5: =SUMIFS('Plant'!$AC$2:$AC$37,'Plant'!$B$2:$B$37,$B5,'Plant'!$D$2:$D$37,$C5) | AB5: =SUMIFS('Plant'!$AD$2:$AD$37,'Plant'!$B$2:$B$37,$B5,'Plant'!$D$2:$D$37,$C5) | AC5: =SUMIFS('Plant'!$AE$2:$AE$37,'Plant'!$B$2:$B$37,$B5,'Plant'!$D$2:$D$37,$C5) | AD5: =SUMIFS('Plant'!$AF$2:$AF$37,'Plant'!$B$2:$B$37,$B5,'Plant'!$D$2:$D$37,$C5) | AE5: =SUMIFS('Plant'!$AG$2:$AG$37,'Plant'!$B$2:$B$37,$B5,'Plant'!$D$2:$D$37,$C5) | AF5: =SUMIFS('Plant'!$AH$2:$AH$37,'Plant'!$B$2:$B$37,$B5,'Plant'!$D$2:$D$37,$C5) | AG5: =SUMIFS('Plant'!$AI$2:$AI$37,'Plant'!$B$2:$B$37,$B5,'Plant'!$D$2:$D$37,$C5) | AH5: =SUMIFS('Plant'!$AJ$2:$AJ$37,'Plant'!$B$2:$B$37,$B5,'Plant'!$D$2:$D$37,$C5) | AI5: =SUMIFS('Plant'!$AK$2:$AK$37,'Plant'!$B$2:$B$37,$B5,'Plant'!$D$2:$D$37,$C5) | AJ5: =SUMIFS('Plant'!$AL$2:$AL$37,'Plant'!$B$2:$B$37,$B5,'Plant'!$D$2:$D$37,$C5) | AK5: =SUMIFS('Plant'!$AM$2:$AM$37,'Plant'!$B$2:$B$37,$B5,'Plant'!$D$2:$D$37,$C5) | AL5: =SUMIFS('Plant'!$AN$2:$AN$37,'Plant'!$B$2:$B$37,$B5,'Plant'!$D$2:$D$37,$C5) | AM5: =SUMIFS('Plant'!$AO$2:$AO$37,'Plant'!$B$2:$B$37,$B5,'Plant'!$D$2:$D$37,$C5) | AN5: =SUMIFS('Plant'!$AP$2:$AP$37,'Plant'!$B$2:$B$37,$B5,'Plant'!$D$2:$D$37,$C5) | AO5: =SUMIFS('Plant'!$AQ$2:$AQ$37,'Plant'!$B$2:$B$37,$B5,'Plant'!$D$2:$D$37,$C5) | AP5: =SUMIFS('Plant'!$AR$2:$AR$37,'Plant'!$B$2:$B$37,$B5,'Plant'!$D$2:$D$37,$C5) | AQ5: =MINIFS('Plant'!$AS$2:$AS$37,'Plant'!$B$2:$B$37,$B5,'Plant'!$D$2:$D$37,$C5) | AR5: =IFERROR(100*L5/J5,0) | AS5: =IFERROR(100*L5/I5,0) | AT5: =IFERROR(100*F5/D5,0) | AU5: =IFERROR(100*L5/H5,0) | AV5: =IFERROR(100*O5/N5,0) | AW5: =IFERROR(100*L5/M5,0) | AX5: =IFERROR(F5/Q5,0) | AY5: =IFERROR(R5/Q5,0) | AZ5: =G5 | BA5: =P5 | BB5: =IFERROR(100*T5/S5,0) | BC5: =IFERROR(1000*(U5+W5)/L5,0) | BD5: =U5 | BE5: =V5 | BF5: =X5 | BG5: =Y5 | BH5: =IFERROR(Z5/L5,0) | BI5: =AA5 | BJ5: =AB5 | BK5: =AN5 | BL5: =IFERROR(100*AP5/AO5,0) | BM5: =AI5 | BN5: =IFERROR(200000*AD5/AC5,0) | BO5: =AE5 | BP5: =AF5 | BQ5: =AG5 | BR5: =AH5 | BS5: =AJ5 | BT5: =AK5 | BU5: =IF(AL5=0,100,100*AM5/AL5) | BV5: =AQ5
A6: Group | B6: Entity A1 | C6: 2026-08 | D6: =SUMIFS('Plant'!$F$2:$F$37,'Plant'!$B$2:$B$37,$B6,'Plant'!$D$2:$D$37,$C6) | E6: =SUMIFS('Plant'!$G$2:$G$37,'Plant'!$B$2:$B$37,$B6,'Plant'!$D$2:$D$37,$C6) | F6: =SUMIFS('Plant'!$H$2:$H$37,'Plant'!$B$2:$B$37,$B6,'Plant'!$D$2:$D$37,$C6) | G6: =SUMIFS('Plant'!$I$2:$I$37,'Plant'!$B$2:$B$37,$B6,'Plant'!$D$2:$D$37,$C6) | H6: =SUMIFS('Plant'!$J$2:$J$37,'Plant'!$B$2:$B$37,$B6,'Plant'!$D$2:$D$37,$C6) | I6: =SUMIFS('Plant'!$K$2:$K$37,'Plant'!$B$2:$B$37,$B6,'Plant'!$D$2:$D$37,$C6) | J6: =SUMIFS('Plant'!$L$2:$L$37,'Plant'!$B$2:$B$37,$B6,'Plant'!$D$2:$D$37,$C6) | K6: =SUMIFS('Plant'!$M$2:$M$37,'Plant'!$B$2:$B$37,$B6,'Plant'!$D$2:$D$37,$C6) | L6: =SUMIFS('Plant'!$N$2:$N$37,'Plant'!$B$2:$B$37,$B6,'Plant'!$D$2:$D$37,$C6) | M6: =SUMIFS('Plant'!$O$2:$O$37,'Plant'!$B$2:$B$37,$B6,'Plant'!$D$2:$D$37,$C6) | N6: =SUMIFS('Plant'!$P$2:$P$37,'Plant'!$B$2:$B$37,$B6,'Plant'!$D$2:$D$37,$C6) | O6: =SUMIFS('Plant'!$Q$2:$Q$37,'Plant'!$B$2:$B$37,$B6,'Plant'!$D$2:$D$37,$C6) | P6: =SUMIFS('Plant'!$R$2:$R$37,'Plant'!$B$2:$B$37,$B6,'Plant'!$D$2:$D$37,$C6) | Q6: =SUMIFS('Plant'!$S$2:$S$37,'Plant'!$B$2:$B$37,$B6,'Plant'!$D$2:$D$37,$C6) | R6: =SUMIFS('Plant'!$T$2:$T$37,'Plant'!$B$2:$B$37,$B6,'Plant'!$D$2:$D$37,$C6) | S6: =SUMIFS('Plant'!$U$2:$U$37,'Plant'!$B$2:$B$37,$B6,'Plant'!$D$2:$D$37,$C6) | T6: =SUMIFS('Plant'!$V$2:$V$37,'Plant'!$B$2:$B$37,$B6,'Plant'!$D$2:$D$37,$C6) | U6: =SUMIFS('Plant'!$W$2:$W$37,'Plant'!$B$2:$B$37,$B6,'Plant'!$D$2:$D$37,$C6) | V6: =SUMIFS('Plant'!$X$2:$X$37,'Plant'!$B$2:$B$37,$B6,'Plant'!$D$2:$D$37,$C6) | W6: =SUMIFS('Plant'!$Y$2:$Y$37,'Plant'!$B$2:$B$37,$B6,'Plant'!$D$2:$D$37,$C6) | X6: =SUMIFS('Plant'!$Z$2:$Z$37,'Plant'!$B$2:$B$37,$B6,'Plant'!$D$2:$D$37,$C6) | Y6: =SUMIFS('Plant'!$AA$2:$AA$37,'Plant'!$B$2:$B$37,$B6,'Plant'!$D$2:$D$37,$C6) | Z6: =SUMIFS('Plant'!$AB$2:$AB$37,'Plant'!$B$2:$B$37,$B6,'Plant'!$D$2:$D$37,$C6) | AA6: =SUMIFS('Plant'!$AC$2:$AC$37,'Plant'!$B$2:$B$37,$B6,'Plant'!$D$2:$D$37,$C6) | AB6: =SUMIFS('Plant'!$AD$2:$AD$37,'Plant'!$B$2:$B$37,$B6,'Plant'!$D$2:$D$37,$C6) | AC6: =SUMIFS('Plant'!$AE$2:$AE$37,'Plant'!$B$2:$B$37,$B6,'Plant'!$D$2:$D$37,$C6) | AD6: =SUMIFS('Plant'!$AF$2:$AF$37,'Plant'!$B$2:$B$37,$B6,'Plant'!$D$2:$D$37,$C6) | AE6: =SUMIFS('Plant'!$AG$2:$AG$37,'Plant'!$B$2:$B$37,$B6,'Plant'!$D$2:$D$37,$C6) | AF6: =SUMIFS('Plant'!$AH$2:$AH$37,'Plant'!$B$2:$B$37,$B6,'Plant'!$D$2:$D$37,$C6) | AG6: =SUMIFS('Plant'!$AI$2:$AI$37,'Plant'!$B$2:$B$37,$B6,'Plant'!$D$2:$D$37,$C6) | AH6: =SUMIFS('Plant'!$AJ$2:$AJ$37,'Plant'!$B$2:$B$37,$B6,'Plant'!$D$2:$D$37,$C6) | AI6: =SUMIFS('Plant'!$AK$2:$AK$37,'Plant'!$B$2:$B$37,$B6,'Plant'!$D$2:$D$37,$C6) | AJ6: =SUMIFS('Plant'!$AL$2:$AL$37,'Plant'!$B$2:$B$37,$B6,'Plant'!$D$2:$D$37,$C6) | AK6: =SUMIFS('Plant'!$AM$2:$AM$37,'Plant'!$B$2:$B$37,$B6,'Plant'!$D$2:$D$37,$C6) | AL6: =SUMIFS('Plant'!$AN$2:$AN$37,'Plant'!$B$2:$B$37,$B6,'Plant'!$D$2:$D$37,$C6) | AM6: =SUMIFS('Plant'!$AO$2:$AO$37,'Plant'!$B$2:$B$37,$B6,'Plant'!$D$2:$D$37,$C6) | AN6: =SUMIFS('Plant'!$AP$2:$AP$37,'Plant'!$B$2:$B$37,$B6,'Plant'!$D$2:$D$37,$C6) | AO6: =SUMIFS('Plant'!$AQ$2:$AQ$37,'Plant'!$B$2:$B$37,$B6,'Plant'!$D$2:$D$37,$C6) | AP6: =SUMIFS('Plant'!$AR$2:$AR$37,'Plant'!$B$2:$B$37,$B6,'Plant'!$D$2:$D$37,$C6) | AQ6: =MINIFS('Plant'!$AS$2:$AS$37,'Plant'!$B$2:$B$37,$B6,'Plant'!$D$2:$D$37,$C6) | AR6: =IFERROR(100*L6/J6,0) | AS6: =IFERROR(100*L6/I6,0) | AT6: =IFERROR(100*F6/D6,0) | AU6: =IFERROR(100*L6/H6,0) | AV6: =IFERROR(100*O6/N6,0) | AW6: =IFERROR(100*L6/M6,0) | AX6: =IFERROR(F6/Q6,0) | AY6: =IFERROR(R6/Q6,0) | AZ6: =G6 | BA6: =P6 | BB6: =IFERROR(100*T6/S6,0) | BC6: =IFERROR(1000*(U6+W6)/L6,0) | BD6: =U6 | BE6: =V6 | BF6: =X6 | BG6: =Y6 | BH6: =IFERROR(Z6/L6,0) | BI6: =AA6 | BJ6: =AB6 | BK6: =AN6 | BL6: =IFERROR(100*AP6/AO6,0) | BM6: =AI6 | BN6: =IFERROR(200000*AD6/AC6,0) | BO6: =AE6 | BP6: =AF6 | BQ6: =AG6 | BR6: =AH6 | BS6: =AJ6 | BT6: =AK6 | BU6: =IF(AL6=0,100,100*AM6/AL6) | BV6: =AQ6
A7: Group | B7: Entity A1 | C7: 2026-09 | D7: =SUMIFS('Plant'!$F$2:$F$37,'Plant'!$B$2:$B$37,$B7,'Plant'!$D$2:$D$37,$C7) | E7: =SUMIFS('Plant'!$G$2:$G$37,'Plant'!$B$2:$B$37,$B7,'Plant'!$D$2:$D$37,$C7) | F7: =SUMIFS('Plant'!$H$2:$H$37,'Plant'!$B$2:$B$37,$B7,'Plant'!$D$2:$D$37,$C7) | G7: =SUMIFS('Plant'!$I$2:$I$37,'Plant'!$B$2:$B$37,$B7,'Plant'!$D$2:$D$37,$C7) | H7: =SUMIFS('Plant'!$J$2:$J$37,'Plant'!$B$2:$B$37,$B7,'Plant'!$D$2:$D$37,$C7) | I7: =SUMIFS('Plant'!$K$2:$K$37,'Plant'!$B$2:$B$37,$B7,'Plant'!$D$2:$D$37,$C7) | J7: =SUMIFS('Plant'!$L$2:$L$37,'Plant'!$B$2:$B$37,$B7,'Plant'!$D$2:$D$37,$C7) | K7: =SUMIFS('Plant'!$M$2:$M$37,'Plant'!$B$2:$B$37,$B7,'Plant'!$D$2:$D$37,$C7) | L7: =SUMIFS('Plant'!$N$2:$N$37,'Plant'!$B$2:$B$37,$B7,'Plant'!$D$2:$D$37,$C7) | M7: =SUMIFS('Plant'!$O$2:$O$37,'Plant'!$B$2:$B$37,$B7,'Plant'!$D$2:$D$37,$C7) | N7: =SUMIFS('Plant'!$P$2:$P$37,'Plant'!$B$2:$B$37,$B7,'Plant'!$D$2:$D$37,$C7) | O7: =SUMIFS('Plant'!$Q$2:$Q$37,'Plant'!$B$2:$B$37,$B7,'Plant'!$D$2:$D$37,$C7) | P7: =SUMIFS('Plant'!$R$2:$R$37,'Plant'!$B$2:$B$37,$B7,'Plant'!$D$2:$D$37,$C7) | Q7: =SUMIFS('Plant'!$S$2:$S$37,'Plant'!$B$2:$B$37,$B7,'Plant'!$D$2:$D$37,$C7) | R7: =SUMIFS('Plant'!$T$2:$T$37,'Plant'!$B$2:$B$37,$B7,'Plant'!$D$2:$D$37,$C7) | S7: =SUMIFS('Plant'!$U$2:$U$37,'Plant'!$B$2:$B$37,$B7,'Plant'!$D$2:$D$37,$C7) | T7: =SUMIFS('Plant'!$V$2:$V$37,'Plant'!$B$2:$B$37,$B7,'Plant'!$D$2:$D$37,$C7) | U7: =SUMIFS('Plant'!$W$2:$W$37,'Plant'!$B$2:$B$37,$B7,'Plant'!$D$2:$D$37,$C7) | V7: =SUMIFS('Plant'!$X$2:$X$37,'Plant'!$B$2:$B$37,$B7,'Plant'!$D$2:$D$37,$C7) | W7: =SUMIFS('Plant'!$Y$2:$Y$37,'Plant'!$B$2:$B$37,$B7,'Plant'!$D$2:$D$37,$C7) | X7: =SUMIFS('Plant'!$Z$2:$Z$37,'Plant'!$B$2:$B$37,$B7,'Plant'!$D$2:$D$37,$C7) | Y7: =SUMIFS('Plant'!$AA$2:$AA$37,'Plant'!$B$2:$B$37,$B7,'Plant'!$D$2:$D$37,$C7) | Z7: =SUMIFS('Plant'!$AB$2:$AB$37,'Plant'!$B$2:$B$37,$B7,'Plant'!$D$2:$D$37,$C7) | AA7: =SUMIFS('Plant'!$AC$2:$AC$37,'Plant'!$B$2:$B$37,$B7,'Plant'!$D$2:$D$37,$C7) | AB7: =SUMIFS('Plant'!$AD$2:$AD$37,'Plant'!$B$2:$B$37,$B7,'Plant'!$D$2:$D$37,$C7) | AC7: =SUMIFS('Plant'!$AE$2:$AE$37,'Plant'!$B$2:$B$37,$B7,'Plant'!$D$2:$D$37,$C7) | AD7: =SUMIFS('Plant'!$AF$2:$AF$37,'Plant'!$B$2:$B$37,$B7,'Plant'!$D$2:$D$37,$C7) | AE7: =SUMIFS('Plant'!$AG$2:$AG$37,'Plant'!$B$2:$B$37,$B7,'Plant'!$D$2:$D$37,$C7) | AF7: =SUMIFS('Plant'!$AH$2:$AH$37,'Plant'!$B$2:$B$37,$B7,'Plant'!$D$2:$D$37,$C7) | AG7: =SUMIFS('Plant'!$AI$2:$AI$37,'Plant'!$B$2:$B$37,$B7,'Plant'!$D$2:$D$37,$C7) | AH7: =SUMIFS('Plant'!$AJ$2:$AJ$37,'Plant'!$B$2:$B$37,$B7,'Plant'!$D$2:$D$37,$C7) | AI7: =SUMIFS('Plant'!$AK$2:$AK$37,'Plant'!$B$2:$B$37,$B7,'Plant'!$D$2:$D$37,$C7) | AJ7: =SUMIFS('Plant'!$AL$2:$AL$37,'Plant'!$B$2:$B$37,$B7,'Plant'!$D$2:$D$37,$C7) | AK7: =SUMIFS('Plant'!$AM$2:$AM$37,'Plant'!$B$2:$B$37,$B7,'Plant'!$D$2:$D$37,$C7) | AL7: =SUMIFS('Plant'!$AN$2:$AN$37,'Plant'!$B$2:$B$37,$B7,'Plant'!$D$2:$D$37,$C7) | AM7: =SUMIFS('Plant'!$AO$2:$AO$37,'Plant'!$B$2:$B$37,$B7,'Plant'!$D$2:$D$37,$C7) | AN7: =SUMIFS('Plant'!$AP$2:$AP$37,'Plant'!$B$2:$B$37,$B7,'Plant'!$D$2:$D$37,$C7) | AO7: =SUMIFS('Plant'!$AQ$2:$AQ$37,'Plant'!$B$2:$B$37,$B7,'Plant'!$D$2:$D$37,$C7) | AP7: =SUMIFS('Plant'!$AR$2:$AR$37,'Plant'!$B$2:$B$37,$B7,'Plant'!$D$2:$D$37,$C7) | AQ7: =MINIFS('Plant'!$AS$2:$AS$37,'Plant'!$B$2:$B$37,$B7,'Plant'!$D$2:$D$37,$C7) | AR7: =IFERROR(100*L7/J7,0) | AS7: =IFERROR(100*L7/I7,0) | AT7: =IFERROR(100*F7/D7,0) | AU7: =IFERROR(100*L7/H7,0) | AV7: =IFERROR(100*O7/N7,0) | AW7: =IFERROR(100*L7/M7,0) | AX7: =IFERROR(F7/Q7,0) | AY7: =IFERROR(R7/Q7,0) | AZ7: =G7 | BA7: =P7 | BB7: =IFERROR(100*T7/S7,0) | BC7: =IFERROR(1000*(U7+W7)/L7,0) | BD7: =U7 | BE7: =V7 | BF7: =X7 | BG7: =Y7 | BH7: =IFERROR(Z7/L7,0) | BI7: =AA7 | BJ7: =AB7 | BK7: =AN7 | BL7: =IFERROR(100*AP7/AO7,0) | BM7: =AI7 | BN7: =IFERROR(200000*AD7/AC7,0) | BO7: =AE7 | BP7: =AF7 | BQ7: =AG7 | BR7: =AH7 | BS7: =AJ7 | BT7: =AK7 | BU7: =IF(AL7=0,100,100*AM7/AL7) | BV7: =AQ7
A8: Group | B8: Entity A2 | C8: 2026-04 | D8: =SUMIFS('Plant'!$F$2:$F$37,'Plant'!$B$2:$B$37,$B8,'Plant'!$D$2:$D$37,$C8) | E8: =SUMIFS('Plant'!$G$2:$G$37,'Plant'!$B$2:$B$37,$B8,'Plant'!$D$2:$D$37,$C8) | F8: =SUMIFS('Plant'!$H$2:$H$37,'Plant'!$B$2:$B$37,$B8,'Plant'!$D$2:$D$37,$C8) | G8: =SUMIFS('Plant'!$I$2:$I$37,'Plant'!$B$2:$B$37,$B8,'Plant'!$D$2:$D$37,$C8) | H8: =SUMIFS('Plant'!$J$2:$J$37,'Plant'!$B$2:$B$37,$B8,'Plant'!$D$2:$D$37,$C8) | I8: =SUMIFS('Plant'!$K$2:$K$37,'Plant'!$B$2:$B$37,$B8,'Plant'!$D$2:$D$37,$C8) | J8: =SUMIFS('Plant'!$L$2:$L$37,'Plant'!$B$2:$B$37,$B8,'Plant'!$D$2:$D$37,$C8) | K8: =SUMIFS('Plant'!$M$2:$M$37,'Plant'!$B$2:$B$37,$B8,'Plant'!$D$2:$D$37,$C8) | L8: =SUMIFS('Plant'!$N$2:$N$37,'Plant'!$B$2:$B$37,$B8,'Plant'!$D$2:$D$37,$C8) | M8: =SUMIFS('Plant'!$O$2:$O$37,'Plant'!$B$2:$B$37,$B8,'Plant'!$D$2:$D$37,$C8) | N8: =SUMIFS('Plant'!$P$2:$P$37,'Plant'!$B$2:$B$37,$B8,'Plant'!$D$2:$D$37,$C8) | O8: =SUMIFS('Plant'!$Q$2:$Q$37,'Plant'!$B$2:$B$37,$B8,'Plant'!$D$2:$D$37,$C8) | P8: =SUMIFS('Plant'!$R$2:$R$37,'Plant'!$B$2:$B$37,$B8,'Plant'!$D$2:$D$37,$C8) | Q8: =SUMIFS('Plant'!$S$2:$S$37,'Plant'!$B$2:$B$37,$B8,'Plant'!$D$2:$D$37,$C8) | R8: =SUMIFS('Plant'!$T$2:$T$37,'Plant'!$B$2:$B$37,$B8,'Plant'!$D$2:$D$37,$C8) | S8: =SUMIFS('Plant'!$U$2:$U$37,'Plant'!$B$2:$B$37,$B8,'Plant'!$D$2:$D$37,$C8) | T8: =SUMIFS('Plant'!$V$2:$V$37,'Plant'!$B$2:$B$37,$B8,'Plant'!$D$2:$D$37,$C8) | U8: =SUMIFS('Plant'!$W$2:$W$37,'Plant'!$B$2:$B$37,$B8,'Plant'!$D$2:$D$37,$C8) | V8: =SUMIFS('Plant'!$X$2:$X$37,'Plant'!$B$2:$B$37,$B8,'Plant'!$D$2:$D$37,$C8) | W8: =SUMIFS('Plant'!$Y$2:$Y$37,'Plant'!$B$2:$B$37,$B8,'Plant'!$D$2:$D$37,$C8) | X8: =SUMIFS('Plant'!$Z$2:$Z$37,'Plant'!$B$2:$B$37,$B8,'Plant'!$D$2:$D$37,$C8) | Y8: =SUMIFS('Plant'!$AA$2:$AA$37,'Plant'!$B$2:$B$37,$B8,'Plant'!$D$2:$D$37,$C8) | Z8: =SUMIFS('Plant'!$AB$2:$AB$37,'Plant'!$B$2:$B$37,$B8,'Plant'!$D$2:$D$37,$C8) | AA8: =SUMIFS('Plant'!$AC$2:$AC$37,'Plant'!$B$2:$B$37,$B8,'Plant'!$D$2:$D$37,$C8) | AB8: =SUMIFS('Plant'!$AD$2:$AD$37,'Plant'!$B$2:$B$37,$B8,'Plant'!$D$2:$D$37,$C8) | AC8: =SUMIFS('Plant'!$AE$2:$AE$37,'Plant'!$B$2:$B$37,$B8,'Plant'!$D$2:$D$37,$C8) | AD8: =SUMIFS('Plant'!$AF$2:$AF$37,'Plant'!$B$2:$B$37,$B8,'Plant'!$D$2:$D$37,$C8) | AE8: =SUMIFS('Plant'!$AG$2:$AG$37,'Plant'!$B$2:$B$37,$B8,'Plant'!$D$2:$D$37,$C8) | AF8: =SUMIFS('Plant'!$AH$2:$AH$37,'Plant'!$B$2:$B$37,$B8,'Plant'!$D$2:$D$37,$C8) | AG8: =SUMIFS('Plant'!$AI$2:$AI$37,'Plant'!$B$2:$B$37,$B8,'Plant'!$D$2:$D$37,$C8) | AH8: =SUMIFS('Plant'!$AJ$2:$AJ$37,'Plant'!$B$2:$B$37,$B8,'Plant'!$D$2:$D$37,$C8) | AI8: =SUMIFS('Plant'!$AK$2:$AK$37,'Plant'!$B$2:$B$37,$B8,'Plant'!$D$2:$D$37,$C8) | AJ8: =SUMIFS('Plant'!$AL$2:$AL$37,'Plant'!$B$2:$B$37,$B8,'Plant'!$D$2:$D$37,$C8) | AK8: =SUMIFS('Plant'!$AM$2:$AM$37,'Plant'!$B$2:$B$37,$B8,'Plant'!$D$2:$D$37,$C8) | AL8: =SUMIFS('Plant'!$AN$2:$AN$37,'Plant'!$B$2:$B$37,$B8,'Plant'!$D$2:$D$37,$C8) | AM8: =SUMIFS('Plant'!$AO$2:$AO$37,'Plant'!$B$2:$B$37,$B8,'Plant'!$D$2:$D$37,$C8) | AN8: =SUMIFS('Plant'!$AP$2:$AP$37,'Plant'!$B$2:$B$37,$B8,'Plant'!$D$2:$D$37,$C8) | AO8: =SUMIFS('Plant'!$AQ$2:$AQ$37,'Plant'!$B$2:$B$37,$B8,'Plant'!$D$2:$D$37,$C8) | AP8: =SUMIFS('Plant'!$AR$2:$AR$37,'Plant'!$B$2:$B$37,$B8,'Plant'!$D$2:$D$37,$C8) | AQ8: =MINIFS('Plant'!$AS$2:$AS$37,'Plant'!$B$2:$B$37,$B8,'Plant'!$D$2:$D$37,$C8) | AR8: =IFERROR(100*L8/J8,0) | AS8: =IFERROR(100*L8/I8,0) | AT8: =IFERROR(100*F8/D8,0) | AU8: =IFERROR(100*L8/H8,0) | AV8: =IFERROR(100*O8/N8,0) | AW8: =IFERROR(100*L8/M8,0) | AX8: =IFERROR(F8/Q8,0) | AY8: =IFERROR(R8/Q8,0) | AZ8: =G8 | BA8: =P8 | BB8: =IFERROR(100*T8/S8,0) | BC8: =IFERROR(1000*(U8+W8)/L8,0) | BD8: =U8 | BE8: =V8 | BF8: =X8 | BG8: =Y8 | BH8: =IFERROR(Z8/L8,0) | BI8: =AA8 | BJ8: =AB8 | BK8: =AN8 | BL8: =IFERROR(100*AP8/AO8,0) | BM8: =AI8 | BN8: =IFERROR(200000*AD8/AC8,0) | BO8: =AE8 | BP8: =AF8 | BQ8: =AG8 | BR8: =AH8 | BS8: =AJ8 | BT8: =AK8 | BU8: =IF(AL8=0,100,100*AM8/AL8) | BV8: =AQ8
A9: Group | B9: Entity A2 | C9: 2026-05 | D9: =SUMIFS('Plant'!$F$2:$F$37,'Plant'!$B$2:$B$37,$B9,'Plant'!$D$2:$D$37,$C9) | E9: =SUMIFS('Plant'!$G$2:$G$37,'Plant'!$B$2:$B$37,$B9,'Plant'!$D$2:$D$37,$C9) | F9: =SUMIFS('Plant'!$H$2:$H$37,'Plant'!$B$2:$B$37,$B9,'Plant'!$D$2:$D$37,$C9) | G9: =SUMIFS('Plant'!$I$2:$I$37,'Plant'!$B$2:$B$37,$B9,'Plant'!$D$2:$D$37,$C9) | H9: =SUMIFS('Plant'!$J$2:$J$37,'Plant'!$B$2:$B$37,$B9,'Plant'!$D$2:$D$37,$C9) | I9: =SUMIFS('Plant'!$K$2:$K$37,'Plant'!$B$2:$B$37,$B9,'Plant'!$D$2:$D$37,$C9) | J9: =SUMIFS('Plant'!$L$2:$L$37,'Plant'!$B$2:$B$37,$B9,'Plant'!$D$2:$D$37,$C9) | K9: =SUMIFS('Plant'!$M$2:$M$37,'Plant'!$B$2:$B$37,$B9,'Plant'!$D$2:$D$37,$C9) | L9: =SUMIFS('Plant'!$N$2:$N$37,'Plant'!$B$2:$B$37,$B9,'Plant'!$D$2:$D$37,$C9) | M9: =SUMIFS('Plant'!$O$2:$O$37,'Plant'!$B$2:$B$37,$B9,'Plant'!$D$2:$D$37,$C9) | N9: =SUMIFS('Plant'!$P$2:$P$37,'Plant'!$B$2:$B$37,$B9,'Plant'!$D$2:$D$37,$C9) | O9: =SUMIFS('Plant'!$Q$2:$Q$37,'Plant'!$B$2:$B$37,$B9,'Plant'!$D$2:$D$37,$C9) | P9: =SUMIFS('Plant'!$R$2:$R$37,'Plant'!$B$2:$B$37,$B9,'Plant'!$D$2:$D$37,$C9) | Q9: =SUMIFS('Plant'!$S$2:$S$37,'Plant'!$B$2:$B$37,$B9,'Plant'!$D$2:$D$37,$C9) | R9: =SUMIFS('Plant'!$T$2:$T$37,'Plant'!$B$2:$B$37,$B9,'Plant'!$D$2:$D$37,$C9) | S9: =SUMIFS('Plant'!$U$2:$U$37,'Plant'!$B$2:$B$37,$B9,'Plant'!$D$2:$D$37,$C9) | T9: =SUMIFS('Plant'!$V$2:$V$37,'Plant'!$B$2:$B$37,$B9,'Plant'!$D$2:$D$37,$C9) | U9: =SUMIFS('Plant'!$W$2:$W$37,'Plant'!$B$2:$B$37,$B9,'Plant'!$D$2:$D$37,$C9) | V9: =SUMIFS('Plant'!$X$2:$X$37,'Plant'!$B$2:$B$37,$B9,'Plant'!$D$2:$D$37,$C9) | W9: =SUMIFS('Plant'!$Y$2:$Y$37,'Plant'!$B$2:$B$37,$B9,'Plant'!$D$2:$D$37,$C9) | X9: =SUMIFS('Plant'!$Z$2:$Z$37,'Plant'!$B$2:$B$37,$B9,'Plant'!$D$2:$D$37,$C9) | Y9: =SUMIFS('Plant'!$AA$2:$AA$37,'Plant'!$B$2:$B$37,$B9,'Plant'!$D$2:$D$37,$C9) | Z9: =SUMIFS('Plant'!$AB$2:$AB$37,'Plant'!$B$2:$B$37,$B9,'Plant'!$D$2:$D$37,$C9) | AA9: =SUMIFS('Plant'!$AC$2:$AC$37,'Plant'!$B$2:$B$37,$B9,'Plant'!$D$2:$D$37,$C9) | AB9: =SUMIFS('Plant'!$AD$2:$AD$37,'Plant'!$B$2:$B$37,$B9,'Plant'!$D$2:$D$37,$C9) | AC9: =SUMIFS('Plant'!$AE$2:$AE$37,'Plant'!$B$2:$B$37,$B9,'Plant'!$D$2:$D$37,$C9) | AD9: =SUMIFS('Plant'!$AF$2:$AF$37,'Plant'!$B$2:$B$37,$B9,'Plant'!$D$2:$D$37,$C9) | AE9: =SUMIFS('Plant'!$AG$2:$AG$37,'Plant'!$B$2:$B$37,$B9,'Plant'!$D$2:$D$37,$C9) | AF9: =SUMIFS('Plant'!$AH$2:$AH$37,'Plant'!$B$2:$B$37,$B9,'Plant'!$D$2:$D$37,$C9) | AG9: =SUMIFS('Plant'!$AI$2:$AI$37,'Plant'!$B$2:$B$37,$B9,'Plant'!$D$2:$D$37,$C9) | AH9: =SUMIFS('Plant'!$AJ$2:$AJ$37,'Plant'!$B$2:$B$37,$B9,'Plant'!$D$2:$D$37,$C9) | AI9: =SUMIFS('Plant'!$AK$2:$AK$37,'Plant'!$B$2:$B$37,$B9,'Plant'!$D$2:$D$37,$C9) | AJ9: =SUMIFS('Plant'!$AL$2:$AL$37,'Plant'!$B$2:$B$37,$B9,'Plant'!$D$2:$D$37,$C9) | AK9: =SUMIFS('Plant'!$AM$2:$AM$37,'Plant'!$B$2:$B$37,$B9,'Plant'!$D$2:$D$37,$C9) | AL9: =SUMIFS('Plant'!$AN$2:$AN$37,'Plant'!$B$2:$B$37,$B9,'Plant'!$D$2:$D$37,$C9) | AM9: =SUMIFS('Plant'!$AO$2:$AO$37,'Plant'!$B$2:$B$37,$B9,'Plant'!$D$2:$D$37,$C9) | AN9: =SUMIFS('Plant'!$AP$2:$AP$37,'Plant'!$B$2:$B$37,$B9,'Plant'!$D$2:$D$37,$C9) | AO9: =SUMIFS('Plant'!$AQ$2:$AQ$37,'Plant'!$B$2:$B$37,$B9,'Plant'!$D$2:$D$37,$C9) | AP9: =SUMIFS('Plant'!$AR$2:$AR$37,'Plant'!$B$2:$B$37,$B9,'Plant'!$D$2:$D$37,$C9) | AQ9: =MINIFS('Plant'!$AS$2:$AS$37,'Plant'!$B$2:$B$37,$B9,'Plant'!$D$2:$D$37,$C9) | AR9: =IFERROR(100*L9/J9,0) | AS9: =IFERROR(100*L9/I9,0) | AT9: =IFERROR(100*F9/D9,0) | AU9: =IFERROR(100*L9/H9,0) | AV9: =IFERROR(100*O9/N9,0) | AW9: =IFERROR(100*L9/M9,0) | AX9: =IFERROR(F9/Q9,0) | AY9: =IFERROR(R9/Q9,0) | AZ9: =G9 | BA9: =P9 | BB9: =IFERROR(100*T9/S9,0) | BC9: =IFERROR(1000*(U9+W9)/L9,0) | BD9: =U9 | BE9: =V9 | BF9: =X9 | BG9: =Y9 | BH9: =IFERROR(Z9/L9,0) | BI9: =AA9 | BJ9: =AB9 | BK9: =AN9 | BL9: =IFERROR(100*AP9/AO9,0) | BM9: =AI9 | BN9: =IFERROR(200000*AD9/AC9,0) | BO9: =AE9 | BP9: =AF9 | BQ9: =AG9 | BR9: =AH9 | BS9: =AJ9 | BT9: =AK9 | BU9: =IF(AL9=0,100,100*AM9/AL9) | BV9: =AQ9
A10: Group | B10: Entity A2 | C10: 2026-06 | D10: =SUMIFS('Plant'!$F$2:$F$37,'Plant'!$B$2:$B$37,$B10,'Plant'!$D$2:$D$37,$C10) | E10: =SUMIFS('Plant'!$G$2:$G$37,'Plant'!$B$2:$B$37,$B10,'Plant'!$D$2:$D$37,$C10) | F10: =SUMIFS('Plant'!$H$2:$H$37,'Plant'!$B$2:$B$37,$B10,'Plant'!$D$2:$D$37,$C10) | G10: =SUMIFS('Plant'!$I$2:$I$37,'Plant'!$B$2:$B$37,$B10,'Plant'!$D$2:$D$37,$C10) | H10: =SUMIFS('Plant'!$J$2:$J$37,'Plant'!$B$2:$B$37,$B10,'Plant'!$D$2:$D$37,$C10) | I10: =SUMIFS('Plant'!$K$2:$K$37,'Plant'!$B$2:$B$37,$B10,'Plant'!$D$2:$D$37,$C10) | J10: =SUMIFS('Plant'!$L$2:$L$37,'Plant'!$B$2:$B$37,$B10,'Plant'!$D$2:$D$37,$C10) | K10: =SUMIFS('Plant'!$M$2:$M$37,'Plant'!$B$2:$B$37,$B10,'Plant'!$D$2:$D$37,$C10) | L10: =SUMIFS('Plant'!$N$2:$N$37,'Plant'!$B$2:$B$37,$B10,'Plant'!$D$2:$D$37,$C10) | M10: =SUMIFS('Plant'!$O$2:$O$37,'Plant'!$B$2:$B$37,$B10,'Plant'!$D$2:$D$37,$C10) | N10: =SUMIFS('Plant'!$P$2:$P$37,'Plant'!$B$2:$B$37,$B10,'Plant'!$D$2:$D$37,$C10) | O10: =SUMIFS('Plant'!$Q$2:$Q$37,'Plant'!$B$2:$B$37,$B10,'Plant'!$D$2:$D$37,$C10) | P10: =SUMIFS('Plant'!$R$2:$R$37,'Plant'!$B$2:$B$37,$B10,'Plant'!$D$2:$D$37,$C10) | Q10: =SUMIFS('Plant'!$S$2:$S$37,'Plant'!$B$2:$B$37,$B10,'Plant'!$D$2:$D$37,$C10) | R10: =SUMIFS('Plant'!$T$2:$T$37,'Plant'!$B$2:$B$37,$B10,'Plant'!$D$2:$D$37,$C10) | S10: =SUMIFS('Plant'!$U$2:$U$37,'Plant'!$B$2:$B$37,$B10,'Plant'!$D$2:$D$37,$C10) | T10: =SUMIFS('Plant'!$V$2:$V$37,'Plant'!$B$2:$B$37,$B10,'Plant'!$D$2:$D$37,$C10) | U10: =SUMIFS('Plant'!$W$2:$W$37,'Plant'!$B$2:$B$37,$B10,'Plant'!$D$2:$D$37,$C10) | V10: =SUMIFS('Plant'!$X$2:$X$37,'Plant'!$B$2:$B$37,$B10,'Plant'!$D$2:$D$37,$C10) | W10: =SUMIFS('Plant'!$Y$2:$Y$37,'Plant'!$B$2:$B$37,$B10,'Plant'!$D$2:$D$37,$C10) | X10: =SUMIFS('Plant'!$Z$2:$Z$37,'Plant'!$B$2:$B$37,$B10,'Plant'!$D$2:$D$37,$C10) | Y10: =SUMIFS('Plant'!$AA$2:$AA$37,'Plant'!$B$2:$B$37,$B10,'Plant'!$D$2:$D$37,$C10) | Z10: =SUMIFS('Plant'!$AB$2:$AB$37,'Plant'!$B$2:$B$37,$B10,'Plant'!$D$2:$D$37,$C10) | AA10: =SUMIFS('Plant'!$AC$2:$AC$37,'Plant'!$B$2:$B$37,$B10,'Plant'!$D$2:$D$37,$C10) | AB10: =SUMIFS('Plant'!$AD$2:$AD$37,'Plant'!$B$2:$B$37,$B10,'Plant'!$D$2:$D$37,$C10) | AC10: =SUMIFS('Plant'!$AE$2:$AE$37,'Plant'!$B$2:$B$37,$B10,'Plant'!$D$2:$D$37,$C10) | AD10: =SUMIFS('Plant'!$AF$2:$AF$37,'Plant'!$B$2:$B$37,$B10,'Plant'!$D$2:$D$37,$C10) | AE10: =SUMIFS('Plant'!$AG$2:$AG$37,'Plant'!$B$2:$B$37,$B10,'Plant'!$D$2:$D$37,$C10) | AF10: =SUMIFS('Plant'!$AH$2:$AH$37,'Plant'!$B$2:$B$37,$B10,'Plant'!$D$2:$D$37,$C10) | AG10: =SUMIFS('Plant'!$AI$2:$AI$37,'Plant'!$B$2:$B$37,$B10,'Plant'!$D$2:$D$37,$C10) | AH10: =SUMIFS('Plant'!$AJ$2:$AJ$37,'Plant'!$B$2:$B$37,$B10,'Plant'!$D$2:$D$37,$C10) | AI10: =SUMIFS('Plant'!$AK$2:$AK$37,'Plant'!$B$2:$B$37,$B10,'Plant'!$D$2:$D$37,$C10) | AJ10: =SUMIFS('Plant'!$AL$2:$AL$37,'Plant'!$B$2:$B$37,$B10,'Plant'!$D$2:$D$37,$C10) | AK10: =SUMIFS('Plant'!$AM$2:$AM$37,'Plant'!$B$2:$B$37,$B10,'Plant'!$D$2:$D$37,$C10) | AL10: =SUMIFS('Plant'!$AN$2:$AN$37,'Plant'!$B$2:$B$37,$B10,'Plant'!$D$2:$D$37,$C10) | AM10: =SUMIFS('Plant'!$AO$2:$AO$37,'Plant'!$B$2:$B$37,$B10,'Plant'!$D$2:$D$37,$C10) | AN10: =SUMIFS('Plant'!$AP$2:$AP$37,'Plant'!$B$2:$B$37,$B10,'Plant'!$D$2:$D$37,$C10) | AO10: =SUMIFS('Plant'!$AQ$2:$AQ$37,'Plant'!$B$2:$B$37,$B10,'Plant'!$D$2:$D$37,$C10) | AP10: =SUMIFS('Plant'!$AR$2:$AR$37,'Plant'!$B$2:$B$37,$B10,'Plant'!$D$2:$D$37,$C10) | AQ10: =MINIFS('Plant'!$AS$2:$AS$37,'Plant'!$B$2:$B$37,$B10,'Plant'!$D$2:$D$37,$C10) | AR10: =IFERROR(100*L10/J10,0) | AS10: =IFERROR(100*L10/I10,0) | AT10: =IFERROR(100*F10/D10,0) | AU10: =IFERROR(100*L10/H10,0) | AV10: =IFERROR(100*O10/N10,0) | AW10: =IFERROR(100*L10/M10,0) | AX10: =IFERROR(F10/Q10,0) | AY10: =IFERROR(R10/Q10,0) | AZ10: =G10 | BA10: =P10 | BB10: =IFERROR(100*T10/S10,0) | BC10: =IFERROR(1000*(U10+W10)/L10,0) | BD10: =U10 | BE10: =V10 | BF10: =X10 | BG10: =Y10 | BH10: =IFERROR(Z10/L10,0) | BI10: =AA10 | BJ10: =AB10 | BK10: =AN10 | BL10: =IFERROR(100*AP10/AO10,0) | BM10: =AI10 | BN10: =IFERROR(200000*AD10/AC10,0) | BO10: =AE10 | BP10: =AF10 | BQ10: =AG10 | BR10: =AH10 | BS10: =AJ10 | BT10: =AK10 | BU10: =IF(AL10=0,100,100*AM10/AL10) | BV10: =AQ10
A11: Group | B11: Entity A2 | C11: 2026-07 | D11: =SUMIFS('Plant'!$F$2:$F$37,'Plant'!$B$2:$B$37,$B11,'Plant'!$D$2:$D$37,$C11) | E11: =SUMIFS('Plant'!$G$2:$G$37,'Plant'!$B$2:$B$37,$B11,'Plant'!$D$2:$D$37,$C11) | F11: =SUMIFS('Plant'!$H$2:$H$37,'Plant'!$B$2:$B$37,$B11,'Plant'!$D$2:$D$37,$C11) | G11: =SUMIFS('Plant'!$I$2:$I$37,'Plant'!$B$2:$B$37,$B11,'Plant'!$D$2:$D$37,$C11) | H11: =SUMIFS('Plant'!$J$2:$J$37,'Plant'!$B$2:$B$37,$B11,'Plant'!$D$2:$D$37,$C11) | I11: =SUMIFS('Plant'!$K$2:$K$37,'Plant'!$B$2:$B$37,$B11,'Plant'!$D$2:$D$37,$C11) | J11: =SUMIFS('Plant'!$L$2:$L$37,'Plant'!$B$2:$B$37,$B11,'Plant'!$D$2:$D$37,$C11) | K11: =SUMIFS('Plant'!$M$2:$M$37,'Plant'!$B$2:$B$37,$B11,'Plant'!$D$2:$D$37,$C11) | L11: =SUMIFS('Plant'!$N$2:$N$37,'Plant'!$B$2:$B$37,$B11,'Plant'!$D$2:$D$37,$C11) | M11: =SUMIFS('Plant'!$O$2:$O$37,'Plant'!$B$2:$B$37,$B11,'Plant'!$D$2:$D$37,$C11) | N11: =SUMIFS('Plant'!$P$2:$P$37,'Plant'!$B$2:$B$37,$B11,'Plant'!$D$2:$D$37,$C11) | O11: =SUMIFS('Plant'!$Q$2:$Q$37,'Plant'!$B$2:$B$37,$B11,'Plant'!$D$2:$D$37,$C11) | P11: =SUMIFS('Plant'!$R$2:$R$37,'Plant'!$B$2:$B$37,$B11,'Plant'!$D$2:$D$37,$C11) | Q11: =SUMIFS('Plant'!$S$2:$S$37,'Plant'!$B$2:$B$37,$B11,'Plant'!$D$2:$D$37,$C11) | R11: =SUMIFS('Plant'!$T$2:$T$37,'Plant'!$B$2:$B$37,$B11,'Plant'!$D$2:$D$37,$C11) | S11: =SUMIFS('Plant'!$U$2:$U$37,'Plant'!$B$2:$B$37,$B11,'Plant'!$D$2:$D$37,$C11) | T11: =SUMIFS('Plant'!$V$2:$V$37,'Plant'!$B$2:$B$37,$B11,'Plant'!$D$2:$D$37,$C11) | U11: =SUMIFS('Plant'!$W$2:$W$37,'Plant'!$B$2:$B$37,$B11,'Plant'!$D$2:$D$37,$C11) | V11: =SUMIFS('Plant'!$X$2:$X$37,'Plant'!$B$2:$B$37,$B11,'Plant'!$D$2:$D$37,$C11) | W11: =SUMIFS('Plant'!$Y$2:$Y$37,'Plant'!$B$2:$B$37,$B11,'Plant'!$D$2:$D$37,$C11) | X11: =SUMIFS('Plant'!$Z$2:$Z$37,'Plant'!$B$2:$B$37,$B11,'Plant'!$D$2:$D$37,$C11) | Y11: =SUMIFS('Plant'!$AA$2:$AA$37,'Plant'!$B$2:$B$37,$B11,'Plant'!$D$2:$D$37,$C11) | Z11: =SUMIFS('Plant'!$AB$2:$AB$37,'Plant'!$B$2:$B$37,$B11,'Plant'!$D$2:$D$37,$C11) | AA11: =SUMIFS('Plant'!$AC$2:$AC$37,'Plant'!$B$2:$B$37,$B11,'Plant'!$D$2:$D$37,$C11) | AB11: =SUMIFS('Plant'!$AD$2:$AD$37,'Plant'!$B$2:$B$37,$B11,'Plant'!$D$2:$D$37,$C11) | AC11: =SUMIFS('Plant'!$AE$2:$AE$37,'Plant'!$B$2:$B$37,$B11,'Plant'!$D$2:$D$37,$C11) | AD11: =SUMIFS('Plant'!$AF$2:$AF$37,'Plant'!$B$2:$B$37,$B11,'Plant'!$D$2:$D$37,$C11) | AE11: =SUMIFS('Plant'!$AG$2:$AG$37,'Plant'!$B$2:$B$37,$B11,'Plant'!$D$2:$D$37,$C11) | AF11: =SUMIFS('Plant'!$AH$2:$AH$37,'Plant'!$B$2:$B$37,$B11,'Plant'!$D$2:$D$37,$C11) | AG11: =SUMIFS('Plant'!$AI$2:$AI$37,'Plant'!$B$2:$B$37,$B11,'Plant'!$D$2:$D$37,$C11) | AH11: =SUMIFS('Plant'!$AJ$2:$AJ$37,'Plant'!$B$2:$B$37,$B11,'Plant'!$D$2:$D$37,$C11) | AI11: =SUMIFS('Plant'!$AK$2:$AK$37,'Plant'!$B$2:$B$37,$B11,'Plant'!$D$2:$D$37,$C11) | AJ11: =SUMIFS('Plant'!$AL$2:$AL$37,'Plant'!$B$2:$B$37,$B11,'Plant'!$D$2:$D$37,$C11) | AK11: =SUMIFS('Plant'!$AM$2:$AM$37,'Plant'!$B$2:$B$37,$B11,'Plant'!$D$2:$D$37,$C11) | AL11: =SUMIFS('Plant'!$AN$2:$AN$37,'Plant'!$B$2:$B$37,$B11,'Plant'!$D$2:$D$37,$C11) | AM11: =SUMIFS('Plant'!$AO$2:$AO$37,'Plant'!$B$2:$B$37,$B11,'Plant'!$D$2:$D$37,$C11) | AN11: =SUMIFS('Plant'!$AP$2:$AP$37,'Plant'!$B$2:$B$37,$B11,'Plant'!$D$2:$D$37,$C11) | AO11: =SUMIFS('Plant'!$AQ$2:$AQ$37,'Plant'!$B$2:$B$37,$B11,'Plant'!$D$2:$D$37,$C11) | AP11: =SUMIFS('Plant'!$AR$2:$AR$37,'Plant'!$B$2:$B$37,$B11,'Plant'!$D$2:$D$37,$C11) | AQ11: =MINIFS('Plant'!$AS$2:$AS$37,'Plant'!$B$2:$B$37,$B11,'Plant'!$D$2:$D$37,$C11) | AR11: =IFERROR(100*L11/J11,0) | AS11: =IFERROR(100*L11/I11,0) | AT11: =IFERROR(100*F11/D11,0) | AU11: =IFERROR(100*L11/H11,0) | AV11: =IFERROR(100*O11/N11,0) | AW11: =IFERROR(100*L11/M11,0) | AX11: =IFERROR(F11/Q11,0) | AY11: =IFERROR(R11/Q11,0) | AZ11: =G11 | BA11: =P11 | BB11: =IFERROR(100*T11/S11,0) | BC11: =IFERROR(1000*(U11+W11)/L11,0) | BD11: =U11 | BE11: =V11 | BF11: =X11 | BG11: =Y11 | BH11: =IFERROR(Z11/L11,0) | BI11: =AA11 | BJ11: =AB11 | BK11: =AN11 | BL11: =IFERROR(100*AP11/AO11,0) | BM11: =AI11 | BN11: =IFERROR(200000*AD11/AC11,0) | BO11: =AE11 | BP11: =AF11 | BQ11: =AG11 | BR11: =AH11 | BS11: =AJ11 | BT11: =AK11 | BU11: =IF(AL11=0,100,100*AM11/AL11) | BV11: =AQ11
