Workbook

Sheet UI KPI Map
A1: KPI ID | B1: Measure | C1: Scopes shown in UI | D1: Screens | E1: Group P06 | F1: A1 P06 | G1: A2 P06 | H1: Plant-level? | I1: Source
A2: CMP-005 | B2: Regulatory breaches YTD (same measure as REG-010) | C2: A1,Group | D2: E01 O01 | E2: 0 | F2: 0 | G2: 0 | H2: yes | I2: alias of REG-010
A3: CON-001 | B3: Contracts expiring, next 90 days | C3: A1,Group | D3: E04 E07 G07 O05 | E3: 4 | F3: 2 | G3: 2 | H3: no | I3: source model
A4: CON-002 | B4: Contract-compliance rate | C4: A1,Group | D4: E04 E07 G07 O05 | E4: 95.71 | F4: 95.83 | G4: 95.59 | H4: no | I4: source model
A5: CON-003 | B5: Supplier EHS non-compliance | C5: A1,Group | D5: E04 E07 G05 G07 O05 | E5: 0 | F5: 0 | G5: 0 | H5: no | I5: source model
A6: CPX-001 | B6: Approved capex budget | C6: A1,Group | D6: E06 G06 O04 | E6: 1860 | F6: 1000 | G6: 860 | H6: no | I6: source model
A7: CPX-002 | B7: Committed capex | C7: A1,Group | D7: E06 G06 O04 | E7: 1347.73 | F7: 722.63 | G7: 625.1 | H7: no | I7: source model
A8: CPX-003 | B8: Capex actual spend YTD | C8: A1,Group | D8: E06 G06 O04 | E8: 879.71 | F8: 468.11 | G8: 411.6 | H8: no | I8: source model
A9: CPX-004 | B9: Capex physical progress, weighted | C9: A1,Group | D9: E06 G01 G01b G06 O01 O04 X L | E9: 60.85 | F9: 59 | G9: 63 | H9: no | I9: source model
A10: CSH-001 | B10: Cash position | C10: A1,Group | D10: E05 G04 G08 G08o O03 | E10: 2141.82 | F10: 967.08 | G10: 1174.74 | H10: no | I10: source model
A11: CSH-002 | B11: Cash released YTD | C11: A1,Group | D11: E05 G04 | E11: 22.03 | F11: 4.2 | G11: 17.83 | H11: no | I11: source model
A12: CSH-003 | B12: Daily collections | C12: A1,Group | D12: E01 E05 E08 G04 S11 | E12: 76.77 | F12: 38.6 | G12: 38.17 | H12: no | I12: source model
A13: CSH-004 | B13: Cash-conversion cycle | C13: A1,Group | D13: E05 G04 | E13: 32.59 | F13: 52.3 | G13: 13.42 | H13: no | I13: source model
... A20: CTL-002 | B20: Control failures YTD | C20: A1,Group | D20: E07 G07 O05 | E20: 4 | F20: 2 | G20: 2 | H20: no | I20: source model
A21: CTL-003 | B21: Assurance reviews completed | C21: Group | D21: G07 | E21: 6 of 8 | F21: 2 of 4 | G21: 4 of 4 | H21: no | I21: source model
A22: CTL-004 | B22: High-severity control failures YTD | C22: Group | D22: G07 O05 | E22: 0 | F22: 0 | G22: 0 | H22: no | I22: source model
A23: CTL-005 | B23: Policy exceptions YTD | C23: A1,Group | D23: E07 G07 O05 | E23: 4 | F23: 2 | G23: 2 | H23: no | I23: source model
A24: CTL-006 | B24: Unauthorised-vendor usage YTD | C24: A1,Group | D24: E07 G07 O05 | E24: 0 | F24: 0 | G24: 0 | H24: no | I24: source model
A25: CTL-007 | B25: Segregation-of-duties exceptions YTD | C25: A1,Group | D25: E07 G07 O05 | E25: 1 | F25: 0 | G25: 1 | H25: no | I25: source model
A26: CTL-008 | B26: Unauthorised-access events YTD | C26: A1,Group | D26: E07 G07 O05 | E26: 0 | F26: 0 | G26: 0 | H26: no | I26: source model
A27: CTL-009 | B27: Data-sharing exceptions YTD | C27: A1,Group | D27: E07 G07 O05 | E27: 0 | F27: 0 | G27: 0 | H27: no | I27: source model
A28: CTL-010 | B28: Manual overrides YTD | C28: A1,Group | D28: E07 G07 O05 | E28: 14 | F28: 7 | G28: 7 | H28: no | I28: source model
A29: EFF-002 | B29: Open critical alerts | C29: A1,Group | D29: E01 E09 G01 G01b G02 G07 G09 O01 X L | E29: 1 | F29: 1 | G29: 0 | H29: no | I29: source model
A30: EFF-006 | B30: Alerts without accepted owners | C30: Group | D30: G09 | E30: 1 | F30: 0 | G30: 1 | H30: no | I30: source model
A31: EFF-007 | B31: Overdue actions | C31: A1,Group | D31: E01 E09 G09 | E31: 0 | F31: 0 | G31: 0 | H31: no | I31: source model
A32: EFF-008 | B32: Average resolution time | C32: A1,Group | D32: E09 G09 O06 | E32: 2.45 | F32: 2.78 | G32: 2.06 | H32: no | I32: source model
A33: EFF-009 | B33: Closed escalations, last 30 days | C33: A1,Group | D33: E09 G09 O06 | E33: 11 | F33: 3 | G33: 8 | H33: no | I33: source model
A34: EFF-010 | B34: Repeat issues, last 90 days | C34: A1,Group | D34: E09 G09 O06 | E34: 4 | F34: 3 | G34: 1 | H34: no | I34: source model
A35: EFF-011 | B35: Root causes eliminated YTD | C35: A1,Group | D35: E09 G09 O06 | E35: 8 of 9 | F35: 4 of 4 | G35: 4 of 5 | H35: no | I35: source model
A36: EHS-001 | B36: TRIR | C36: A1,Group | D36: E07 G07 G08 O05 | E36: 0.47 | F36: 0.91 | G36: 0 | H36: yes | I36: source model
A37: EHS-002 | B37: Severity incidents | C37: A1,Group | D37: E07 G01 G01b G07 O01 O05 | E37: 3 | F37: 1 | G37: 2 | H37: yes | I37: source model
A38: EHS-003 | B38: Near misses | C38: A1,Group | D38: E07 G07 O05 | E38: 41 | F38: 20 | G38: 21 | H38: yes | I38: source model
A39: EHS-004 | B39: Critical safety incidents | C39: A1,Group | D39: E07 G07 O05 | E39: 0 | F39: 0 | G39: 0 | H39: yes | I39: source model
A40: EHS-005 | B40: Environmental excursions | C40: A1,Group | D40: E07 G07 O05 | E40: 2 | F40: 1 | G40: 1 | H40: yes | I40: source model
A41: EHS-006 | B41: Open EHS corrective actions | C41: A1,Group | D41: E07 G07 | E41: 45 | F41: 28 | G41: 17 | H41: yes | I41: source model
A42: EHS-007 | B42: Overdue EHS actions | C42: A1,Group | D42: E07 G07 O05 | E42: 9 | F42: 7 | G42: 2 | H42: yes | I42: source model
A43: EHS-008 | B43: EHS escalation clocks running | C43: A1,Group | D43: E07 G07 O05 | E43: 0 | F43: 0 | G43: 0 | H43: yes | I43: source model
A44: EHS-009 | B44: EHS investigation completion | C44: A1,Group | D44: E07 G07 | E44: 75 | F44: 75 | G44: 100 | H44: yes | I44: source model
A45: EHS-010 | B45: EHS investigation completion rate YTD | C45: Group | D45: G07 | E45: 85.42 | F45: 81.82 | G45: 88.46 | H45: yes | I45: source model
A46: FIN-001 | B46: EBITDA YTD | C46: A1,Group | D46: E01 E11 G01 G01b G02 G03 G08 G08o O01 X L | E46: 1760.09 | F46: 890.55 | G46: 869.54 | H46: no | I46: source model
...

Sheet Calculated vs Shown
A1: KPI ID | B1: Measure | C1: Unit | D1: Formula | E1: Calculated value, Sep 2026 (P06) | F1: Shown on the mockups (Group) | G1: Same or different | H1: Screens | I1: Where the inputs come from
A2: OPS-001 | B2: Production vs plan | C2: % | D2: Good output ÷ Planned production × 100 | E2: ='Group KPIs'!K2 | F2: 95.5 % of plan | G2: Different | H2: O-01, O-09, E-01, E-02, E-05, G-01, G-02, G-03, G-05, S-03, S-10, STATE GALLERY | I2: Original plant data (plant_base.csv, synthetic)
A3: OPS-003 | B3: Capacity utilization | C3: % | D3: Good output ÷ Installed capacity × 100 | E3: ='Group KPIs'!K3 | F3: 83.4 % | G3: Different | H3: O-01, E-02, G-05, STATE GALLERY | I3: Original plant data (plant_base.csv, synthetic)
A4: PLT-001 | B4: Asset utilization | C4: % | D4: Run hours ÷ Calendar hours × 100 | E4: ='Group KPIs'!K4 | F4: Not shown | G4: Not shown | I4: Original plant data (plant_base.csv, synthetic)
A5: PLT-002 | B5: OEE | C5: % | D5: Availability × Performance × Quality = Good output ÷ Ideal output × 100 | E5: ='Group KPIs'!K5 | F5: 84.1 % | G5: Different | H5: E-02, G-05 | I5: Original plant data (plant_base.csv, synthetic)
A6: PLT-004 | B6: Recovery percentage | C6: % | D6: Valuable content recovered ÷ Valuable content in feed × 100 | E6: ='Group KPIs'!K6 | F6: Not shown | G6: Not shown | I6: Original plant data (plant_base.csv, synthetic)
A7: PLT-005 | B7: Yield | C7: % | D7: Good output ÷ Feed input × 100 | E7: ='Group KPIs'!K7 | F7: Not shown | G7: Not shown | I7: Original plant data (plant_base.csv, synthetic)
A8: REL-001 | B8: MTBF | C8: h | D8: Run hours ÷ Breakdowns | E8: ='Group KPIs'!K8 | F8: 270 h | G8: Different | H8: O-09, E-03, G-05 | I8: Original plant data (plant_base.csv, synthetic)
A9: REL-002 | B9: Mean Time to Repair | C9: h | D9: Repair hours ÷ Breakdowns | E9: ='Group KPIs'!K9 | F9: 7.8 h | G9: Different | H9: E-03, G-05 | I9: Original plant data (plant_base.csv, synthetic)
A10: REL-003 | B10: Unplanned downtime | C10: h | D10: Unplanned downtime | E10: ='Group KPIs'!K10 | F10: 3.1 % of hours | G10: Different | H10: E-03, G-05 | I10: Original plant data (plant_base.csv, synthetic)
A11: REL-004 | B11: Production loss from downtime | C11: t | D11: Production lost to downtime | E11: ='Group KPIs'!K11 | F11: 93% | G11: Different | H11: E-03,G-05 | I11: Original plant data (plant_base.csv, synthetic)
A12: REL-005 | B12: Preventive-maintenance compliance | C12: % | D12: Preventive maintenance completed ÷ Preventive maintenance scheduled × 100 | E12: ='Group KPIs'!K12 | F12: 95.6 % | G12: Different | H12: E-03 | I12: Original plant data (plant_base.csv, synthetic)
A13: CST-001 | B13: Cost per tonne | C13: ₹/t | D13: (Variable cost + Fixed cost) × 1000 ÷ Good output | E13: ='Group KPIs'!K13 | F13: 2,934 ₹/t | G13: Different | H13: O-09, E-02, E-11, G-03, G-05 | I13: Original plant data (plant_base.csv, synthetic)
A14: CST-002 | B14: Variable cost | C14: ₹ thousand | D14: Variable cost | E14: ='Group KPIs'!K14 | F14: ₹214 /t | G14: Different | H14: E-02, E-11, G-03 | I14: Original plant data (plant_base.csv, synthetic)
A15: CST-003 | B15: Fuel cost | C15: ₹ thousand | D15: Fuel cost | E15: ='Group KPIs'!K15 | F15: 9.8 ₹/t | G15: Different | H15: E-02 | I15: Original plant data (plant_base.csv, synthetic)
A16: SUS-001 | B16: Water usage | C16: m3 | D16: Water used | E16: ='Group KPIs'!K16 | F16: 3.1 m³/t | G16: Different | H16: O-05, E-02, E-07, G-05, G-07 | I16: Original plant data (plant_base.csv, synthetic)
A17: SUS-002 | B17: Emissions | C17: tCO2e | D17: Emissions | E17: ='Group KPIs'!K17 | F17: 427.7 kt CO2e | G17: Different | H17: O-05, E-02, E-07, G-05, G-07 | I17: Original plant data (plant_base.csv, synthetic)
A18: SUS-003 | B18: Energy intensity | C18: GJ/t | D18: Energy used ÷ Good output | E18: ='Group KPIs'!K18 | F18: 5.2 GJ/t | G18: Different | H18: O-05, E-02, E-07, G-05, G-07 | I18: Original plant data (plant_base.csv, synthetic)
A19: SIG-007 | B19: Production at risk | C19: t | D19: Production at risk | E19: ='Group KPIs'!K19 | F19: Not shown | G19: Not shown | I19: Original plant data (plant_base.csv, synthetic)
A20: SIG-008 | B20: Critical plant-state alerts | C20: count | D20: Critical plant alerts | E20: ='Group KPIs'!K20 | F20: Not shown | G20: Not shown | I20: Original plant data (plant_base.csv, synthetic)
A21: SIG-009 | B21: Critical-material shortage risk | C21: count | D21: Critical materials at risk | E21: ='Group KPIs'!K21 | F21: 3.5 days of cover | G21: Different | H21: E-01, E-04, S-10, S-12 | I21: Original plant data (plant_base.csv, synthetic)
A22: SIG-012 | B22: Dispatch delays | C22: % | D22: Delayed dispatches ÷ Dispatches × 100 | E22: ='Group KPIs'!K22 | F22: 2–4 days | G22: Different | H22: E-05,S-11,S-12 | I22: Original plant data (plant_base.csv, synthetic)
A23: SIG-021 | B23: Environmental violations | C23: count | D23: Environmental violations | E23: ='Group KPIs'!K23 | F23: Not shown | G23: Not shown | I23: Original plant data (plant_base.csv, synthetic)
A24: EHS-001 | B24: TRIR | C24: per 200,000 h | D24: Recordable injuries × 200,000 ÷ Hours worked | E24: ='Group KPIs'!K24 | F24: 0.42 | G24: Different | H24: E-07,G-07,O-05 | I24: Original plant data (plant_base.csv, synthetic)
A25: EHS-002 | B25: Severity incidents | C25: count | D25: Severity incidents | E25: ='Group KPIs'!K25 | F25: 0 | G25: Different | H25: E-07,G-01,G-07,O-05 | I25: Original plant data (plant_base.csv, synthetic)
A26: EHS-003 | B26: Near misses | C26: count | D26: Near misses | E26: ='Group KPIs'!K26 | F26: 14 | G26: Different | H26: E-07,G-07,O-05 | I26: Original plant data (plant_base.csv, synthetic)
A27: EHS-004 | B27: Critical safety incidents | C27: count | D27: Critical safety incidents | E27: ='Group KPIs'!K27 | F27: 0 | G27: Same | H27: E-07,G-07,O-05 | I27: Original plant data (plant_base.csv, synthetic)
A28: EHS-005 | B28: Environmental excursions | C28: count | D28: Environmental excursions | E28: ='Group KPIs'!K28 | F28: 1 (minor, closed) | G28: Different | H28: E-07,G-07,O-05 | I28: Original plant data (plant_base.csv, synthetic)
A29: EHS-006 | B29: Open EHS corrective actions | C29: count | D29: Open EHS corrective actions | E29: ='Group KPIs'!K29 | F29: 9 | G29: Different | H29: E-07,G-07 | I29: Original plant data (plant_base.csv, synthetic)
A30: EHS-007 | B30: Overdue EHS actions | C30: count | D30: Overdue EHS corrective actions | E30: ='Group KPIs'!K30 | F30: 0 | G30: Different | H30: E-07,G-07,O-05 | I30: Original plant data (plant_base.csv, synthetic)
A31: EHS-009 | B31: EHS investigation completion | C31: % | D31: EHS investigations completed ÷ EHS investigations due × 100 (100 if none due) | E31: ='Group KPIs'!K31 | F31: 100% | G31: Different | H31: E-07,G-07 | I31: Original plant data (plant_base.csv, synthetic)
A32: REG-006 | B32: Licence or permit expiry clock | C32: days | D32: Days to permit expiry (lowest plant) | E32: ='Group KPIs'!K32 | F32: 74 days · Entity C1 | G32: Different | H32: E-07,O-05 | I32: Original plant data (plant_base.csv, synthetic)
A33: OPS-005 | B33: Capacity utilisation (same measure as OPS-003) | C33: % | D33: Good output ÷ Installed capacity × 100 | E33: ='Group KPIs'!K33 | F33: 86% | G33: Different | H33: O-01, E-01, G-01 | I33: Original plant data (plant_base.csv, synthetic)
A34: OPS-006 | B34: OEE · Group weighted (same measure as PLT-002) | C34: % | D34: Good output ÷ Ideal output × 100 (weighted by output, not an average of plants) | E34: ='Group KPIs'!K34 | F34: Not on a screen | G34: — | H34: — | I34: Original plant data (plant_base.csv, synthetic)
A35: OPS-002 | B35: Sales vs plan | C35: % | D35: Sales volume ÷ Planned sales volume × 100 | E35: ='Group KPIs'!K35 | F35: 97.6% | G35: Different | H35: E-01,G-01,G-03,O-01,STATE GALLERY | I35: Synthetic inputs added for this model
... A82: SUP-002 | B82: Supplier fill rate | C82: % | D82: Quantity received ÷ Quantity ordered × 100 | E82: ='Group KPIs'!K82 | F82: Not on a screen | G82: — | H82: — | I82: Synthetic inputs added for this model
A83: SUP-003 | B83: Supplier quality-rejection rate | C83: % | D83: Quantity rejected ÷ Quantity received × 100 | E83: ='Group KPIs'!K83 | F83: Not shown | G83: Not shown | I83: Synthetic inputs added for this model
A84: SUP-004 | B84: Supplier lead-time variance | C84: % | D84: (Actual lead time − Planned lead time) ÷ Planned lead time × 100 | E84: ='Group KPIs'!K84 | F84: 38% | G84: Different | H84: E-04,G-05 | I84: Synthetic inputs added for this model
A85: SUP-005 | B85: Critical supplier exposure | C85: count | D85: Critical single-source suppliers [Month end] | E85: ='Group KPIs'!K85 | F85: 3 single-source (1 elevated: S-07) | G85: Same | H85: E-04,G-05 | I85: Synthetic inputs added for this model
A86: SUP-007 | B86: Single-source spend share | C86: % | D86: Spend with single-source suppliers ÷ Supplier spend × 100 | E86: ='Group KPIs'!K86 | F86: Not on a screen | G86: — | H86: — | I86: Synthetic inputs added for this model
...

Sheet Group KPIs
A1: KPI ID | B1: Measure | C1: Unit | D1: Time basis | E1: How it is calculated | F1: 2026-04 (P01) | G1: 2026-05 (P02) | H1: 2026-06 (P03) | I1: 2026-07 (P04) | J1: 2026-08 (P05) | K1: 2026-09 (P06) | L1: Shown on the mockups today (Group) | M1: Screens | N1: Inputs used (Group Inputs columns)
A2: OPS-001 | B2: Production vs plan | C2: % | D2: Month | E2: Good output ÷ Planned production × 100 | F2: =ROUND(IFERROR(100*'Group Inputs'!M4/'Group Inputs'!K4,0),2) | G2: =ROUND(IFERROR(100*'Group Inputs'!M5/'Group Inputs'!K5,0),2) | H2: =ROUND(IFERROR(100*'Group Inputs'!M6/'Group Inputs'!K6,0),2) | I2: =ROUND(IFERROR(100*'Group Inputs'!M7/'Group Inputs'!K7,0),2) | J2: =ROUND(IFERROR(100*'Group Inputs'!M8/'Group Inputs'!K8,0),2) | K2: =ROUND(IFERROR(100*'Group Inputs'!M9/'Group Inputs'!K9,0),2) | L2: 98.1%; 95.5 % of plan (O-09) | M2: O-01, O-09, E-01, E-02, E-05, G-01, G-02, G-03, G-05, S-03, S-10, STATE GALLERY | N2: planned_production_t, good_output_t
A3: OPS-003 | B3: Capacity utilization | C3: % | D3: Month | E3: Good output ÷ Installed capacity × 100 | F3: =ROUND(IFERROR(100*'Group Inputs'!M4/'Group Inputs'!J4,0),2) | G3: =ROUND(IFERROR(100*'Group Inputs'!M5/'Group Inputs'!J5,0),2) | H3: =ROUND(IFERROR(100*'Group Inputs'!M6/'Group Inputs'!J6,0),2) | I3: =ROUND(IFERROR(100*'Group Inputs'!M7/'Group Inputs'!J7,0),2) | J3: =ROUND(IFERROR(100*'Group Inputs'!M8/'Group Inputs'!J8,0),2) | K3: =ROUND(IFERROR(100*'Group Inputs'!M9/'Group Inputs'!J9,0),2) | L3: 86% | M3: O-01, E-02, G-05, STATE GALLERY | N3: installed_capacity_t, good_output_t
A4: PLT-001 | B4: Asset utilization | C4: % | D4: Month | E4: Run hours ÷ Calendar hours × 100 | F4: =ROUND(IFERROR(100*'Group Inputs'!G4/'Group Inputs'!E4,0),2) | G4: =ROUND(IFERROR(100*'Group Inputs'!G5/'Group Inputs'!E5,0),2) | H4: =ROUND(IFERROR(100*'Group Inputs'!G6/'Group Inputs'!E6,0),2) | I4: =ROUND(IFERROR(100*'Group Inputs'!G7/'Group Inputs'!E7,0),2) | J4: =ROUND(IFERROR(100*'Group Inputs'!G8/'Group Inputs'!E8,0),2) | K4: =ROUND(IFERROR(100*'Group Inputs'!G9/'Group Inputs'!E9,0),2) | L4: Not shown | N4: calendar_hours, run_hours
A5: PLT-002 | B5: OEE | C5: % | D5: Month | E5: Availability × Performance × Quality = Good output ÷ Ideal output × 100 | F5: =ROUND(IFERROR(100*'Group Inputs'!M4/'Group Inputs'!I4,0),2) | G5: =ROUND(IFERROR(100*'Group Inputs'!M5/'Group Inputs'!I5,0),2) | H5: =ROUND(IFERROR(100*'Group Inputs'!M6/'Group Inputs'!I6,0),2) | I5: =ROUND(IFERROR(100*'Group Inputs'!M7/'Group Inputs'!I7,0),2) | J5: =ROUND(IFERROR(100*'Group Inputs'!M8/'Group Inputs'!I8,0),2) | K5: =ROUND(IFERROR(100*'Group Inputs'!M9/'Group Inputs'!I9,0),2) | L5: 78 % | M5: E-02, G-05 | N5: ideal_output_t, good_output_t
A6: PLT-004 | B6: Recovery percentage | C6: % | D6: Month | E6: Valuable content recovered ÷ Valuable content in feed × 100 | F6: =ROUND(IFERROR(100*'Group Inputs'!P4/'Group Inputs'!O4,0),2) | G6: =ROUND(IFERROR(100*'Group Inputs'!P5/'Group Inputs'!O5,0),2) | H6: =ROUND(IFERROR(100*'Group Inputs'!P6/'Group Inputs'!O6,0),2) | I6: =ROUND(IFERROR(100*'Group Inputs'!P7/'Group Inputs'!O7,0),2) | J6: =ROUND(IFERROR(100*'Group Inputs'!P8/'Group Inputs'!O8,0),2) | K6: =ROUND(IFERROR(100*'Group Inputs'!P9/'Group Inputs'!O9,0),2) | L6: Not shown | N6: feed_contained_t, recovered_contained_t
A7: PLT-005 | B7: Yield | C7: % | D7: Month | E7: Good output ÷ Feed input × 100 | F7: =ROUND(IFERROR(100*'Group Inputs'!M4/'Group Inputs'!N4,0),2) | G7: =ROUND(IFERROR(100*'Group Inputs'!M5/'Group Inputs'!N5,0),2) | H7: =ROUND(IFERROR(100*'Group Inputs'!M6/'Group Inputs'!N6,0),2) | I7: =ROUND(IFERROR(100*'Group Inputs'!M7/'Group Inputs'!N7,0),2) | J7: =ROUND(IFERROR(100*'Group Inputs'!M8/'Group Inputs'!N8,0),2) | K7: =ROUND(IFERROR(100*'Group Inputs'!M9/'Group Inputs'!N9,0),2) | L7: Not shown | N7: good_output_t, feed_input_t
A8: REL-001 | B8: MTBF | C8: h | D8: Month | E8: Run hours ÷ Breakdowns | F8: =ROUND(IFERROR('Group Inputs'!G4/'Group Inputs'!R4,0),2) | G8: =ROUND(IFERROR('Group Inputs'!G5/'Group Inputs'!R5,0),2) | H8: =ROUND(IFERROR('Group Inputs'!G6/'Group Inputs'!R6,0),2) | I8: =ROUND(IFERROR('Group Inputs'!G7/'Group Inputs'!R7,0),2) | J8: =ROUND(IFERROR('Group Inputs'!G8/'Group Inputs'!R8,0),2) | K8: =ROUND(IFERROR('Group Inputs'!G9/'Group Inputs'!R9,0),2) | L8: 205 h; 270 h (O-09) | M8: O-09, E-03, G-05 | N8: run_hours, failures
A9: REL-002 | B9: Mean Time to Repair | C9: h | D9: Month | E9: Repair hours ÷ Breakdowns | F9: =ROUND(IFERROR('Group Inputs'!S4/'Group Inputs'!R4,0),2) | G9: =ROUND(IFERROR('Group Inputs'!S5/'Group Inputs'!R5,0),2) | H9: =ROUND(IFERROR('Group Inputs'!S6/'Group Inputs'!R6,0),2) | I9: =ROUND(IFERROR('Group Inputs'!S7/'Group Inputs'!R7,0),2) | J9: =ROUND(IFERROR('Group Inputs'!S8/'Group Inputs'!R8,0),2) | K9: =ROUND(IFERROR('Group Inputs'!S9/'Group Inputs'!R9,0),2) | L9: 3.6 h | M9: E-03, G-05 | N9: failures, repair_hours
A10: REL-003 | B10: Unplanned downtime | C10: h | D10: Month | E10: Unplanned downtime | F10: =ROUND('Group Inputs'!H4,2) | G10: =ROUND('Group Inputs'!H5,2) | H10: =ROUND('Group Inputs'!H6,2) | I10: =ROUND('Group Inputs'!H7,2) | J10: =ROUND('Group Inputs'!H8,2) | K10: =ROUND('Group Inputs'!H9,2) | L10: 3.1 % of hours | M10: E-03, G-05 | N10: unplanned_downtime_hours
A11: REL-004 | B11: Production loss from downtime | C11: t | D11: Month | E11: Production lost to downtime | F11: =ROUND('Group Inputs'!Q4,2) | G11: =ROUND('Group Inputs'!Q5,2) | H11: =ROUND('Group Inputs'!Q6,2) | I11: =ROUND('Group Inputs'!Q7,2) | J11: =ROUND('Group Inputs'!Q8,2) | K11: =ROUND('Group Inputs'!Q9,2) | L11: 93% | M11: E-03,G-05 | N11: prod_loss_downtime_t
A12: REL-005 | B12: Preventive-maintenance compliance | C12: % | D12: Month | E12: Preventive maintenance completed ÷ Preventive maintenance scheduled × 100 | F12: =ROUND(IFERROR(100*'Group Inputs'!U4/'Group Inputs'!T4,0),2) | G12: =ROUND(IFERROR(100*'Group Inputs'!U5/'Group Inputs'!T5,0),2) | H12: =ROUND(IFERROR(100*'Group Inputs'!U6/'Group Inputs'!T6,0),2) | I12: =ROUND(IFERROR(100*'Group Inputs'!U7/'Group Inputs'!T7,0),2) | J12: =ROUND(IFERROR(100*'Group Inputs'!U8/'Group Inputs'!T8,0),2) | K12: =ROUND(IFERROR(100*'Group Inputs'!U9/'Group Inputs'!T9,0),2) | L12: 93% | M12: E-03 | N12: pm_scheduled, pm_completed
A13: CST-001 | B13: Cost per tonne | C13: ₹/t | D13: Month | E13: (Variable cost + Fixed cost) × 1000 ÷ Good output | F13: =ROUND(IFERROR(1000*('Group Inputs'!V4+'Group Inputs'!X4)/'Group Inputs'!M4,0),2) | G13: =ROUND(IFERROR(1000*('Group Inputs'!V5+'Group Inputs'!X5)/'Group Inputs'!M5,0),2) | H13: =ROUND(IFERROR(1000*('Group Inputs'!V6+'Group Inputs'!X6)/'Group Inputs'!M6,0),2) | I13: =ROUND(IFERROR(1000*('Group Inputs'!V7+'Group Inputs'!X7)/'Group Inputs'!M7,0),2) | J13: =ROUND(IFERROR(1000*('Group Inputs'!V8+'Group Inputs'!X8)/'Group Inputs'!M8,0),2) | K13: =ROUND(IFERROR(1000*('Group Inputs'!V9+'Group Inputs'!X9)/'Group Inputs'!M9,0),2) | L13: ₹412 /t; 2,934 ₹/t (O-09) | M13: O-09, E-02, E-11, G-03, G-05 | N13: good_output_t, variable_cost_k, fixed_cost_k
A14: CST-002 | B14: Variable cost | C14: ₹ thousand | D14: Month | E14: Variable cost | F14: =ROUND('Group Inputs'!V4,2) | G14: =ROUND('Group Inputs'!V5,2) | H14: =ROUND('Group Inputs'!V6,2) | I14: =ROUND('Group Inputs'!V7,2) | J14: =ROUND('Group Inputs'!V8,2) | K14: =ROUND('Group Inputs'!V9,2) | L14: ₹214 /t | M14: E-02, E-11, G-03 | N14: variable_cost_k
A15: CST-003 | B15: Fuel cost | C15: ₹ thousand | D15: Month | E15: Fuel cost | F15: =ROUND('Group Inputs'!W4,2) | G15: =ROUND('Group Inputs'!W5,2) | H15: =ROUND('Group Inputs'!W6,2) | I15: =ROUND('Group Inputs'!W7,2) | J15: =ROUND('Group Inputs'!W8,2) | K15: =ROUND('Group Inputs'!W9,2) | L15: 9.8 ₹/t | M15: E-02 | N15: fuel_cost_k
A16: SUS-001 | B16: Water usage | C16: m3 | D16: Month | E16: Water used | F16: =ROUND('Group Inputs'!Y4,2) | G16: =ROUND('Group Inputs'!Y5,2) | H16: =ROUND('Group Inputs'!Y6,2) | I16: =ROUND('Group Inputs'!Y7,2) | J16: =ROUND('Group Inputs'!Y8,2) | K16: =ROUND('Group Inputs'!Y9,2) | L16: 3.1 m³/t | M16: O-05, E-02, E-07, G-05, G-07 | N16: water_m3
A17: SUS-002 | B17: Emissions | C17: tCO2e | D17: Month | E17: Emissions | F17: =ROUND('Group Inputs'!Z4,2) | G17: =ROUND('Group Inputs'!Z5,2) | H17: =ROUND('Group Inputs'!Z6,2) | I17: =ROUND('Group Inputs'!Z7,2) | J17: =ROUND('Group Inputs'!Z8,2) | K17: =ROUND('Group Inputs'!Z9,2) | L17: 0.82 tCO2e/t | M17: O-05, E-02, E-07, G-05, G-07 | N17: emissions_tco2e
A18: SUS-003 | B18: Energy intensity | C18: GJ/t | D18: Month | E18: Energy used ÷ Good output | F18: =ROUND(IFERROR('Group Inputs'!AA4/'Group Inputs'!M4,0),2) | G18: =ROUND(IFERROR('Group Inputs'!AA5/'Group Inputs'!M5,0),2) | H18: =ROUND(IFERROR('Group Inputs'!AA6/'Group Inputs'!M6,0),2) | I18: =ROUND(IFERROR('Group Inputs'!AA7/'Group Inputs'!M7,0),2) | J18: =ROUND(IFERROR('Group Inputs'!AA8/'Group Inputs'!M8,0),2) | K18: =ROUND(IFERROR('Group Inputs'!AA9/'Group Inputs'!M9,0),2) | L18: 5.2 GJ/t | M18: O-05, E-02, E-07, G-05, G-07 | N18: good_output_t, energy_gj
A19: SIG-007 | B19: Production at risk | C19: t | D19: Month | E19: Production at risk | F19: =ROUND('Group Inputs'!AB4,2) | G19: =ROUND('Group Inputs'!AB5,2) | H19: =ROUND('Group Inputs'!AB6,2) | I19: =ROUND('Group Inputs'!AB7,2) | J19: =ROUND('Group Inputs'!AB8,2) | K19: =ROUND('Group Inputs'!AB9,2) | L19: Not shown | N19: production_at_risk_t
A20: SIG-008 | B20: Critical plant-state alerts | C20: count | D20: Month | E20: Critical plant alerts | F20: =ROUND('Group Inputs'!AC4,2) | G20: =ROUND('Group Inputs'!AC5,2) | H20: =ROUND('Group Inputs'!AC6,2) | I20: =ROUND('Group Inputs'!AC7,2) | J20: =ROUND('Group Inputs'!AC8,2) | K20: =ROUND('Group Inputs'!AC9,2) | L20: Not shown | N20: critical_plant_alerts
A21: SIG-009 | B21: Critical-material shortage risk | C21: count | D21: Month | E21: Critical materials at risk | F21: =ROUND('Group Inputs'!AO4,2) | G21: =ROUND('Group Inputs'!AO5,2) | H21: =ROUND('Group Inputs'!AO6,2) | I21: =ROUND('Group Inputs'!AO7,2) | J21: =ROUND('Group Inputs'!AO8,2) | K21: =ROUND('Group Inputs'!AO9,2) | L21: 3.5 days of cover | M21: E-01, E-04, S-10, S-12 | N21: critical_material_risks
A22: SIG-012 | B22: Dispatch delays | C22: % | D22: Month | E22: Delayed dispatches ÷ Dispatches × 100 | F22: =ROUND(IFERROR(100*'Group Inputs'!AQ4/'Group Inputs'!AP4,0),2) | G22: =ROUND(IFERROR(100*'Group Inputs'!AQ5/'Group Inputs'!AP5,0),2) | H22: =ROUND(IFERROR(100*'Group Inputs'!AQ6/'Group Inputs'!AP6,0),2) | I22: =ROUND(IFERROR(100*'Group Inputs'!AQ7/'Group Inputs'!AP7,0),2) | J22: =ROUND(IFERROR(100*'Group Inputs'!AQ8/'Group Inputs'!AP8,0),2) | K22: =ROUND(IFERROR(100*'Group Inputs'!AQ9/'Group Inputs'!AP9,0),2) | L22: 2–4 days | M22: E-05,S-11,S-12 | N22: dispatches_total, dispatches_delayed
A23: SIG-021 | B23: Environmental violations | C23: count | D23: Month | E23: Environmental violations | F23: =ROUND('Group Inputs'!AJ4,2) | G23: =ROUND('Group Inputs'!AJ5,2) | H23: =ROUND('Group Inputs'!AJ6,2) | I23: =ROUND('Group Inputs'!AJ7,2) | J23: =ROUND('Group Inputs'!AJ8,2) | K23: =ROUND('Group Inputs'!AJ9,2) | L23: Not shown | N23: env_violations
A24: EHS-001 | B24: TRIR | C24: per 200,000 h | D24: Month | E24: Recordable injuries × 200,000 ÷ Hours worked | F24: =ROUND(IFERROR(200000*'Group Inputs'!AE4/'Group Inputs'!AD4,0),2) | G24: =ROUND(IFERROR(200000*'Group Inputs'!AE5/'Group Inputs'!AD5,0),2) | H24: =ROUND(IFERROR(200000*'Group Inputs'!AE6/'Group Inputs'!AD6,0),2) | I24: =ROUND(IFERROR(200000*'Group Inputs'!AE7/'Group Inputs'!AD7,0),2) | J24: =ROUND(IFERROR(200000*'Group Inputs'!AE8/'Group Inputs'!AD8,0),2) | K24: =ROUND(IFERROR(200000*'Group Inputs'!AE9/'Group Inputs'!AD9,0),2) | L24: 0.42 | M24: E-07,G-07,O-05 | N24: hours_worked, recordable_injuries
A25: EHS-002 | B25: Severity incidents | C25: count | D25: Month | E25: Severity incidents | F25: =ROUND('Group Inputs'!AF4,2) | G25: =ROUND('Group Inputs'!AF5,2) | H25: =ROUND('Group Inputs'!AF6,2) | I25: =ROUND('Group Inputs'!AF7,2) | J25: =ROUND('Group Inputs'!AF8,2) | K25: =ROUND('Group Inputs'!AF9,2) | L25: 0 | M25: E-07,G-01,G-07,O-05 | N25: severity_incidents
A26: EHS-003 | B26: Near misses | C26: count | D26: Month | E26: Near misses | F26: =ROUND('Group Inputs'!AG4,2) | G26: =ROUND('Group Inputs'!AG5,2) | H26: =ROUND('Group Inputs'!AG6,2) | I26: =ROUND('Group Inputs'!AG7,2) | J26: =ROUND('Group Inputs'!AG8,2) | K26: =ROUND('Group Inputs'!AG9,2) | L26: 14 | M26: E-07,G-07,O-05 | N26: near_misses
A27: EHS-004 | B27: Critical safety incidents | C27: count | D27: Month | E27: Critical safety incidents | F27: =ROUND('Group Inputs'!AH4,2) | G27: =ROUND('Group Inputs'!AH5,2) | H27: =ROUND('Group Inputs'!AH6,2) | I27: =ROUND('Group Inputs'!AH7,2) | J27: =ROUND('Group Inputs'!AH8,2) | K27: =ROUND('Group Inputs'!AH9,2) | L27: 0 | M27: E-07,G-07,O-05 | N27: critical_safety_incidents
A28: EHS-005 | B28: Environmental excursions | C28: count | D28: Month | E28: Environmental excursions | F28: =ROUND('Group Inputs'!AI4,2) | G28: =ROUND('Group Inputs'!AI5,2) | H28: =ROUND('Group Inputs'!AI6,2) | I28: =ROUND('Group Inputs'!AI7,2) | J28: =ROUND('Group Inputs'!AI8,2) | K28: =ROUND('Group Inputs'!AI9,2) | L28: 1 (minor, closed) | M28: E-07,G-07,O-05 | N28: env_excursions
A29: EHS-006 | B29: Open EHS corrective actions | C29: count | D29: Month | E29: Open EHS corrective actions | F29: =ROUND('Group Inputs'!AK4,2) | G29: =ROUND('Group Inputs'!AK5,2) | H29: =ROUND('Group Inputs'!AK6,2) | I29: =ROUND('Group Inputs'!AK7,2) | J29: =ROUND('Group Inputs'!AK8,2) | K29: =ROUND('Group Inputs'!AK9,2) | L29: 9 | M29: E-07,G-07 | N29: ehs_ca_open
A30: EHS-007 | B30: Overdue EHS actions | C30: count | D30: Month | E30: Overdue EHS corrective actions | F30: =ROUND('Group Inputs'!AL4,2) | G30: =ROUND('Group Inputs'!AL5,2) | H30: =ROUND('Group Inputs'!AL6,2) | I30: =ROUND('Group Inputs'!AL7,2) | J30: =ROUND('Group Inputs'!AL8,2) | K30: =ROUND('Group Inputs'!AL9,2) | L30: 0 | M30: E-07,G-07,O-05 | N30: ehs_ca_overdue
A31: EHS-009 | B31: EHS investigation completion | C31: % | D31: Month | E31: EHS investigations completed ÷ EHS investigations due × 100 (100 if none due) | F31: =ROUND(IF('Group Inputs'!AM4=0,100,100*'Group Inputs'!AN4/'Group Inputs'!AM4),2) | G31: =ROUND(IF('Group Inputs'!AM5=0,100,100*'Group Inputs'!AN5/'Group Inputs'!AM5),2) | H31: =ROUND(IF('Group Inputs'!AM6=0,100,100*'Group Inputs'!AN6/'Group Inputs'!AM6),2) | I31: =ROUND(IF('Group Inputs'!AM7=0,100,100*'Group Inputs'!AN7/'Group Inputs'!AM7),2) | J31: =ROUND(IF('Group Inputs'!AM8=0,100,100*'Group Inputs'!AN8/'Group Inputs'!AM8),2) | K31: =ROUND(IF('Group Inputs'!AM9=0,100,100*'Group Inputs'!AN9/'Group Inputs'!AM9),2) | L31: 100% | M31: E-07,G-07 | N31: investigations_due, investigations_completed
A32: REG-006 | B32: Licence or permit expiry clock | C32: days | D32: Month | E32: Days to permit expiry (lowest plant) | F32: =ROUND('Group Inputs'!AR4,2) | G32: =ROUND('Group Inputs'!AR5,2) | H32: =ROUND('Group Inputs'!AR6,2) | I32: =ROUND('Group Inputs'!AR7,2) | J32: =ROUND('Group Inputs'!AR8,2) | K32: =ROUND('Group Inputs'!AR9,2) | L32: 74 days · Entity C1 | M32: E-07,O-05 | N32: permit_days_to_expiry
A33: OPS-005 | B33: Capacity utilisation (same measure as OPS-003) | C33: % | D33: Month | E33: Good output ÷ Installed capacity × 100 | F33: =ROUND(IFERROR(100*'Group Inputs'!M4/'Group Inputs'!J4,0),2) | G33: =ROUND(IFERROR(100*'Group Inputs'!M5/'Group Inputs'!J5,0),2) | H33: =ROUND(IFERROR(100*'Group Inputs'!M6/'Group Inputs'!J6,0),2) | I33: =ROUND(IFERROR(100*'Group Inputs'!M7/'Group Inputs'!J7,0),2) | J33: =ROUND(IFERROR(100*'Group Inputs'!M8/'Group Inputs'!J8,0),2) | K33: =ROUND(IFERROR(100*'Group Inputs'!M9/'Group Inputs'!J9,0),2) | L33: 86% | M33: O-01, E-01, G-01 | N33: installed_capacity_t, good_output_t
A34: OPS-006 | B34: OEE · Group weighted (same measure as PLT-002) | C34: % | D34: Month | E34: Good output ÷ Ideal output × 100 (weighted by output, not an average of plants) | F34: =ROUND(IFERROR(100*'Group Inputs'!M4/'Group Inputs'!I4,0),2) | G34: =ROUND(IFERROR(100*'Group Inputs'!M5/'Group Inputs'!I5,0),2) | H34: =ROUND(IFERROR(100*'Group Inputs'!M6/'Group Inputs'!I6,0),2) | I34: =ROUND(IFERROR(100*'Group Inputs'!M7/'Group Inputs'!I7,0),2) | J34: =ROUND(IFERROR(100*'Group Inputs'!M8/'Group Inputs'!I8,0),2) | K34: =ROUND(IFERROR(100*'Group Inputs'!M9/'Group Inputs'!I9,0),2) | L34: 78.4 % | M34: — | N34: ideal_output_t, good_output_t
A35: OPS-002 | B35: Sales vs plan | C35: % | D35: Month | E35: Sales volume ÷ Planned sales volume × 100 | F35: =ROUND(IF('Group Inputs'!AT4=0,0,100*'Group Inputs'!AS4/'Group Inputs'!AT4),2) | G35: =ROUND(IF('Group Inputs'!AT5=0,0,100*'Group Inputs'!AS5/'Group Inputs'!AT5),2) | H35: =ROUND(IF('Group Inputs'!AT6=0,0,100*'Group Inputs'!AS6/'Group Inputs'!AT6),2) | I35: =ROUND(IF('Group Inputs'!AT7=0,0,100*'Group Inputs'!AS7/'Group Inputs'!AT7),2) | J35: =ROUND(IF('Group Inputs'!AT8=0,0,100*'Group Inputs'!AS8/'Group Inputs'!AT8),2) | K35: =ROUND(IF('Group Inputs'!AT9=0,0,100*'Group Inputs'!AS9/'Group Inputs'!AT9),2) | L35: 97.6% | M35: E-01,G-01,G-03,O-01,STATE GALLERY | N35: sales_t, planned_sales_t
A36: OPS-004 | B36: Sales vs plan · Group (same measure as OPS-002) | C36: % | D36: Month | E36: Sales volume ÷ Planned sales volume × 100 | F36: =ROUND(IF('Group Inputs'!AT4=0,0,100*'Group Inputs'!AS4/'Group Inputs'!AT4),2) | G36: =ROUND(IF('Group Inputs'!AT5=0,0,100*'Group Inputs'!AS5/'Group Inputs'!AT5),2) | H36: =ROUND(IF('Group Inputs'!AT6=0,0,100*'Group Inputs'!AS6/'Group Inputs'!AT6),2) | I36: =ROUND(IF('Group Inputs'!AT7=0,0,100*'Group Inputs'!AS7/'Group Inputs'!AT7),2) | J36: =ROUND(IF('Group Inputs'!AT8=0,0,100*'Group Inputs'!AS8/'Group Inputs'!AT8),2) | K36: =ROUND(IF('Group Inputs'!AT9=0,0,100*'Group Inputs'!AS9/'Group Inputs'!AT9),2) | L36: 97.6% | M36: O-01 | N36: sales_t, planned_sales_t
A37: CST-004 | B37: Power cost per tonne | C37: ₹/t | D37: Month | E37: Power cost × 1000 ÷ Good output | F37: =ROUND(IF('Group Inputs'!M4=0,0,1000*'Group Inputs'!AW4/'Group Inputs'!M4),2) | G37: =ROUND(IF('Group Inputs'!M5=0,0,1000*'Group Inputs'!AW5/'Group Inputs'!M5),2) | H37: =ROUND(IF('Group Inputs'!M6=0,0,1000*'Group Inputs'!AW6/'Group Inputs'!M6),2) | I37: =ROUND(IF('Group Inputs'!M7=0,0,1000*'Group Inputs'!AW7/'Group Inputs'!M7),2) | J37: =ROUND(IF('Group Inputs'!M8=0,0,1000*'Group Inputs'!AW8/'Group Inputs'!M8),2) | K37: =ROUND(IF('Group Inputs'!M9=0,0,1000*'Group Inputs'!AW9/'Group Inputs'!M9),2) | L37: 6.1 ₹/t; 174 ₹/t (O-09) | M37: O-09 | N37: good_output_t, power_cost_k
A38: FIN-001 | B38: EBITDA YTD | C38: ₹ m | D38: Year to date | E38: Sum of monthly EBITDA since April ÷ 1000 | F38: =ROUND(SUM('Group Inputs'!FV$4:FV4)/1000,2) | G38: =ROUND(SUM('Group Inputs'!FV$4:FV5)/1000,2) | H38: =ROUND(SUM('Group Inputs'!FV$4:FV6)/1000,2) | I38: =ROUND(SUM('Group Inputs'!FV$4:FV7)/1000,2) | J38: =ROUND(SUM('Group Inputs'!FV$4:FV8)/1000,2) | K38: =ROUND(SUM('Group Inputs'!FV$4:FV9)/1000,2) | L38: 361.3 ₹ m | M38: E-01,E-11,G-01,G-02,G-03,O-01,STATE GALLERY | N38: ebitda_k
A39: FIN-002 | B39: EBIT YTD | C39: ₹ m | D39: Year to date | E39: Sum of monthly EBIT since April ÷ 1000 | F39: =ROUND(SUM('Group Inputs'!FW$4:FW4)/1000,2) | G39: =ROUND(SUM('Group Inputs'!FW$4:FW5)/1000,2) | H39: =ROUND(SUM('Group Inputs'!FW$4:FW6)/1000,2) | I39: =ROUND(SUM('Group Inputs'!FW$4:FW7)/1000,2) | J39: =ROUND(SUM('Group Inputs'!FW$4:FW8)/1000,2) | K39: =ROUND(SUM('Group Inputs'!FW$4:FW9)/1000,2) | L39: 238.4 ₹ m | M39: E-01,E-11,G-01,G-03,O-01,STATE GALLERY | N39: ebit_k
A40: FIN-003 | B40: Revenue YTD | C40: ₹ m | D40: Year to date | E40: Sum of monthly Revenue since April ÷ 1000 | F40: =ROUND(SUM('Group Inputs'!AU$4:AU4)/1000,2) | G40: =ROUND(SUM('Group Inputs'!AU$4:AU5)/1000,2) | H40: =ROUND(SUM('Group Inputs'!AU$4:AU6)/1000,2) | I40: =ROUND(SUM('Group Inputs'!AU$4:AU7)/1000,2) | J40: =ROUND(SUM('Group Inputs'!AU$4:AU8)/1000,2) | K40: =ROUND(SUM('Group Inputs'!AU$4:AU9)/1000,2) | L40: 2,410 ₹ m | M40: E-01,E-11,G-01,G-02,G-03,O-01,STATE GALLERY | N40: revenue_k
...

Sheet Group Inputs
A1: Group | B1: Month | C1: Days in month | D1: Months since April (YTD) | E1: Calendar hours (h) | F1: Planned operating hours (h) | G1: Run hours (h) | H1: Unplanned downtime (h) | I1: Ideal output (t) | J1: Installed capacity (t) | K1: Planned production (t) | L1: Gross output (t) | M1: Good output (t) | N1: Feed input (t) | O1: Valuable content in feed (t) | P1: Valuable content recovered (t) | Q1: Production lost to downtime (t) | R1: Breakdowns (count) | S1: Repair hours (h) | T1: Preventive maintenance scheduled (count) | U1: Preventive maintenance completed (count) | V1: Variable cost (₹ thousand) | W1: Fuel cost (₹ thousand) | X1: Fixed cost (₹ thousand) | Y1: Water used (m³) | Z1: Emissions (t CO2e) | AA1: Energy used (GJ) | AB1: Production at risk (t) | AC1: Critical plant alerts (count) | AD1: Hours worked (h) | AE1: Recordable injuries (count) | AF1: Severity incidents (count) | AG1: Near misses (count) | AH1: Critical safety incidents (count) | AI1: Environmental excursions (count) | AJ1: Environmental violations (count) | AK1: Open EHS corrective actions (count) | AL1: Overdue EHS corrective actions (count) | AM1: EHS investigations due (count) | AN1: EHS investigations completed (count) | AO1: Critical materials at risk (count) | AP1: Dispatches (count) | AQ1: Delayed dispatches (count) | AR1: Days to permit expiry (days) | AS1: Sales volume (t) | AT1: Planned sales volume (t) | AU1: Revenue (₹ thousand) | AV1: Planned revenue (₹ thousand) | AW1: Power cost, part of variable cost (₹ thousand) | AX1: Depreciation and amortisation (₹ thousand) | AY1: Purchase-order lines due (count) | AZ1: Purchase-order lines delivered on time (count) | BA1: Quantity ordered from suppliers (t) | BB1: Quantity received (t) | BC1: Quantity rejected on quality (t) | BD1: Planned lead time, all deliveries (days) | BE1: Actual lead time, all deliveries (days) | BF1: Supplier spend (₹ thousand) | BG1: Spend with single-source suppliers (₹ thousand) | BH1: Supplier EHS incidents (count) | BI1: Regulatory filings pending (count) | BJ1: Regulatory deadlines in next 30 days (count) | BK1: Licences expiring in next 12 months (count) | BL1: Regulatory obligations due in next 30 days (count) | BM1: Regulatory obligations overdue (count) | BN1: Open regulatory actions (count) | BO1: Overdue compliance actions (count) | BP1: Regulatory breaches in the month (count) | BQ1: Events that trigger a disclosure clock (count) | BR1: EHS escalation clocks running (count) | BS1: Days until production plan is breached, forecast (days; 99 = not expected) | BT1: Planned production next month (t) | BU1: Forecast good output next month (t) | BV1: Forecast uncertainty next month (variance, t²) | BW1: Ideal output next month (t) | BX1: Forecast production lost to downtime next month (t) | BY1: Overheads, SG&A (₹ thousand) | BZ1: Tax paid (₹ thousand) | CA1: Capital employed, month end (₹ thousand) | CB1: Gross debt, month end (₹ thousand) | CC1: Cash, month end (₹ thousand) | CD1: Undrawn committed facilities (₹ thousand) | CE1: Debt service in the month (₹ thousand) | CF1: Debt maturing in next 12 months (₹ thousand) | CG1: Floating-rate debt (₹ thousand) | CH1: EBITDA as reported in the Board pack (₹ thousand) | CI1: Revenue in the flash report (₹ thousand) | CJ1: Trade receivables, month end (₹ thousand) | CK1: Trade payables, month end (₹ thousand) | CL1: Inventory, month end (₹ thousand) | CM1: Cash collected from customers (₹ thousand) | CN1: Cash released by working-capital actions (₹ thousand) | CO1: Cash due to be upstreamed to Group, next 30 days (₹ thousand) | CP1: Of which covered by available cash (₹ thousand) | CQ1: Invoices collected (count) | CR1: Days taken to collect, all invoices (days) | CS1: Agreed payment terms, all invoices (days) | CT1: Customers more than 30 days overdue (count) | CU1: Forecast EBITDA, rest of year (₹ thousand) | CV1: Planned EBITDA, rest of year (₹ thousand) | CW1: Forecast net cash flow, next 90 days (₹ thousand) | CX1: Forecast net debt at quarter end (₹ thousand) | CY1: Forecast EBITDA, 12 months to quarter end (₹ thousand) | CZ1: Foreign-currency exposure, gross (₹ thousand) | DA1: Foreign-currency exposure hedged (₹ thousand) | DB1: USD exposure, gross (₹ thousand) | DC1: USD exposure hedged (₹ thousand) | DD1: Change in value of hedges (₹ thousand) | DE1: Change in value of hedged items (₹ thousand) | DF1: Forecast foreign-currency flows, next 6 months (₹ thousand) | DG1: Of which hedged (₹ thousand) | DH1: Approved capex budget, full year (₹ thousand) | DI1: Capex committed to date (₹ thousand) | DJ1: Capex spent in the month (₹ thousand) | DK1: Capex work completed, valued at budget (₹ thousand) | DL1: Budget of capex projects at risk (₹ thousand) | DM1: Capex projects on track (count) | DN1: Capex projects at risk (count) | DO1: Capex projects off track (count) | DP1: Capex projects delayed (count) | DQ1: Contractor milestones due (count) | DR1: Contractor days late, all milestones (days) | DS1: Transformation initiatives on track (count) | DT1: Transformation initiatives at risk (count) | DU1: Transformation initiatives delayed (count) | DV1: Transformation milestones in plan (count) | DW1: Transformation milestones completed (count) | DX1: Programme benefits planned in the month (₹ thousand) | DY1: Programme benefits delivered in the month (₹ thousand) | DZ1: EBITDA benefit delivered (₹ thousand) | EA1: Cash benefit delivered (₹ thousand) | EB1: Cost savings delivered (₹ thousand) | EC1: Active supply contracts (count) | ED1: Contracts fully compliant (count) | EE1: Contracts expiring in next 90 days (count) | EF1: Suppliers not meeting EHS requirements (count) | EG1: Critical single-source suppliers (count) | EH1: Control failures (count) | EI1: High-severity control failures (count) | EJ1: Assurance reviews planned (count) | EK1: Assurance reviews completed (count) | EL1: Policy exceptions (count) | EM1: Unauthorised vendor uses (count) | EN1: Segregation-of-duties exceptions (count) | EO1: Unauthorised access events (count) | EP1: Data-sharing exceptions (count) | EQ1: Manual operational or system overrides (count) | ER1: Certification approvals past due date (count) | ES1: KPI values overridden (count) | ET1: Recurring data-quality issues (count) | EU1: Open audit findings (count) | EV1: Overdue assurance actions (count) | EW1: Repeat audit findings (count) | EX1: Leadership KPIs affected by open findings (count) | EY1: Evidence items required (count) | EZ1: Evidence items complete (count) | FA1: Audit findings closed in the month (count) | FB1: Days taken to close those findings (days) | FC1: Leadership KPI values reported (count) | FD1: Of which certified (count) | FE1: Of which inside the certification process (count) | FF1: Certifications overdue (count) | FG1: Open reconciliation breaks (count) | FH1: Material reconciliation breaks (count) | FI1: Records loaded to the data lake (count) | FJ1: Records reconciled to source (count) | FK1: Flash report lines (count) | FL1: Flash lines matching MIS (count) | FM1: Open critical alerts (count) | FN1: Alerts with no accepted owner (count) | FO1: Overdue actions (count) | FP1: Alerts resolved in the month (count) | FQ1: Days taken to resolve those alerts (days) | FR1: Escalations closed in the month (count) | FS1: Repeat issues raised in the month (count) | FT1: Root causes identified (count) | FU1: Root causes eliminated (count) | FV1: EBITDA (₹ thousand) | FW1: EBIT (₹ thousand) | FX1: Net working capital (₹ thousand) | FY1: Change in net working capital (₹ thousand) | FZ1: Operating cash flow (₹ thousand) | GA1: Free cash flow (₹ thousand) | GB1: Net debt (₹ thousand) | GC1: EBITDA, annualised (₹ thousand) | GD1: DSO (days) | GE1: DPO (days) | GF1: Inventory days (days) | GG1: Realised price vs plan (%) | GH1: Full-time employees (FTE, count) | GI1: FCF plan, full year (₹ thousand) | GJ1: Forecast FCF, rest of year (₹ thousand) | GK1: Forecast EBIT, rest of year (₹ thousand) | GL1: Forecast capital employed at P12 (₹ thousand) | GM1: EBITDA plan, full year (₹ thousand) | GN1: EBITDA full-year forecast uncertainty, 1σ (₹ thousand) | GO1: Hours to nearest open disclosure deadline (999 = none) | GP1: Single-source suppliers with cover below lead time (count) | GQ1: RM-1 price index (external, same for every entity) | GR1: Supply lanes with a disruption flag (count)
A2: group | B2: period | C2: days | D2: ytd_months | E2: calendar_hours | F2: planned_op_hours | G2: run_hours | H2: unplanned_downtime_hours | I2: ideal_output_t | J2: installed_capacity_t | K2: planned_production_t | L2: gross_output_t | M2: good_output_t | N2: feed_input_t | O2: feed_contained_t | P2: recovered_contained_t | Q2: prod_loss_downtime_t | R2: failures | S2: repair_hours | T2: pm_scheduled | U2: pm_completed | V2: variable_cost_k | W2: fuel_cost_k | X2: fixed_cost_k | Y2: water_m3 | Z2: emissions_tco2e | AA2: energy_gj | AB2: production_at_risk_t | AC2: critical_plant_alerts | AD2: hours_worked | AE2: recordable_injuries | AF2: severity_incidents | AG2: near_misses | AH2: critical_safety_incidents | AI2: env_excursions | AJ2: env_violations | AK2: ehs_ca_open | AL2: ehs_ca_overdue | AM2: investigations_due | AN2: investigations_completed | AO2: critical_material_risks | AP2: dispatches_total | AQ2: dispatches_delayed | AR2: permit_days_to_expiry | AS2: sales_t | AT2: planned_sales_t | AU2: revenue_k | AV2: planned_revenue_k | AW2: power_cost_k | AX2: depreciation_k | AY2: po_lines_due | AZ2: po_lines_on_time | BA2: qty_ordered_t | BB2: qty_received_t | BC2: qty_rejected_t | BD2: lead_time_planned_days | BE2: lead_time_actual_days | BF2: supplier_spend_k | BG2: single_source_spend_k | BH2: supplier_ehs_incidents | BI2: pending_filings | BJ2: reg_deadlines_30d | BK2: licences_expiring_12m | BL2: reg_obligations_due_30d | BM2: reg_obligations_overdue | BN2: reg_actions_open | BO2: compliance_actions_overdue | BP2: reg_breaches | BQ2: disclosure_events_open | BR2: ehs_escalation_clocks | BS2: days_to_breach | BT2: planned_production_next_t | BU2: forecast_good_next_t | BV2: forecast_good_var_next | BW2: ideal_output_next_t | BX2: forecast_downtime_loss_next_t | BY2: overhead_k | BZ2: tax_paid_k | CA2: capital_employed_k | CB2: gross_debt_k | CC2: cash_k | CD2: undrawn_facilities_k | CE2: debt_service_k | CF2: debt_maturing_12m_k | CG2: floating_rate_debt_k | CH2: board_ebitda_k | CI2: flash_revenue_k | CJ2: receivables_k | CK2: payables_k | CL2: inventory_k | CM2: collections_k | CN2: cash_released_k | CO2: upstream_due_k | CP2: upstream_covered_k | CQ2: invoices_collected | CR2: collection_days | CS2: terms_days | CT2: customers_overdue | CU2: forecast_ebitda_rest_k | CV2: planned_ebitda_rest_k | CW2: forecast_net_cash_flow_90d_k | CX2: forecast_net_debt_k | CY2: forecast_ebitda_ltm_k | CZ2: fx_exposure_k | DA2: fx_hedged_k | DB2: usd_exposure_k | DC2: usd_hedged_k | DD2: hedge_value_change_k | DE2: hedged_item_value_change_k | DF2: fx_flows_6m_k | DG2: fx_hedged_6m_k | DH2: capex_budget_k | DI2: capex_committed_k | DJ2: capex_spend_k | DK2: capex_earned_value_k | DL2: capex_at_risk_k | DM2: projects_on_track | DN2: projects_at_risk | DO2: projects_off_track | DP2: projects_delayed | DQ2: contractor_milestones_due | DR2: contractor_days_late | DS2: initiatives_on_track | DT2: initiatives_at_risk | DU2: initiatives_delayed | DV2: milestones_total | DW2: milestones_done | DX2: benefits_planned_k | DY2: benefits_delivered_k | DZ2: ebitda_benefit_k | EA2: cash_benefit_k | EB2: cost_savings_k | EC2: contracts_total | ED2: contracts_compliant | EE2: contracts_expiring_90d | EF2: supplier_ehs_noncompliance | EG2: single_source_suppliers | EH2: control_failures | EI2: control_failures_high | EJ2: assurance_reviews_planned | EK2: assurance_reviews_done | EL2: policy_exceptions | EM2: unauthorized_vendor_uses | EN2: sod_exceptions | EO2: unauthorized_access_events | EP2: data_sharing_exceptions | EQ2: manual_overrides | ER2: cert_approvals_ageing | ES2: kpi_overrides | ET2: dq_issues_recurring | EU2: audit_findings_open | EV2: assurance_actions_overdue | EW2: repeat_findings | EX2: leadership_kpis_affected | EY2: evidence_required | EZ2: evidence_complete | FA2: findings_closed | FB2: finding_closure_days | FC2: kpis_leadership | FD2: kpis_certified | FE2: kpis_in_scope | FF2: certifications_overdue | FG2: recon_breaks_open | FH2: recon_breaks_material | FI2: lake_records_loaded | FJ2: lake_records_reconciled | FK2: mis_lines_total | FL2: mis_lines_matched | FM2: critical_alerts_open | FN2: alerts_unowned | FO2: actions_overdue | FP2: alerts_resolved | FQ2: alert_resolution_days | FR2: escalations_closed | FS2: repeat_issues | FT2: root_causes_identified | FU2: root_causes_eliminated | FV2: ebitda_k | FW2: ebit_k | FX2: nwc_k | FY2: nwc_change_k | FZ2: op_cash_flow_k | GA2: fcf_k | GB2: net_debt_k | GC2: ebitda_annualised_k | GD2: dso_d | GE2: dpo_d | GF2: dio_d | GG2: price_vs_plan_pct | GH2: fte | GI2: fcf_plan_fy_k | GJ2: forecast_fcf_rest_k | GK2: ebit_fcst_rest_k | GL2: capital_employed_p12_k | GM2: ebitda_plan_fy_k | GN2: ebitda_fy_sigma_k | GO2: disclosure_deadline_h | GP2: single_source_elevated | GQ2: rm1_price_index | GR2: freight_lanes_disrupted
E3: Sum of Entity A1 and Entity A2 (Entity Inputs sheet) | F3: Sum of Entity A1 and Entity A2 (Entity Inputs sheet) | G3: Sum of Entity A1 and Entity A2 (Entity Inputs sheet) | H3: Sum of Entity A1 and Entity A2 (Entity Inputs sheet) | I3: Sum of Entity A1 and Entity A2 (Entity Inputs sheet) | J3: Sum of Entity A1 and Entity A2 (Entity Inputs sheet) | K3: Sum of Entity A1 and Entity A2 (Entity Inputs sheet) | L3: Sum of Entity A1 and Entity A2 (Entity Inputs sheet) | M3: Sum of Entity A1 and Entity A2 (Entity Inputs sheet) | N3: Sum of Entity A1 and Entity A2 (Entity Inputs sheet) | O3: Sum of Entity A1 and Entity A2 (Entity Inputs sheet) | P3: Sum of Entity A1 and Entity A2 (Entity Inputs sheet) | Q3: Sum of Entity A1 and Entity A2 (Entity Inputs sheet) | R3: Sum of Entity A1 and Entity A2 (Entity Inputs sheet) | S3: Sum of Entity A1 and Entity A2 (Entity Inputs sheet) | T3: Sum of Entity A1 and Entity A2 (Entity Inputs sheet) | U3: Sum of Entity A1 and Entity A2 (Entity Inputs sheet) | V3: Sum of Entity A1 and Entity A2 (Entity Inputs sheet) | W3: Sum of Entity A1 and Entity A2 (Entity Inputs sheet) | X3: Sum of Entity A1 and Entity A2 (Entity Inputs sheet) | Y3: Sum of Entity A1 and Entity A2 (Entity Inputs sheet) | Z3: Sum of Entity A1 and Entity A2 (Entity Inputs sheet) | AA3: Sum of Entity A1 and Entity A2 (Entity Inputs sheet) | AB3: Sum of Entity A1 and Entity A2 (Entity Inputs sheet) | AC3: Sum of Entity A1 and Entity A2 (Entity Inputs sheet) | AD3: Sum of Entity A1 and Entity A2 (Entity Inputs sheet) | AE3: Sum of Entity A1 and Entity A2 (Entity Inputs sheet) | AF3: Sum of Entity A1 and Entity A2 (Entity Inputs sheet) | AG3: Sum of Entity A1 and Entity A2 (Entity Inputs sheet) | AH3: Sum of Entity A1 and Entity A2 (Entity Inputs sheet) | AI3: Sum of Entity A1 and Entity A2 (Entity Inputs sheet) | AJ3: Sum of Entity A1 and Entity A2 (Entity Inputs sheet) | AK3: Sum of Entity A1 and Entity A2 (Entity Inputs sheet) | AL3: Sum of Entity A1 and Entity A2 (Entity Inputs sheet) | AM3: Sum of Entity A1 and Entity A2 (Entity Inputs sheet) | AN3: Sum of Entity A1 and Entity A2 (Entity Inputs sheet) | AO3: Sum of Entity A1 and Entity A2 (Entity Inputs sheet) | AP3: Sum of Entity A1 and Entity A2 (Entity Inputs sheet) | AQ3: Sum of Entity A1 and Entity A2 (Entity Inputs sheet) | AR3: Lowest of Entity A1 and Entity A2 (Entity Inputs sheet) | AS3: Sum of Entity A1 and Entity A2 (Entity Inputs sheet) | AT3: Sum of Entity A1 and Entity A2 (Entity Inputs sheet) | AU3: Sum of Entity A1 and Entity A2 (Entity Inputs sheet) | AV3: Sum of Entity A1 and Entity A2 (Entity Inputs sheet) | AW3: Sum of Entity A1 and Entity A2 (Entity Inputs sheet) | AX3: Sum of Entity A1 and Entity A2 (Entity Inputs sheet) | AY3: Sum of Entity A1 and Entity A2 (Entity Inputs sheet) | AZ3: Sum of Entity A1 and Entity A2 (Entity Inputs sheet) | BA3: Sum of Entity A1 and Entity A2 (Entity Inputs sheet) | BB3: Sum of Entity A1 and Entity A2 (Entity Inputs sheet) | BC3: Sum of Entity A1 and Entity A2 (Entity Inputs sheet) | BD3: Sum of Entity A1 and Entity A2 (Entity Inputs sheet) | BE3: Sum of Entity A1 and Entity A2 (Entity Inputs sheet) | BF3: Sum of Entity A1 and Entity A2 (Entity Inputs sheet) | BG3: Sum of Entity A1 and Entity A2 (Entity Inputs sheet) | BH3: Sum of Entity A1 and Entity A2 (Entity Inputs sheet) | BI3: Sum of Entity A1 and Entity A2 (Entity Inputs sheet) | BJ3: Sum of Entity A1 and Entity A2 (Entity Inputs sheet) | BK3: Sum of Entity A1 and Entity A2 (Entity Inputs sheet) | BL3: Sum of Entity A1 and Entity A2 (Entity Inputs sheet) | BM3: Sum of Entity A1 and Entity A2 (Entity Inputs sheet) | BN3: Sum of Entity A1 and Entity A2 (Entity Inputs sheet) | BO3: Sum of Entity A1 and Entity A2 (Entity Inputs sheet) | BP3: Sum of Entity A1 and Entity A2 (Entity Inputs sheet) | BQ3: Sum of Entity A1 and Entity A2 (Entity Inputs sheet) | BR3: Sum of Entity A1 and Entity A2 (Entity Inputs sheet) | BS3: Lowest of Entity A1 and Entity A2 (Entity Inputs sheet) | BT3: Sum of Entity A1 and Entity A2 (Entity Inputs sheet) | BU3: Sum of Entity A1 and Entity A2 (Entity Inputs sheet) | BV3: Sum of Entity A1 and Entity A2 (Entity Inputs sheet) | BW3: Sum of Entity A1 and Entity A2 (Entity Inputs sheet) | BX3: Sum of Entity A1 and Entity A2 (Entity Inputs sheet) | BY3: Sum of Entity A1 and Entity A2 (Entity Inputs sheet) | BZ3: Sum of Entity A1 and Entity A2 (Entity Inputs sheet) | CA3: Sum of Entity A1 and Entity A2 (Entity Inputs sheet) | CB3: Sum of Entity A1 and Entity A2 (Entity Inputs sheet) | CC3: Sum of Entity A1 and Entity A2 (Entity Inputs sheet) | CD3: Sum of Entity A1 and Entity A2 (Entity Inputs sheet) | CE3: Sum of Entity A1 and Entity A2 (Entity Inputs sheet) | CF3: Sum of Entity A1 and Entity A2 (Entity Inputs sheet) | CG3: Sum of Entity A1 and Entity A2 (Entity Inputs sheet) | CH3: Sum of Entity A1 and Entity A2 (Entity Inputs sheet) | CI3: Sum of Entity A1 and Entity A2 (Entity Inputs sheet) | CJ3: Sum of Entity A1 and Entity A2 (Entity Inputs sheet) | CK3: Sum of Entity A1 and Entity A2 (Entity Inputs sheet) | CL3: Sum of Entity A1 and Entity A2 (Entity Inputs sheet) | CM3: Sum of Entity A1 and Entity A2 (Entity Inputs sheet) | CN3: Sum of Entity A1 and Entity A2 (Entity Inputs sheet) | CO3: Sum of Entity A1 and Entity A2 (Entity Inputs sheet) | CP3: Sum of Entity A1 and Entity A2 (Entity Inputs sheet) | CQ3: Sum of Entity A1 and Entity A2 (Entity Inputs sheet) | CR3: Sum of Entity A1 and Entity A2 (Entity Inputs sheet) | CS3: Sum of Entity A1 and Entity A2 (Entity Inputs sheet) | CT3: Sum of Entity A1 and Entity A2 (Entity Inputs sheet) | CU3: Sum of Entity A1 and Entity A2 (Entity Inputs sheet) | CV3: Sum of Entity A1 and Entity A2 (Entity Inputs sheet) | CW3: Sum of Entity A1 and Entity A2 (Entity Inputs sheet) | CX3: Sum of Entity A1 and Entity A2 (Entity Inputs sheet) | CY3: Sum of Entity A1 and Entity A2 (Entity Inputs sheet) | CZ3: Sum of Entity A1 and Entity A2 (Entity Inputs sheet) | DA3: Sum of Entity A1 and Entity A2 (Entity Inputs sheet) | DB3: Sum of Entity A1 and Entity A2 (Entity Inputs sheet) | DC3: Sum of Entity A1 and Entity A2 (Entity Inputs sheet) | DD3: Sum of Entity A1 and Entity A2 (Entity Inputs sheet) | DE3: Sum of Entity A1 and Entity A2 (Entity Inputs sheet) | DF3: Sum of Entity A1 and Entity A2 (Entity Inputs sheet) | DG3: Sum of Entity A1 and Entity A2 (Entity Inputs sheet) | DH3: Sum of Entity A1 and Entity A2 (Entity Inputs sheet) | DI3: Sum of Entity A1 and Entity A2 (Entity Inputs sheet) | DJ3: Sum of Entity A1 and Entity A2 (Entity Inputs sheet) | DK3: Sum of Entity A1 and Entity A2 (Entity Inputs sheet) | DL3: Sum of Entity A1 and Entity A2 (Entity Inputs sheet) | DM3: Sum of Entity A1 and Entity A2 (Entity Inputs sheet) | DN3: Sum of Entity A1 and Entity A2 (Entity Inputs sheet) | DO3: Sum of Entity A1 and Entity A2 (Entity Inputs sheet) | DP3: Sum of Entity A1 and Entity A2 (Entity Inputs sheet) | DQ3: Sum of Entity A1 and Entity A2 (Entity Inputs sheet) | DR3: Sum of Entity A1 and Entity A2 (Entity Inputs sheet) | DS3: Sum of Entity A1 and Entity A2 (Entity Inputs sheet) | DT3: Sum of Entity A1 and Entity A2 (Entity Inputs sheet) | DU3: Sum of Entity A1 and Entity A2 (Entity Inputs sheet) | DV3: Sum of Entity A1 and Entity A2 (Entity Inputs sheet) | DW3: Sum of Entity A1 and Entity A2 (Entity Inputs sheet) | DX3: Sum of Entity A1 and Entity A2 (Entity Inputs sheet) | DY3: Sum of Entity A1 and Entity A2 (Entity Inputs sheet) | DZ3: Sum of Entity A1 and Entity A2 (Entity Inputs sheet) | EA3: Sum of Entity A1 and Entity A2 (Entity Inputs sheet) | EB3: Sum of Entity A1 and Entity A2 (Entity Inputs sheet) | EC3: Sum of Entity A1 and Entity A2 (Entity Inputs sheet) | ED3: Sum of Entity A1 and Entity A2 (Entity Inputs sheet) | EE3: Sum of Entity A1 and Entity A2 (Entity Inputs sheet) | EF3: Sum of Entity A1 and Entity A2 (Entity Inputs sheet) | EG3: Sum of Entity A1 and Entity A2 (Entity Inputs sheet) | EH3: Sum of Entity A1 and Entity A2 (Entity Inputs sheet) | EI3: Sum of Entity A1 and Entity A2 (Entity Inputs sheet) | EJ3: Sum of Entity A1 and Entity A2 (Entity Inputs sheet) | EK3: Sum of Entity A1 and Entity A2 (Entity Inputs sheet) | EL3: Sum of Entity A1 and Entity A2 (Entity Inputs sheet) | EM3: Sum of Entity A1 and Entity A2 (Entity Inputs sheet) | EN3: Sum of Entity A1 and Entity A2 (Entity Inputs sheet) | EO3: Sum of Entity A1 and Entity A2 (Entity Inputs sheet) | EP3: Sum of Entity A1 and Entity A2 (Entity Inputs sheet) | EQ3: Sum of Entity A1 and Entity A2 (Entity Inputs sheet) | ER3: Sum of Entity A1 and Entity A2 (Entity Inputs sheet) | ES3: Sum of Entity A1 and Entity A2 (Entity Inputs sheet) | ET3: Sum of Entity A1 and Entity A2 (Entity Inputs sheet) | EU3: Sum of Entity A1 and Entity A2 (Entity Inputs sheet) | EV3: Sum of Entity A1 and Entity A2 (Entity Inputs sheet) | EW3: Sum of Entity A1 and Entity A2 (Entity Inputs sheet) | EX3: Sum of Entity A1 and Entity A2 (Entity Inputs sheet) | EY3: Sum of Entity A1 and Entity A2 (Entity Inputs sheet) | EZ3: Sum of Entity A1 and Entity A2 (Entity Inputs sheet) | FA3: Sum of Entity A1 and Entity A2 (Entity Inputs sheet) | FB3: Sum of Entity A1 and Entity A2 (Entity Inputs sheet) | FC3: Sum of Entity A1 and Entity A2 (Entity Inputs sheet) | FD3: Sum of Entity A1 and Entity A2 (Entity Inputs sheet) | FE3: Sum of Entity A1 and Entity A2 (Entity Inputs sheet) | FF3: Sum of Entity A1 and Entity A2 (Entity Inputs sheet) | FG3: Sum of Entity A1 and Entity A2 (Entity Inputs sheet) | FH3: Sum of Entity A1 and Entity A2 (Entity Inputs sheet) | FI3: Sum of Entity A1 and Entity A2 (Entity Inputs sheet) | FJ3: Sum of Entity A1 and Entity A2 (Entity Inputs sheet) | FK3: Sum of Entity A1 and Entity A2 (Entity Inputs sheet) | FL3: Sum of Entity A1 and Entity A2 (Entity Inputs sheet) | FM3: Sum of Entity A1 and Entity A2 (Entity Inputs sheet) | FN3: Sum of Entity A1 and Entity A2 (Entity Inputs sheet) | FO3: Sum of Entity A1 and Entity A2 (Entity Inputs sheet) | FP3: Sum of Entity A1 and Entity A2 (Entity Inputs sheet) | FQ3: Sum of Entity A1 and Entity A2 (Entity Inputs sheet) | FR3: Sum of Entity A1 and Entity A2 (Entity Inputs sheet) | FS3: Sum of Entity A1 and Entity A2 (Entity Inputs sheet) | FT3: Sum of Entity A1 and Entity A2 (Entity Inputs sheet) | FU3: Sum of Entity A1 and Entity A2 (Entity Inputs sheet) | FV3: Calculated: Revenue − Variable cost − Fixed cost − Overheads | FW3: Calculated: EBITDA − Depreciation and amortisation | FX3: Calculated: Trade receivables + Inventory − Trade payables | FY3: Calculated: Net working capital − last month's net working capital (April uses the 31 March balance on Parameters) | FZ3: Calculated: EBITDA − Tax paid − Change in net working capital | GA3: Calculated: Operating cash flow − Capex spent | GB3: Calculated: Gross debt − Cash | GC3: Calculated: EBITDA since April × 12 ÷ months elapsed | GD3: Calculated: Trade receivables ÷ Revenue × Days in month | GE3: Calculated: Trade payables ÷ Variable cost × Days in month | GF3: Calculated: Inventory ÷ Variable cost × Days in month | GG3: Calculated: (Revenue ÷ Sales volume) ÷ (Planned revenue ÷ Planned sales volume) − 1, as % | GH3: SUM of Entity A1 and Entity A2 (added) | GI3: SUM of Entity A1 and Entity A2 (added) | GJ3: SUM of Entity A1 and Entity A2 (added) | GK3: SUM of Entity A1 and Entity A2 (added) | GL3: SUM of Entity A1 and Entity A2 (added) | GM3: SUM of Entity A1 and Entity A2 (added) | GN3: SQRTSUMSQ of Entity A1 and Entity A2 (added) | GO3: MIN of Entity A1 and Entity A2 (added) | GP3: SUM of Entity A1 and Entity A2 (added) | GQ3: FIRST of Entity A1 and Entity A2 (added) | GR3: SUM of Entity A1 and Entity A2 (added)
