Workbook

Sheet Calculated vs Shown
A1: KPI ID | B1: Measure | C1: Unit | D1: Formula | E1: Calculated value, Sep 2026 (P06) | F1: Shown on the Owner screens (Group scope) | G1: Same or different | H1: Screens | I1: Where the inputs come from
A2: OPS-001 | B2: Production vs plan | C2: % | D2: Good output ÷ Planned production × 100 | E2: ='Owner KPIs'!K2 | F2: 95.5 % of plan | G2: Different | H2: O-01, O-01 · large display ≥ 1600, O-09, S-03 · Owner view, S-10, STATE GALLERY · O-01 + S-02 | I2: Original plant data (plant_base.csv, synthetic)
A3: OPS-003 | B3: Capacity utilization | C3: % | D3: Good output ÷ Installed capacity × 100 | E3: ='Owner KPIs'!K3 | F3: 83.4 % | G3: Different | H3: O-01, O-01 · large display ≥ 1600, STATE GALLERY · O-01 + S-02 | I3: Original plant data (plant_base.csv, synthetic)
A4: REL-001 | B4: MTBF | C4: h | D4: Run hours ÷ Breakdowns | E4: ='Owner KPIs'!K4 | F4: 270 h | G4: Different | H4: O-09 | I4: Original plant data (plant_base.csv, synthetic)
A5: REL-002 | B5: Mean Time to Repair | C5: h | D5: Repair hours ÷ Breakdowns | E5: ='Owner KPIs'!K5 | F5: Not on a screen | G5: — | H5: — | I5: Original plant data (plant_base.csv, synthetic)
A6: REL-003 | B6: Unplanned downtime | C6: h | D6: Unplanned downtime | E6: ='Owner KPIs'!K6 | F6: Not on a screen | G6: — | H6: — | I6: Original plant data (plant_base.csv, synthetic)
A7: REL-005 | B7: Preventive-maintenance compliance | C7: % | D7: Preventive maintenance completed ÷ Preventive maintenance scheduled × 100 | E7: ='Owner KPIs'!K7 | F7: Not on a screen | G7: — | H7: — | I7: Original plant data (plant_base.csv, synthetic)
A8: CST-001 | B8: Cost per tonne | C8: ₹/t | D8: (Variable cost + Fixed cost) × 1000 ÷ Good output | E8: ='Owner KPIs'!K8 | F8: 2,934 ₹/t | G8: Different | H8: O-09, — | I8: Original plant data (plant_base.csv, synthetic)
A9: CST-002 | B9: Variable cost | C9: ₹ thousand | D9: Variable cost | E9: ='Owner KPIs'!K9 | F9: Not on a screen | G9: — | H9: — | I9: Original plant data (plant_base.csv, synthetic)
A10: CST-003 | B10: Fuel cost | C10: ₹ thousand | D10: Fuel cost | E10: ='Owner KPIs'!K10 | F10: Not on a screen | G10: — | H10: — | I10: Original plant data (plant_base.csv, synthetic)
A11: SUS-001 | B11: Water usage | C11: m3 | D11: Water used | E11: ='Owner KPIs'!K11 | F11: 3.1 m³/t | G11: Different | H11: O-05 | I11: Original plant data (plant_base.csv, synthetic)
A12: SUS-002 | B12: Emissions | C12: tCO2e | D12: Emissions | E12: ='Owner KPIs'!K12 | F12: 427.7 kt CO2e | G12: Different | H12: O-05 | I12: Original plant data (plant_base.csv, synthetic)
A13: SUS-003 | B13: Energy intensity | C13: GJ/t | D13: Energy used ÷ Good output | E13: ='Owner KPIs'!K13 | F13: 5.2 GJ/t | G13: Different | H13: O-05 | I13: Original plant data (plant_base.csv, synthetic)
... A119: PRD-007 | B119: Probability OEE below 78%, next month | C119: % | D119: Chance that Forecast good output < 78% × Ideal output next month (same distribution as PRD-002) [Next month] | E119: ='Owner KPIs'!K119 | F119: Not on a screen | G119: — | H119: — | I119: Synthetic inputs added for this model

Sheet Owner KPIs
A1: KPI ID | B1: Measure | C1: Unit | D1: Time basis | E1: How it is calculated | F1: 2026-04 (P01) | G1: 2026-05 (P02) | H1: 2026-06 (P03) | I1: 2026-07 (P04) | J1: 2026-08 (P05) | K1: 2026-09 (P06) | L1: Shown on Owner screens today (value and screens) | M1: Owner screens | N1: Inputs used (Group Inputs columns)
A2: OPS-001 | B2: Production vs plan | C2: % | D2: Month | E2: Good output ÷ Planned production × 100 | F2: =ROUND(IFERROR(100*'Group Inputs'!M4/'Group Inputs'!K4,0),2) | G2: =ROUND(IFERROR(100*'Group Inputs'!M5/'Group Inputs'!K5,0),2) | H2: =ROUND(IFERROR(100*'Group Inputs'!M6/'Group Inputs'!K6,0),2) | I2: =ROUND(IFERROR(100*'Group Inputs'!M7/'Group Inputs'!K7,0),2) | J2: =ROUND(IFERROR(100*'Group Inputs'!M8/'Group Inputs'!K8,0),2) | K2: =ROUND(IFERROR(100*'Group Inputs'!M9/'Group Inputs'!K9,0),2) | L2: 98.1 % of plan (O-01, STATE GALLERY); 103.2 % of plan (flash) (S-03); 100.2 % of plan (S-10); 95.5 % of plan (O-09) | M2: O-01, O-01 · large display ≥ 1600, O-09, S-03 · Owner view, S-10, STATE GALLERY · O-01 + S-02 | N2: planned_production_t, good_output_t
A3: OPS-003 | B3: Capacity utilization | C3: % | D3: Month | E3: Good output ÷ Installed capacity × 100 | F3: =ROUND(IFERROR(100*'Group Inputs'!M4/'Group Inputs'!J4,0),2) | G3: =ROUND(IFERROR(100*'Group Inputs'!M5/'Group Inputs'!J5,0),2) | H3: =ROUND(IFERROR(100*'Group Inputs'!M6/'Group Inputs'!J6,0),2) | I3: =ROUND(IFERROR(100*'Group Inputs'!M7/'Group Inputs'!J7,0),2) | J3: =ROUND(IFERROR(100*'Group Inputs'!M8/'Group Inputs'!J8,0),2) | K3: =ROUND(IFERROR(100*'Group Inputs'!M9/'Group Inputs'!J9,0),2) | L3: 86% (O-01, STATE GALLERY) | M3: O-01, O-01 · large display ≥ 1600, STATE GALLERY · O-01 + S-02 | N3: installed_capacity_t, good_output_t
A4: REL-001 | B4: MTBF | C4: h | D4: Month | E4: Run hours ÷ Breakdowns | F4: =ROUND(IFERROR('Group Inputs'!G4/'Group Inputs'!R4,0),2) | G4: =ROUND(IFERROR('Group Inputs'!G5/'Group Inputs'!R5,0),2) | H4: =ROUND(IFERROR('Group Inputs'!G6/'Group Inputs'!R6,0),2) | I4: =ROUND(IFERROR('Group Inputs'!G7/'Group Inputs'!R7,0),2) | J4: =ROUND(IFERROR('Group Inputs'!G8/'Group Inputs'!R8,0),2) | K4: =ROUND(IFERROR('Group Inputs'!G9/'Group Inputs'!R9,0),2) | L4: 270 h (O-09) | M4: O-09 | N4: run_hours, failures
A5: REL-002 | B5: Mean Time to Repair | C5: h | D5: Month | E5: Repair hours ÷ Breakdowns | F5: =ROUND(IFERROR('Group Inputs'!S4/'Group Inputs'!R4,0),2) | G5: =ROUND(IFERROR('Group Inputs'!S5/'Group Inputs'!R5,0),2) | H5: =ROUND(IFERROR('Group Inputs'!S6/'Group Inputs'!R6,0),2) | I5: =ROUND(IFERROR('Group Inputs'!S7/'Group Inputs'!R7,0),2) | J5: =ROUND(IFERROR('Group Inputs'!S8/'Group Inputs'!R8,0),2) | K5: =ROUND(IFERROR('Group Inputs'!S9/'Group Inputs'!R9,0),2) | L5: Not on a screen | M5: — | N5: failures, repair_hours
A6: REL-003 | B6: Unplanned downtime | C6: h | D6: Month | E6: Unplanned downtime | F6: =ROUND('Group Inputs'!H4,2) | G6: =ROUND('Group Inputs'!H5,2) | H6: =ROUND('Group Inputs'!H6,2) | I6: =ROUND('Group Inputs'!H7,2) | J6: =ROUND('Group Inputs'!H8,2) | K6: =ROUND('Group Inputs'!H9,2) | L6: Not on a screen | M6: — | N6: unplanned_downtime_hours
A7: REL-005 | B7: Preventive-maintenance compliance | C7: % | D7: Month | E7: Preventive maintenance completed ÷ Preventive maintenance scheduled × 100 | F7: =ROUND(IFERROR(100*'Group Inputs'!U4/'Group Inputs'!T4,0),2) | G7: =ROUND(IFERROR(100*'Group Inputs'!U5/'Group Inputs'!T5,0),2) | H7: =ROUND(IFERROR(100*'Group Inputs'!U6/'Group Inputs'!T6,0),2) | I7: =ROUND(IFERROR(100*'Group Inputs'!U7/'Group Inputs'!T7,0),2) | J7: =ROUND(IFERROR(100*'Group Inputs'!U8/'Group Inputs'!T8,0),2) | K7: =ROUND(IFERROR(100*'Group Inputs'!U9/'Group Inputs'!T9,0),2) | L7: Not on a screen | M7: — | N7: pm_scheduled, pm_completed
A8: CST-001 | B8: Cost per tonne | C8: ₹/t | D8: Month | E8: (Variable cost + Fixed cost) × 1000 ÷ Good output | F8: =ROUND(IFERROR(1000*('Group Inputs'!V4+'Group Inputs'!X4)/'Group Inputs'!M4,0),2) | G8: =ROUND(IFERROR(1000*('Group Inputs'!V5+'Group Inputs'!X5)/'Group Inputs'!M5,0),2) | H8: =ROUND(IFERROR(1000*('Group Inputs'!V6+'Group Inputs'!X6)/'Group Inputs'!M6,0),2) | I8: =ROUND(IFERROR(1000*('Group Inputs'!V7+'Group Inputs'!X7)/'Group Inputs'!M7,0),2) | J8: =ROUND(IFERROR(1000*('Group Inputs'!V8+'Group Inputs'!X8)/'Group Inputs'!M8,0),2) | K8: =ROUND(IFERROR(1000*('Group Inputs'!V9+'Group Inputs'!X9)/'Group Inputs'!M9,0),2) | L8: Not on a screen; 2,934 ₹/t (O-09) | M8: O-09, — | N8: good_output_t, variable_cost_k, fixed_cost_k
A9: CST-002 | B9: Variable cost | C9: ₹ thousand | D9: Month | E9: Variable cost | F9: =ROUND('Group Inputs'!V4,2) | G9: =ROUND('Group Inputs'!V5,2) | H9: =ROUND('Group Inputs'!V6,2) | I9: =ROUND('Group Inputs'!V7,2) | J9: =ROUND('Group Inputs'!V8,2) | K9: =ROUND('Group Inputs'!V9,2) | L9: Not on a screen | M9: — | N9: variable_cost_k
A10: CST-003 | B10: Fuel cost | C10: ₹ thousand | D10: Month | E10: Fuel cost | F10: =ROUND('Group Inputs'!W4,2) | G10: =ROUND('Group Inputs'!W5,2) | H10: =ROUND('Group Inputs'!W6,2) | I10: =ROUND('Group Inputs'!W7,2) | J10: =ROUND('Group Inputs'!W8,2) | K10: =ROUND('Group Inputs'!W9,2) | L10: Not on a screen | M10: — | N10: fuel_cost_k
A11: SUS-001 | B11: Water usage | C11: m3 | D11: Month | E11: Water used | F11: =ROUND('Group Inputs'!Y4,2) | G11: =ROUND('Group Inputs'!Y5,2) | H11: =ROUND('Group Inputs'!Y6,2) | I11: =ROUND('Group Inputs'!Y7,2) | J11: =ROUND('Group Inputs'!Y8,2) | K11: =ROUND('Group Inputs'!Y9,2) | L11: 3.1 m³/t (O-05) | M11: O-05 | N11: water_m3
A12: SUS-002 | B12: Emissions | C12: tCO2e | D12: Month | E12: Emissions | F12: =ROUND('Group Inputs'!Z4,2) | G12: =ROUND('Group Inputs'!Z5,2) | H12: =ROUND('Group Inputs'!Z6,2) | I12: =ROUND('Group Inputs'!Z7,2) | J12: =ROUND('Group Inputs'!Z8,2) | K12: =ROUND('Group Inputs'!Z9,2) | L12: 0.82 tCO2e/t (O-05) | M12: O-05 | N12: emissions_tco2e
A13: SUS-003 | B13: Energy intensity | C13: GJ/t | D13: Month | E13: Energy used ÷ Good output | F13: =ROUND(IFERROR('Group Inputs'!AA4/'Group Inputs'!M4,0),2) | G13: =ROUND(IFERROR('Group Inputs'!AA5/'Group Inputs'!M5,0),2) | H13: =ROUND(IFERROR('Group Inputs'!AA6/'Group Inputs'!M6,0),2) | I13: =ROUND(IFERROR('Group Inputs'!AA7/'Group Inputs'!M7,0),2) | J13: =ROUND(IFERROR('Group Inputs'!AA8/'Group Inputs'!M8,0),2) | K13: =ROUND(IFERROR('Group Inputs'!AA9/'Group Inputs'!M9,0),2) | L13: 5.2 GJ/t (O-05) | M13: O-05 | N13: good_output_t, energy_gj
A14: SIG-007 | B14: Production at risk | C14: t | D14: Month | E14: Production at risk | F14: =ROUND('Group Inputs'!AB4,2) | G14: =ROUND('Group Inputs'!AB5,2) | H14: =ROUND('Group Inputs'!AB6,2) | I14: =ROUND('Group Inputs'!AB7,2) | J14: =ROUND('Group Inputs'!AB8,2) | K14: =ROUND('Group Inputs'!AB9,2) | L14: 18.4 kt (FCST) (S-10) | M14: S-10 | N14: production_at_risk_t
A15: SIG-009 | B15: Critical-material shortage risk | C15: count | D15: Month | E15: Critical materials at risk | F15: =ROUND('Group Inputs'!AO4,2) | G15: =ROUND('Group Inputs'!AO5,2) | H15: =ROUND('Group Inputs'!AO6,2) | I15: =ROUND('Group Inputs'!AO7,2) | J15: =ROUND('Group Inputs'!AO8,2) | K15: =ROUND('Group Inputs'!AO9,2) | L15: 3.5 days of cover (S-10) | M15: S-10 | N15: critical_material_risks
A16: SIG-012 | B16: Dispatch delays | C16: % | D16: Month | E16: Delayed dispatches ÷ Dispatches × 100 | F16: =ROUND(IFERROR(100*'Group Inputs'!AQ4/'Group Inputs'!AP4,0),2) | G16: =ROUND(IFERROR(100*'Group Inputs'!AQ5/'Group Inputs'!AP5,0),2) | H16: =ROUND(IFERROR(100*'Group Inputs'!AQ6/'Group Inputs'!AP6,0),2) | I16: =ROUND(IFERROR(100*'Group Inputs'!AQ7/'Group Inputs'!AP7,0),2) | J16: =ROUND(IFERROR(100*'Group Inputs'!AQ8/'Group Inputs'!AP8,0),2) | K16: =ROUND(IFERROR(100*'Group Inputs'!AQ9/'Group Inputs'!AP9,0),2) | L16: 2–4 days (S-11) | M16: S-11 | N16: dispatches_total, dispatches_delayed
A17: EHS-001 | B17: TRIR | C17: per 200,000 h | D17: Month | E17: Recordable injuries × 200,000 ÷ Hours worked | F17: =ROUND(IFERROR(200000*'Group Inputs'!AE4/'Group Inputs'!AD4,0),2) | G17: =ROUND(IFERROR(200000*'Group Inputs'!AE5/'Group Inputs'!AD5,0),2) | H17: =ROUND(IFERROR(200000*'Group Inputs'!AE6/'Group Inputs'!AD6,0),2) | I17: =ROUND(IFERROR(200000*'Group Inputs'!AE7/'Group Inputs'!AD7,0),2) | J17: =ROUND(IFERROR(200000*'Group Inputs'!AE8/'Group Inputs'!AD8,0),2) | K17: =ROUND(IFERROR(200000*'Group Inputs'!AE9/'Group Inputs'!AD9,0),2) | L17: 0.42 (O-05) | M17: O-05 | N17: hours_worked, recordable_injuries
A18: EHS-002 | B18: Severity incidents | C18: count | D18: Month | E18: Severity incidents | F18: =ROUND('Group Inputs'!AF4,2) | G18: =ROUND('Group Inputs'!AF5,2) | H18: =ROUND('Group Inputs'!AF6,2) | I18: =ROUND('Group Inputs'!AF7,2) | J18: =ROUND('Group Inputs'!AF8,2) | K18: =ROUND('Group Inputs'!AF9,2) | L18: 0 (O-05) | M18: O-05 | N18: severity_incidents
A19: EHS-003 | B19: Near misses | C19: count | D19: Month | E19: Near misses | F19: =ROUND('Group Inputs'!AG4,2) | G19: =ROUND('Group Inputs'!AG5,2) | H19: =ROUND('Group Inputs'!AG6,2) | I19: =ROUND('Group Inputs'!AG7,2) | J19: =ROUND('Group Inputs'!AG8,2) | K19: =ROUND('Group Inputs'!AG9,2) | L19: 14 (O-05) | M19: O-05 | N19: near_misses
A20: EHS-004 | B20: Critical safety incidents | C20: count | D20: Month | E20: Critical safety incidents | F20: =ROUND('Group Inputs'!AH4,2) | G20: =ROUND('Group Inputs'!AH5,2) | H20: =ROUND('Group Inputs'!AH6,2) | I20: =ROUND('Group Inputs'!AH7,2) | J20: =ROUND('Group Inputs'!AH8,2) | K20: =ROUND('Group Inputs'!AH9,2) | L20: 0 (O-05) | M20: O-05 | N20: critical_safety_incidents
A21: EHS-005 | B21: Environmental excursions | C21: count | D21: Month | E21: Environmental excursions | F21: =ROUND('Group Inputs'!AI4,2) | G21: =ROUND('Group Inputs'!AI5,2) | H21: =ROUND('Group Inputs'!AI6,2) | I21: =ROUND('Group Inputs'!AI7,2) | J21: =ROUND('Group Inputs'!AI8,2) | K21: =ROUND('Group Inputs'!AI9,2) | L21: 1 (minor, closed) (O-05) | M21: O-05 | N21: env_excursions
A22: EHS-007 | B22: Overdue EHS actions | C22: count | D22: Month | E22: Overdue EHS corrective actions | F22: =ROUND('Group Inputs'!AL4,2) | G22: =ROUND('Group Inputs'!AL5,2) | H22: =ROUND('Group Inputs'!AL6,2) | I22: =ROUND('Group Inputs'!AL7,2) | J22: =ROUND('Group Inputs'!AL8,2) | K22: =ROUND('Group Inputs'!AL9,2) | L22: 0 (O-05) | M22: O-05 | N22: ehs_ca_overdue
A23: REG-006 | B23: Licence or permit expiry clock | C23: days | D23: Month | E23: Days to permit expiry (lowest plant) | F23: =ROUND('Group Inputs'!AR4,2) | G23: =ROUND('Group Inputs'!AR5,2) | H23: =ROUND('Group Inputs'!AR6,2) | I23: =ROUND('Group Inputs'!AR7,2) | J23: =ROUND('Group Inputs'!AR8,2) | K23: =ROUND('Group Inputs'!AR9,2) | L23: 74 days · Entity C1 (O-05) | M23: O-05 | N23: permit_days_to_expiry
A24: OPS-005 | B24: Capacity utilisation (same measure as OPS-003) | C24: % | D24: Month | E24: Good output ÷ Installed capacity × 100 | F24: =ROUND(IFERROR(100*'Group Inputs'!M4/'Group Inputs'!J4,0),2) | G24: =ROUND(IFERROR(100*'Group Inputs'!M5/'Group Inputs'!J5,0),2) | H24: =ROUND(IFERROR(100*'Group Inputs'!M6/'Group Inputs'!J6,0),2) | I24: =ROUND(IFERROR(100*'Group Inputs'!M7/'Group Inputs'!J7,0),2) | J24: =ROUND(IFERROR(100*'Group Inputs'!M8/'Group Inputs'!J8,0),2) | K24: =ROUND(IFERROR(100*'Group Inputs'!M9/'Group Inputs'!J9,0),2) | L24: 86% (O-01) | M24: O-01 | N24: installed_capacity_t, good_output_t
A25: OPS-006 | B25: OEE · Group weighted (same measure as PLT-002) | C25: % | D25: Month | E25: Good output ÷ Ideal output × 100 (weighted by output, not an average of plants) | F25: =ROUND(IFERROR(100*'Group Inputs'!M4/'Group Inputs'!I4,0),2) | G25: =ROUND(IFERROR(100*'Group Inputs'!M5/'Group Inputs'!I5,0),2) | H25: =ROUND(IFERROR(100*'Group Inputs'!M6/'Group Inputs'!I6,0),2) | I25: =ROUND(IFERROR(100*'Group Inputs'!M7/'Group Inputs'!I7,0),2) | J25: =ROUND(IFERROR(100*'Group Inputs'!M8/'Group Inputs'!I8,0),2) | K25: =ROUND(IFERROR(100*'Group Inputs'!M9/'Group Inputs'!I9,0),2) | L25: Not on a screen | M25: — | N25: ideal_output_t, good_output_t
A26: OPS-002 | B26: Sales vs plan | C26: % | D26: Month | E26: Sales volume ÷ Planned sales volume × 100 | F26: =ROUND(IF('Group Inputs'!AT4=0,0,100*'Group Inputs'!AS4/'Group Inputs'!AT4),2) | G26: =ROUND(IF('Group Inputs'!AT5=0,0,100*'Group Inputs'!AS5/'Group Inputs'!AT5),2) | H26: =ROUND(IF('Group Inputs'!AT6=0,0,100*'Group Inputs'!AS6/'Group Inputs'!AT6),2) | I26: =ROUND(IF('Group Inputs'!AT7=0,0,100*'Group Inputs'!AS7/'Group Inputs'!AT7),2) | J26: =ROUND(IF('Group Inputs'!AT8=0,0,100*'Group Inputs'!AS8/'Group Inputs'!AT8),2) | K26: =ROUND(IF('Group Inputs'!AT9=0,0,100*'Group Inputs'!AS9/'Group Inputs'!AT9),2) | L26: 97.6% (O-01, STATE GALLERY) | M26: O-01, STATE GALLERY · O-01 + S-02, O-01 · large display ≥ 1600 | N26: sales_t, planned_sales_t
A27: OPS-004 | B27: Sales vs plan · Group (same measure as OPS-002) | C27: % | D27: Month | E27: Sales volume ÷ Planned sales volume × 100 | F27: =ROUND(IF('Group Inputs'!AT4=0,0,100*'Group Inputs'!AS4/'Group Inputs'!AT4),2) | G27: =ROUND(IF('Group Inputs'!AT5=0,0,100*'Group Inputs'!AS5/'Group Inputs'!AT5),2) | H27: =ROUND(IF('Group Inputs'!AT6=0,0,100*'Group Inputs'!AS6/'Group Inputs'!AT6),2) | I27: =ROUND(IF('Group Inputs'!AT7=0,0,100*'Group Inputs'!AS7/'Group Inputs'!AT7),2) | J27: =ROUND(IF('Group Inputs'!AT8=0,0,100*'Group Inputs'!AS8/'Group Inputs'!AT8),2) | K27: =ROUND(IF('Group Inputs'!AT9=0,0,100*'Group Inputs'!AS9/'Group Inputs'!AT9),2) | L27: 97.6% (O-01) | M27: O-01 | N27: sales_t, planned_sales_t
A28: CST-004 | B28: Power cost per tonne | C28: ₹/t | D28: Month | E28: Power cost × 1000 ÷ Good output | F28: =ROUND(IF('Group Inputs'!M4=0,0,1000*'Group Inputs'!AW4/'Group Inputs'!M4),2) | G28: =ROUND(IF('Group Inputs'!M5=0,0,1000*'Group Inputs'!AW5/'Group Inputs'!M5),2) | H28: =ROUND(IF('Group Inputs'!M6=0,0,1000*'Group Inputs'!AW6/'Group Inputs'!M6),2) | I28: =ROUND(IF('Group Inputs'!M7=0,0,1000*'Group Inputs'!AW7/'Group Inputs'!M7),2) | J28: =ROUND(IF('Group Inputs'!M8=0,0,1000*'Group Inputs'!AW8/'Group Inputs'!M8),2) | K28: =ROUND(IF('Group Inputs'!M9=0,0,1000*'Group Inputs'!AW9/'Group Inputs'!M9),2) | L28: Not on a screen | M28: — | N28: good_output_t, power_cost_k
A29: FIN-001 | B29: EBITDA YTD | C29: ₹ m | D29: Year to date | E29: Sum of monthly EBITDA since April ÷ 1000 | F29: =ROUND(SUM('Group Inputs'!FV$4:FV4)/1000,2) | G29: =ROUND(SUM('Group Inputs'!FV$4:FV5)/1000,2) | H29: =ROUND(SUM('Group Inputs'!FV$4:FV6)/1000,2) | I29: =ROUND(SUM('Group Inputs'!FV$4:FV7)/1000,2) | J29: =ROUND(SUM('Group Inputs'!FV$4:FV8)/1000,2) | K29: =ROUND(SUM('Group Inputs'!FV$4:FV9)/1000,2) | L29: 361.3 ₹ m (O-01, STATE GALLERY) | M29: O-01, STATE GALLERY · O-01 + S-02, O-01 · large display ≥ 1600 | N29: ebitda_k
A30: FIN-002 | B30: EBIT YTD | C30: ₹ m | D30: Year to date | E30: Sum of monthly EBIT since April ÷ 1000 | F30: =ROUND(SUM('Group Inputs'!FW$4:FW4)/1000,2) | G30: =ROUND(SUM('Group Inputs'!FW$4:FW5)/1000,2) | H30: =ROUND(SUM('Group Inputs'!FW$4:FW6)/1000,2) | I30: =ROUND(SUM('Group Inputs'!FW$4:FW7)/1000,2) | J30: =ROUND(SUM('Group Inputs'!FW$4:FW8)/1000,2) | K30: =ROUND(SUM('Group Inputs'!FW$4:FW9)/1000,2) | L30: 238.4 ₹ m (O-01, STATE GALLERY) | M30: O-01, STATE GALLERY · O-01 + S-02, O-01 · large display ≥ 1600 | N30: ebit_k
A31: FIN-003 | B31: Revenue YTD | C31: ₹ m | D31: Year to date | E31: Sum of monthly Revenue since April ÷ 1000 | F31: =ROUND(SUM('Group Inputs'!AU$4:AU4)/1000,2) | G31: =ROUND(SUM('Group Inputs'!AU$4:AU5)/1000,2) | H31: =ROUND(SUM('Group Inputs'!AU$4:AU6)/1000,2) | I31: =ROUND(SUM('Group Inputs'!AU$4:AU7)/1000,2) | J31: =ROUND(SUM('Group Inputs'!AU$4:AU8)/1000,2) | K31: =ROUND(SUM('Group Inputs'!AU$4:AU9)/1000,2) | L31: 2,410 ₹ m (O-01, STATE GALLERY) | M31: O-01, STATE GALLERY · O-01 + S-02, O-01 · large display ≥ 1600 | N31: revenue_k
A32: FIN-004 | B32: Free cash flow YTD | C32: ₹ m | D32: Year to date | E32: Sum of monthly Free cash flow since April ÷ 1000 | F32: =ROUND(SUM('Group Inputs'!GA$4:GA4)/1000,2) | G32: =ROUND(SUM('Group Inputs'!GA$4:GA5)/1000,2) | H32: =ROUND(SUM('Group Inputs'!GA$4:GA6)/1000,2) | I32: =ROUND(SUM('Group Inputs'!GA$4:GA7)/1000,2) | J32: =ROUND(SUM('Group Inputs'!GA$4:GA8)/1000,2) | K32: =ROUND(SUM('Group Inputs'!GA$4:GA9)/1000,2) | L32: 96.4 ₹ m (O-01, STATE GALLERY) | M32: O-01, O-01 · large display ≥ 1600, STATE GALLERY · O-01 + S-02 | N32: fcf_k
A33: FIN-005 | B33: ROCE, annualised | C33: % | D33: Year to date | E33: EBIT since April × 12 ÷ months elapsed ÷ Capital employed × 100 | F33: =ROUND(IF('Group Inputs'!CA4=0,0,100*SUM('Group Inputs'!FW$4:FW4)*12/'Group Inputs'!D4/'Group Inputs'!CA4),2) | G33: =ROUND(IF('Group Inputs'!CA5=0,0,100*SUM('Group Inputs'!FW$4:FW5)*12/'Group Inputs'!D5/'Group Inputs'!CA5),2) | H33: =ROUND(IF('Group Inputs'!CA6=0,0,100*SUM('Group Inputs'!FW$4:FW6)*12/'Group Inputs'!D6/'Group Inputs'!CA6),2) | I33: =ROUND(IF('Group Inputs'!CA7=0,0,100*SUM('Group Inputs'!FW$4:FW7)*12/'Group Inputs'!D7/'Group Inputs'!CA7),2) | J33: =ROUND(IF('Group Inputs'!CA8=0,0,100*SUM('Group Inputs'!FW$4:FW8)*12/'Group Inputs'!D8/'Group Inputs'!CA8),2) | K33: =ROUND(IF('Group Inputs'!CA9=0,0,100*SUM('Group Inputs'!FW$4:FW9)*12/'Group Inputs'!D9/'Group Inputs'!CA9),2) | L33: 11.8 % (O-01); 11.8% (O-01, STATE GALLERY) | M33: O-01, STATE GALLERY · O-01 + S-02, O-01 · large display ≥ 1600 | N33: ytd_months, capital_employed_k, ebit_k
A34: FIN-006 | B34: Net debt | C34: ₹ m | D34: Month end | E34: (Gross debt − Cash) ÷ 1000 | F34: =ROUND('Group Inputs'!GB4/1000,2) | G34: =ROUND('Group Inputs'!GB5/1000,2) | H34: =ROUND('Group Inputs'!GB6/1000,2) | I34: =ROUND('Group Inputs'!GB7/1000,2) | J34: =ROUND('Group Inputs'!GB8/1000,2) | K34: =ROUND('Group Inputs'!GB9/1000,2) | L34: 1,140 ₹ m (O-01, STATE GALLERY); 6,650.0 ₹ m (O-03) | M34: O-01, O-01 · large display ≥ 1600, O-03, STATE GALLERY · O-01 + S-02 | N34: net_debt_k
A35: FIN-007 | B35: Shareholder-value indicator (economic profit YTD) | C35: ₹ m | D35: Year to date | E35: (EBIT since April × (1 − Tax rate) − Capital employed × Cost of capital × months elapsed ÷ 12) ÷ 1000 | F35: =ROUND((SUM('Group Inputs'!FW$4:FW4)*(1-Parameters!$B$2)-'Group Inputs'!CA4*Parameters!$B$3*'Group Inputs'!D4/12)/1000,2) | G35: =ROUND((SUM('Group Inputs'!FW$4:FW5)*(1-Parameters!$B$2)-'Group Inputs'!CA5*Parameters!$B$3*'Group Inputs'!D5/12)/1000,2) | H35: =ROUND((SUM('Group Inputs'!FW$4:FW6)*(1-Parameters!$B$2)-'Group Inputs'!CA6*Parameters!$B$3*'Group Inputs'!D6/12)/1000,2) | I35: =ROUND((SUM('Group Inputs'!FW$4:FW7)*(1-Parameters!$B$2)-'Group Inputs'!CA7*Parameters!$B$3*'Group Inputs'!D7/12)/1000,2) | J35: =ROUND((SUM('Group Inputs'!FW$4:FW8)*(1-Parameters!$B$2)-'Group Inputs'!CA8*Parameters!$B$3*'Group Inputs'!D8/12)/1000,2) | K35: =ROUND((SUM('Group Inputs'!FW$4:FW9)*(1-Parameters!$B$2)-'Group Inputs'!CA9*Parameters!$B$3*'Group Inputs'!D9/12)/1000,2) | L35: [PLACEHOLDER] (O-01, STATE GALLERY) | M35: O-01, STATE GALLERY · O-01 + S-02, O-01 · large display ≥ 1600 | N35: ytd_months, capital_employed_k, ebit_k
A36: CSH-001 | B36: Cash position | C36: ₹ m | D36: Month end | E36: Cash ÷ 1000 | F36: =ROUND('Group Inputs'!CC4/1000,2) | G36: =ROUND('Group Inputs'!CC5/1000,2) | H36: =ROUND('Group Inputs'!CC6/1000,2) | I36: =ROUND('Group Inputs'!CC7/1000,2) | J36: =ROUND('Group Inputs'!CC8/1000,2) | K36: =ROUND('Group Inputs'!CC9/1000,2) | L36: 2,141.8 ₹ m (O-03) | M36: O-03 | N36: cash_k
A37: CSH-002 | B37: Cash released YTD | C37: ₹ m | D37: Year to date | E37: Sum of cash released since April ÷ 1000 | F37: =ROUND(SUM('Group Inputs'!CN$4:CN4)/1000,2) | G37: =ROUND(SUM('Group Inputs'!CN$4:CN5)/1000,2) | H37: =ROUND(SUM('Group Inputs'!CN$4:CN6)/1000,2) | I37: =ROUND(SUM('Group Inputs'!CN$4:CN7)/1000,2) | J37: =ROUND(SUM('Group Inputs'!CN$4:CN8)/1000,2) | K37: =ROUND(SUM('Group Inputs'!CN$4:CN9)/1000,2) | L37: Not on a screen | M37: — | N37: cash_released_k
A38: CSH-003 | B38: Daily collections | C38: ₹ m per day | D38: Month | E38: Cash collected ÷ Days in month ÷ 1000 | F38: =ROUND('Group Inputs'!CM4/'Group Inputs'!C4/1000,2) | G38: =ROUND('Group Inputs'!CM5/'Group Inputs'!C5/1000,2) | H38: =ROUND('Group Inputs'!CM6/'Group Inputs'!C6/1000,2) | I38: =ROUND('Group Inputs'!CM7/'Group Inputs'!C7/1000,2) | J38: =ROUND('Group Inputs'!CM8/'Group Inputs'!C8/1000,2) | K38: =ROUND('Group Inputs'!CM9/'Group Inputs'!C9/1000,2) | L38: 4.1 ₹ m (S-11) | M38: S-11 | N38: days, collections_k
A39: CSH-004 | B39: Cash-conversion cycle | C39: days | D39: Month end | E39: DSO + Inventory days − DPO | F39: =ROUND('Group Inputs'!GD4+'Group Inputs'!GF4-'Group Inputs'!GE4,2) | G39: =ROUND('Group Inputs'!GD5+'Group Inputs'!GF5-'Group Inputs'!GE5,2) | H39: =ROUND('Group Inputs'!GD6+'Group Inputs'!GF6-'Group Inputs'!GE6,2) | I39: =ROUND('Group Inputs'!GD7+'Group Inputs'!GF7-'Group Inputs'!GE7,2) | J39: =ROUND('Group Inputs'!GD8+'Group Inputs'!GF8-'Group Inputs'!GE8,2) | K39: =ROUND('Group Inputs'!GD9+'Group Inputs'!GF9-'Group Inputs'!GE9,2) | L39: Not on a screen | M39: — | N39: dso_d, dpo_d, dio_d
A40: CSH-006 | B40: Cash-upstream exposure | C40: ₹ m | D40: Next 30 days | E40: (Cash due to be upstreamed − Amount covered by available cash) ÷ 1000 | F40: =ROUND(('Group Inputs'!CO4-'Group Inputs'!CP4)/1000,2) | G40: =ROUND(('Group Inputs'!CO5-'Group Inputs'!CP5)/1000,2) | H40: =ROUND(('Group Inputs'!CO6-'Group Inputs'!CP6)/1000,2) | I40: =ROUND(('Group Inputs'!CO7-'Group Inputs'!CP7)/1000,2) | J40: =ROUND(('Group Inputs'!CO8-'Group Inputs'!CP8)/1000,2) | K40: =ROUND(('Group Inputs'!CO9-'Group Inputs'!CP9)/1000,2) | L40: 26 ₹ m (S-11); 27.2 ₹ m (O-03) | M40: O-03, S-11 | N40: upstream_due_k, upstream_covered_k
...

Sheet Owner Screens
A1: No. | B1: Screen | C1: Screen title | D1: Element | E1: Label on the screen | F1: KPI ID | G1: Scope | H1: Shown on the screen | I1: Model value, P06 (Sep 2026) | J1: Where the model value comes from
A2: 1 | B2: O-01 | C2: Enterprise Health | D2: Card | E2: Production vs plan · Group MTD | F2: OPS-001 | G2: Group | H2: 98.1 % of plan | I2: ='Owner KPIs'!K2 | J2: Owner KPIs sheet, row 2 (Group, Sep 2026)
A3: 2 | B3: O-01 | C3: Enterprise Health | D3: Card | E3: EBITDA YTD (to P06) | F3: FIN-001 | G3: Group | H3: 361.3 ₹ m | I3: ='Owner KPIs'!K29 | J3: Owner KPIs sheet, row 29 (Group, Sep 2026)
A4: 3 | B4: O-01 | C4: Enterprise Health | D4: Card | E4: EBIT YTD (to P06) | F4: FIN-002 | G4: Group | H4: 238.4 ₹ m | I4: ='Owner KPIs'!K30 | J4: Owner KPIs sheet, row 30 (Group, Sep 2026)
A5: 4 | B5: O-01 | C5: Enterprise Health | D5: Card | E5: Free Cash Flow YTD | F5: FIN-004 | G5: Group | H5: 96.4 ₹ m | I5: ='Owner KPIs'!K32 | J5: Owner KPIs sheet, row 32 (Group, Sep 2026)
A6: 5 | B6: O-01 | C6: Enterprise Health | D6: Card | E6: ROCE · rolling 12 m | F6: FIN-005 | G6: Group | H6: 11.8 % | I6: ='Owner KPIs'!K33 | J6: Owner KPIs sheet, row 33 (Group, Sep 2026)
A7: 6 | B7: O-01 | C7: Enterprise Health | D7: Card | E7: Net Debt | F7: FIN-006 | G7: Group | H7: 1,140 ₹ m | I7: ='Owner KPIs'!K34 | J7: Owner KPIs sheet, row 34 (Group, Sep 2026)
A8: 7 | B8: O-01 | C8: Enterprise Health | D8: Card | E8: Capex physical progress | F8: CPX-004 | G8: Group | H8: 61 % weighted | I8: ='Owner KPIs'!K59 | J8: Owner KPIs sheet, row 59 (Group, Sep 2026)
A9: 8 | B9: O-01 | C9: Enterprise Health | D9: Card | E9: Open critical alerts | F9: EFF-002 | G9: Group | H9: 1 alert | I9: ='Owner KPIs'!K106 | J9: Owner KPIs sheet, row 106 (Group, Sep 2026)
A10: 9 | B10: O-01 | C10: Enterprise Health | D10: Tile | E10: Days to breach · Plant 02 plan | F10: PRD-001 | G10: Plant 02 | H10: 4 days | I10: =ROUND('Plant Inputs'!BT15,2) | J10: Same formula on Plant Inputs row 15 (Plant 02, Sep 2026)
A11: 10 | B11: O-01 | C11: Enterprise Health | D11: Tile | E11: Probability of plan miss · P07 | F11: PRD-002 | G11: Group | H11: 64% | I11: ='Owner KPIs'!K114 | J11: Owner KPIs sheet, row 114 (Group, Sep 2026)
A12: 11 | B12: O-01 | C12: Enterprise Health | D12: Tile | E12: Projected EBITDA gap · P07–P12 | F12: PRD-003 | G12: Group | H12: −₹9.2 m | I12: ='Owner KPIs'!K115 | J12: Owner KPIs sheet, row 115 (Group, Sep 2026)
A13: 12 | B13: O-01 | C13: Enterprise Health | D13: Table | E13: Capacity utilization | F13: OPS-003 | G13: Group | H13: 86% | I13: ='Owner KPIs'!K3 | J13: Owner KPIs sheet, row 3 (Group, Sep 2026)
A14: 13 | B14: O-01 | C14: Enterprise Health | D14: Table | E14: Capacity utilisation | F14: OPS-005 | G14: Group | H14: 86% | I14: ='Owner KPIs'!K24 | J14: Owner KPIs sheet, row 24 (Group, Sep 2026)
A15: 14 | B15: O-01 | C15: Enterprise Health | D15: Table | E15: Sales vs plan · MTD | F15: OPS-002 | G15: Group | H15: 97.6% | I15: ='Owner KPIs'!K26 | J15: Owner KPIs sheet, row 26 (Group, Sep 2026)
A16: 15 | B16: O-01 | C16: Enterprise Health | D16: Table | E16: Sales vs plan · Group MTD | F16: OPS-004 | G16: Group | H16: 97.6% | I16: ='Owner KPIs'!K27 | J16: Owner KPIs sheet, row 27 (Group, Sep 2026)
A17: 16 | B17: O-01 | C17: Enterprise Health | D17: Table | E17: EBIT YTD | F17: FIN-002 | G17: Group | H17: 238.4 ₹ m | I17: ='Owner KPIs'!K30 | J17: Owner KPIs sheet, row 30 (Group, Sep 2026)
A18: 17 | B18: O-01 | C18: Enterprise Health | D18: Table | E18: Revenue YTD | F18: FIN-003 | G18: Group | H18: 2,410 ₹ m | I18: ='Owner KPIs'!K31 | J18: Owner KPIs sheet, row 31 (Group, Sep 2026)
A19: 18 | B19: O-01 | C19: Enterprise Health | D19: Table | E19: ROCE (rolling 12 m) | F19: FIN-005 | G19: Group | H19: 11.8% | I19: ='Owner KPIs'!K33 | J19: Owner KPIs sheet, row 33 (Group, Sep 2026)
A20: 19 | B20: O-01 | C20: Enterprise Health | D20: Table | E20: Shareholder-value indicator | F20: FIN-007 | G20: Group | H20: [PLACEHOLDER] | I20: ='Owner KPIs'!K35 | J20: Owner KPIs sheet, row 35 (Group, Sep 2026)
A21: 20 | B21: O-01 | C21: Enterprise Health | D21: Table | E21: Transformation progress (weighted) | F21: PRG-004 | G21: Group | H21: 54% | I21: ='Owner KPIs'!K64 | J21: Owner KPIs sheet, row 64 (Group, Sep 2026)
A22: 21 | B22: O-01 | C22: Enterprise Health | D22: Table | E22: Transformation progress | F22: STR-002 | G22: Group | H22: 54% | I22: ='Owner KPIs'!K65 | J22: Owner KPIs sheet, row 65 (Group, Sep 2026)
A23: 22 | B23: O-01 | C23: Enterprise Health | D23: Table | E23: Regulatory breaches · YTD | F23: RSK-003 | G23: Group | H23: 0 | I23: ='Owner KPIs'!K79 | J23: Owner KPIs sheet, row 79 (Group, Sep 2026)
A24: 23 | B24: O-01 | C24: Enterprise Health | D24: Table | E24: Regulatory breaches · YTD | F24: CMP-005 | G24: Group | H24: 0 | I24: ='Owner KPIs'!K80 | J24: Owner KPIs sheet, row 80 (Group, Sep 2026)
A25: 24 | B25: O-02 | C25: 24-Hour Executive Change Report | D25: Tile | E25: Days to breach · Plant 02 plan | F25: PRD-001 | G25: Plant 02 | H25: 4 days | I25: =ROUND('Plant Inputs'!BT15,2) | J25: Same formula on Plant Inputs row 15 (Plant 02, Sep 2026)
A26: 25 | B26: O-02 | C26: 24-Hour Executive Change Report | D26: Tile | E26: Probability of plan miss · P07 | F26: PRD-002 | G26: Group | H26: 64% | I26: ='Owner KPIs'!K114 | J26: Owner KPIs sheet, row 114 (Group, Sep 2026)
A27: 26 | B27: O-02 | C27: 24-Hour Executive Change Report | D27: Tile | E27: Projected EBITDA gap P07–P12 | F27: PRD-003 | G27: Group | H27: −₹9.2 m | I27: ='Owner KPIs'!K115 | J27: Owner KPIs sheet, row 115 (Group, Sep 2026)
A28: 27 | B28: O-02 | C28: 24-Hour Executive Change Report | D28: Tile | E28: Projected liquidity gap | F28: PRD-004 | G28: Group | H28: None | I28: ='Owner KPIs'!K116 | J28: Owner KPIs sheet, row 116 (Group, Sep 2026)
A29: 28 | B29: O-02 | C29: 24-Hour Executive Change Report | D29: Tile | E29: Forecast covenant breach | F29: PRD-005 | G29: Group | H29: Not forecast | I29: ='Owner KPIs'!K117 | J29: Owner KPIs sheet, row 117 (Group, Sep 2026)
A30: 29 | B30: O-03 | C30: Cash & Liquidity Dashboard | D30: Card | E30: Cash position | F30: CSH-001 | G30: Group | H30: 2,141.8 ₹ m | I30: 2141.82 | J30: Owner KPIs sheet, row 36 (Group, Sep 2026)
A31: 30 | B31: O-03 | C31: Cash & Liquidity Dashboard | D31: Card | E31: Liquidity runway | F31: LIQ-001 | G31: Group | H31: 16.7 months | I31: 16.71 | J31: Owner KPIs sheet, row 47 (Group, Sep 2026)
A32: 31 | B32: O-03 | C32: Cash & Liquidity Dashboard | D32: Card | E32: Net debt | F32: FIN-006 | G32: Group | H32: 6,650.0 ₹ m | I32: 6650 | J32: Owner KPIs sheet, row 34 (Group, Sep 2026)
A33: 32 | B33: O-03 | C33: Cash & Liquidity Dashboard | D33: Card | E33: Debt maturity (next 12 months) | F33: LIQ-003 | G33: Group | H33: 891.4 ₹ m | I33: 891.41 | J33: Owner KPIs sheet, row 49 (Group, Sep 2026)
A34: 33 | B34: O-03 | C34: Cash & Liquidity Dashboard | D34: Card | E34: DSO above target | F34: WCP-001 | G34: Group | H34: 47.0 days | I34: 46.97 | J34: Owner KPIs sheet, row 41 (Group, Sep 2026)
A35: 34 | B35: O-03 | C35: Cash & Liquidity Dashboard | D35: Card | E35: Working capital | F35: WCP-004 | G35: Group | H35: 2,781.0 ₹ m | I35: 2780.99 | J35: Owner KPIs sheet, row 44 (Group, Sep 2026)
A36: 35 | B36: O-03 | C36: Cash & Liquidity Dashboard | D36: Card | E36: FX hedge ratio (next 6 months) | F36: TRS-004 | G36: Group | H36: 70.7 % | I36: 70.65 | J36: Owner KPIs sheet, row 54 (Group, Sep 2026)
A37: 36 | B37: O-03 | C37: Cash & Liquidity Dashboard | D37: Card detail | E37: FX hedge ratio (next 6 months) · Hedged (Sep) | G37: Group | H37: ₹546.0 m | I37: 546 | J37: Group Inputs, fx_hedged_k ÷ 1000 (Sep 2026)
A38: 37 | B38: O-03 | C38: Cash & Liquidity Dashboard | D38: Card detail | E38: FX hedge ratio (next 6 months) · Gross FX exposure (Sep) | G38: Group | H38: ₹767.7 m | I38: 767.72 | J38: Group Inputs, fx_exposure_k ÷ 1000 (Sep 2026)
A39: 38 | B39: O-03 | C39: Cash & Liquidity Dashboard | D39: Card | E39: Financing exposure | F39: LIQ-004 | G39: Group | H39: 2,720.8 ₹ m | I39: 2720.83 | J39: Owner KPIs sheet, row 50 (Group, Sep 2026)
A40: 39 | B40: O-03 | C40: Cash & Liquidity Dashboard | D40: Card | E40: Upstream exposure | F40: CSH-006 | G40: Group | H40: 27.2 ₹ m | I40: 27.21 | J40: Owner KPIs sheet, row 40 (Group, Sep 2026)
...

Sheet Group Inputs
A1: Group | B1: Month | C1: Days in month | D1: Months since April (YTD) | E1: Calendar hours (h) | F1: Planned operating hours (h) | G1: Run hours (h) | H1: Unplanned downtime (h) | I1: Ideal output (t) | J1: Installed capacity (t) | K1: Planned production (t) | L1: Gross output (t) | M1: Good output (t) | N1: Feed input (t) | O1: Valuable content in feed (t) | P1: Valuable content recovered (t) | Q1: Production lost to downtime (t) | R1: Breakdowns (count) | S1: Repair hours (h) | T1: Preventive maintenance scheduled (count) | U1: Preventive maintenance completed (count) | V1: Variable cost (₹ thousand) | W1: Fuel cost (₹ thousand) | X1: Fixed cost (₹ thousand) | Y1: Water used (m³) | Z1: Emissions (t CO2e) | AA1: Energy used (GJ) | AB1: Production at risk (t) | AC1: Critical plant alerts (count) | AD1: Hours worked (h) | AE1: Recordable injuries (count) | AF1: Severity incidents (count) | AG1: Near misses (count) | AH1: Critical safety incidents (count) | AI1: Environmental excursions (count) | AJ1: Environmental violations (count) | AK1: Open EHS corrective actions (count) | AL1: Overdue EHS corrective actions (count) | AM1: EHS investigations due (count) | AN1: EHS investigations completed (count) | AO1: Critical materials at risk (count) | AP1: Dispatches (count) | AQ1: Delayed dispatches (count) | AR1: Days to permit expiry (days) | AS1: Sales volume (t) | AT1: Planned sales volume (t) | AU1: Revenue (₹ thousand) | AV1: Planned revenue (₹ thousand) | AW1: Power cost, part of variable cost (₹ thousand) | AX1: Depreciation and amortisation (₹ thousand) | AY1: Purchase-order lines due (count) | AZ1: Purchase-order lines delivered on time (count) | BA1: Quantity ordered from suppliers (t) | BB1: Quantity received (t) | BC1: Quantity rejected on quality (t) | BD1: Planned lead time, all deliveries (days) | BE1: Actual lead time, all deliveries (days) | BF1: Supplier spend (₹ thousand) | BG1: Spend with single-source suppliers (₹ thousand) | BH1: Supplier EHS incidents (count) | BI1: Regulatory filings pending (count) | BJ1: Regulatory deadlines in next 30 days (count) | BK1: Licences expiring in next 12 months (count) | BL1: Regulatory obligations due in next 30 days (count) | BM1: Regulatory obligations overdue (count) | BN1: Open regulatory actions (count) | BO1: Overdue compliance actions (count) | BP1: Regulatory breaches in the month (count) | BQ1: Events that trigger a disclosure clock (count) | BR1: EHS escalation clocks running (count) | BS1: Days until production plan is breached, forecast (days; 99 = not expected) | BT1: Planned production next month (t) | BU1: Forecast good output next month (t) | BV1: Forecast uncertainty next month (variance, t²) | BW1: Ideal output next month (t) | BX1: Forecast production lost to downtime next month (t) | BY1: Overheads, SG&A (₹ thousand) | BZ1: Tax paid (₹ thousand) | CA1: Capital employed, month end (₹ thousand) | CB1: Gross debt, month end (₹ thousand) | CC1: Cash, month end (₹ thousand) | CD1: Undrawn committed facilities (₹ thousand) | CE1: Debt service in the month (₹ thousand) | CF1: Debt maturing in next 12 months (₹ thousand) | CG1: Floating-rate debt (₹ thousand) | CH1: EBITDA as reported in the Board pack (₹ thousand) | CI1: Revenue in the flash report (₹ thousand) | CJ1: Trade receivables, month end (₹ thousand) | CK1: Trade payables, month end (₹ thousand) | CL1: Inventory, month end (₹ thousand) | CM1: Cash collected from customers (₹ thousand) | CN1: Cash released by working-capital actions (₹ thousand) | CO1: Cash due to be upstreamed to Group, next 30 days (₹ thousand) | CP1: Of which covered by available cash (₹ thousand) | CQ1: Invoices collected (count) | CR1: Days taken to collect, all invoices (days) | CS1: Agreed payment terms, all invoices (days) | CT1: Customers more than 30 days overdue (count) | CU1: Forecast EBITDA, rest of year (₹ thousand) | CV1: Planned EBITDA, rest of year (₹ thousand) | CW1: Forecast net cash flow, next 90 days (₹ thousand) | CX1: Forecast net debt at quarter end (₹ thousand) | CY1: Forecast EBITDA, 12 months to quarter end (₹ thousand) | CZ1: Foreign-currency exposure, gross (₹ thousand) | DA1: Foreign-currency exposure hedged (₹ thousand) | DB1: USD exposure, gross (₹ thousand) | DC1: USD exposure hedged (₹ thousand) | DD1: Change in value of hedges (₹ thousand) | DE1: Change in value of hedged items (₹ thousand) | DF1: Forecast foreign-currency flows, next 6 months (₹ thousand) | DG1: Of which hedged (₹ thousand) | DH1: Approved capex budget, full year (₹ thousand) | DI1: Capex committed to date (₹ thousand) | DJ1: Capex spent in the month (₹ thousand) | DK1: Capex work completed, valued at budget (₹ thousand) | DL1: Budget of capex projects at risk (₹ thousand) | DM1: Capex projects on track (count) | DN1: Capex projects at risk (count) | DO1: Capex projects off track (count) | DP1: Capex projects delayed (count) | DQ1: Contractor milestones due (count) | DR1: Contractor days late, all milestones (days) | DS1: Transformation initiatives on track (count) | DT1: Transformation initiatives at risk (count) | DU1: Transformation initiatives delayed (count) | DV1: Transformation milestones in plan (count) | DW1: Transformation milestones completed (count) | DX1: Programme benefits planned in the month (₹ thousand) | DY1: Programme benefits delivered in the month (₹ thousand) | DZ1: EBITDA benefit delivered (₹ thousand) | EA1: Cash benefit delivered (₹ thousand) | EB1: Cost savings delivered (₹ thousand) | EC1: Active supply contracts (count) | ED1: Contracts fully compliant (count) | EE1: Contracts expiring in next 90 days (count) | EF1: Suppliers not meeting EHS requirements (count) | EG1: Critical single-source suppliers (count) | EH1: Control failures (count) | EI1: High-severity control failures (count) | EJ1: Assurance reviews planned (count) | EK1: Assurance reviews completed (count) | EL1: Policy exceptions (count) | EM1: Unauthorised vendor uses (count) | EN1: Segregation-of-duties exceptions (count) | EO1: Unauthorised access events (count) | EP1: Data-sharing exceptions (count) | EQ1: Manual operational or system overrides (count) | ER1: Certification approvals past due date (count) | ES1: KPI values overridden (count) | ET1: Recurring data-quality issues (count) | EU1: Open audit findings (count) | EV1: Overdue assurance actions (count) | EW1: Repeat audit findings (count) | EX1: Leadership KPIs affected by open findings (count) | EY1: Evidence items required (count) | EZ1: Evidence items complete (count) | FA1: Audit findings closed in the month (count) | FB1: Days taken to close those findings (days) | FC1: Leadership KPI values reported (count) | FD1: Of which certified (count) | FE1: Of which inside the certification process (count) | FF1: Certifications overdue (count) | FG1: Open reconciliation breaks (count) | FH1: Material reconciliation breaks (count) | FI1: Records loaded to the data lake (count) | FJ1: Records reconciled to source (count) | FK1: Flash report lines (count) | FL1: Flash lines matching MIS (count) | FM1: Open critical alerts (count) | FN1: Alerts with no accepted owner (count) | FO1: Overdue actions (count) | FP1: Alerts resolved in the month (count) | FQ1: Days taken to resolve those alerts (days) | FR1: Escalations closed in the month (count) | FS1: Repeat issues raised in the month (count) | FT1: Root causes identified (count) | FU1: Root causes eliminated (count) | FV1: EBITDA (₹ thousand) | FW1: EBIT (₹ thousand) | FX1: Net working capital (₹ thousand) | FY1: Change in net working capital (₹ thousand) | FZ1: Operating cash flow (₹ thousand) | GA1: Free cash flow (₹ thousand) | GB1: Net debt (₹ thousand) | GC1: EBITDA, annualised (₹ thousand) | GD1: DSO (days) | GE1: DPO (days) | GF1: Inventory days (days) | GG1: Realised price vs plan (%)
A2: group | B2: period | C2: days | D2: ytd_months | E2: calendar_hours | F2: planned_op_hours | G2: run_hours | H2: unplanned_downtime_hours | I2: ideal_output_t | J2: installed_capacity_t | K2: planned_production_t | L2: gross_output_t | M2: good_output_t | N2: feed_input_t | O2: feed_contained_t | P2: recovered_contained_t | Q2: prod_loss_downtime_t | R2: failures | S2: repair_hours | T2: pm_scheduled | U2: pm_completed | V2: variable_cost_k | W2: fuel_cost_k | X2: fixed_cost_k | Y2: water_m3 | Z2: emissions_tco2e | AA2: energy_gj | AB2: production_at_risk_t | AC2: critical_plant_alerts | AD2: hours_worked | AE2: recordable_injuries | AF2: severity_incidents | AG2: near_misses | AH2: critical_safety_incidents | AI2: env_excursions | AJ2: env_violations | AK2: ehs_ca_open | AL2: ehs_ca_overdue | AM2: investigations_due | AN2: investigations_completed | AO2: critical_material_risks | AP2: dispatches_total | AQ2: dispatches_delayed | AR2: permit_days_to_expiry | AS2: sales_t | AT2: planned_sales_t | AU2: revenue_k | AV2: planned_revenue_k | AW2: power_cost_k | AX2: depreciation_k | AY2: po_lines_due | AZ2: po_lines_on_time | BA2: qty_ordered_t | BB2: qty_received_t | BC2: qty_rejected_t | BD2: lead_time_planned_days | BE2: lead_time_actual_days | BF2: supplier_spend_k | BG2: single_source_spend_k | BH2: supplier_ehs_incidents | BI2: pending_filings | BJ2: reg_deadlines_30d | BK2: licences_expiring_12m | BL2: reg_obligations_due_30d | BM2: reg_obligations_overdue | BN2: reg_actions_open | BO2: compliance_actions_overdue | BP2: reg_breaches | BQ2: disclosure_events_open | BR2: ehs_escalation_clocks | BS2: days_to_breach | BT2: planned_production_next_t | BU2: forecast_good_next_t | BV2: forecast_good_var_next | BW2: ideal_output_next_t | BX2: forecast_downtime_loss_next_t | BY2: overhead_k | BZ2: tax_paid_k | CA2: capital_employed_k | CB2: gross_debt_k | CC2: cash_k | CD2: undrawn_facilities_k | CE2: debt_service_k | CF2: debt_maturing_12m_k | CG2: floating_rate_debt_k | CH2: board_ebitda_k | CI2: flash_revenue_k | CJ2: receivables_k | CK2: payables_k | CL2: inventory_k | CM2: collections_k | CN2: cash_released_k | CO2: upstream_due_k | CP2: upstream_covered_k | CQ2: invoices_collected | CR2: collection_days | CS2: terms_days | CT2: customers_overdue | CU2: forecast_ebitda_rest_k | CV2: planned_ebitda_rest_k | CW2: forecast_net_cash_flow_90d_k | CX2: forecast_net_debt_k | CY2: forecast_ebitda_ltm_k | CZ2: fx_exposure_k | DA2: fx_hedged_k | DB2: usd_exposure_k | DC2: usd_hedged_k | DD2: hedge_value_change_k | DE2: hedged_item_value_change_k | DF2: fx_flows_6m_k | DG2: fx_hedged_6m_k | DH2: capex_budget_k | DI2: capex_committed_k | DJ2: capex_spend_k | DK2: capex_earned_value_k | DL2: capex_at_risk_k | DM2: projects_on_track | DN2: projects_at_risk | DO2: projects_off_track | DP2: projects_delayed | DQ2: contractor_milestones_due | DR2: contractor_days_late | DS2: initiatives_on_track | DT2: initiatives_at_risk | DU2: initiatives_delayed | DV2: milestones_total | DW2: milestones_done | DX2: benefits_planned_k | DY2: benefits_delivered_k | DZ2: ebitda_benefit_k | EA2: cash_benefit_k | EB2: cost_savings_k | EC2: contracts_total | ED2: contracts_compliant | EE2: contracts_expiring_90d | EF2: supplier_ehs_noncompliance | EG2: single_source_suppliers | EH2: control_failures | EI2: control_failures_high | EJ2: assurance_reviews_planned | EK2: assurance_reviews_done | EL2: policy_exceptions | EM2: unauthorized_vendor_uses | EN2: sod_exceptions | EO2: unauthorized_access_events | EP2: data_sharing_exceptions | EQ2: manual_overrides | ER2: cert_approvals_ageing | ES2: kpi_overrides | ET2: dq_issues_recurring | EU2: audit_findings_open | EV2: assurance_actions_overdue | EW2: repeat_findings | EX2: leadership_kpis_affected | EY2: evidence_required | EZ2: evidence_complete | FA2: findings_closed | FB2: finding_closure_days | FC2: kpis_leadership | FD2: kpis_certified | FE2: kpis_in_scope | FF2: certifications_overdue | FG2: recon_breaks_open | FH2: recon_breaks_material | FI2: lake_records_loaded | FJ2: lake_records_reconciled | FK2: mis_lines_total | FL2: mis_lines_matched | FM2: critical_alerts_open | FN2: alerts_unowned | FO2: actions_overdue | FP2: alerts_resolved | FQ2: alert_resolution_days | FR2: escalations_closed | FS2: repeat_issues | FT2: root_causes_identified | FU2: root_causes_eliminated | FV2: ebitda_k | FW2: ebit_k | FX2: nwc_k | FY2: nwc_change_k | FZ2: op_cash_flow_k | GA2: fcf_k | GB2: net_debt_k | GC2: ebitda_annualised_k | GD2: dso_d | GE2: dpo_d | GF2: dio_d | GG2: price_vs_plan_pct
E3: Sum of Entity A1 and Entity A2 (Entity Inputs sheet) | F3: Sum of Entity A1 and Entity A2 (Entity Inputs sheet) | G3: Sum of Entity A1 and Entity A2 (Entity Inputs sheet) | H3: Sum of Entity A1 and Entity A2 (Entity Inputs sheet) | I3: Sum of Entity A1 and Entity A2 (Entity Inputs sheet) | J3: Sum of Entity A1 and Entity A2 (Entity Inputs sheet) | K3: Sum of Entity A1 and Entity A2 (Entity Inputs sheet) | L3: Sum of Entity A1 and Entity A2 (Entity Inputs sheet) | M3: Sum of Entity A1 and Entity A2 (Entity Inputs sheet) | N3: Sum of Entity A1 and Entity A2 (Entity Inputs sheet) | O3: Sum of Entity A1 and Entity A2 (Entity Inputs sheet) | P3: Sum of Entity A1 and Entity A2 (Entity Inputs sheet) | Q3: Sum of Entity A1 and Entity A2 (Entity Inputs sheet) | R3: Sum of Entity A1 and Entity A2 (Entity Inputs sheet) | S3: Sum of Entity A1 and Entity A2 (Entity Inputs sheet) | T3: Sum of Entity A1 and Entity A2 (Entity Inputs sheet) | U3: Sum of Entity A1 and Entity A2 (Entity Inputs sheet) | V3: Sum of Entity A1 and Entity A2 (Entity Inputs sheet) | W3: Sum of Entity A1 and Entity A2 (Entity Inputs sheet) | X3: Sum of Entity A1 and Entity A2 (Entity Inputs sheet) | Y3: Sum of Entity A1 and Entity A2 (Entity Inputs sheet) | Z3: Sum of Entity A1 and Entity A2 (Entity Inputs sheet) | AA3: Sum of Entity A1 and Entity A2 (Entity Inputs sheet) | AB3: Sum of Entity A1 and Entity A2 (Entity Inputs sheet) | AC3: Sum of Entity A1 and Entity A2 (Entity Inputs sheet) | AD3: Sum of Entity A1 and Entity A2 (Entity Inputs sheet) | AE3: Sum of Entity A1 and Entity A2 (Entity Inputs sheet) | AF3: Sum of Entity A1 and Entity A2 (Entity Inputs sheet) | AG3: Sum of Entity A1 and Entity A2 (Entity Inputs sheet) | AH3: Sum of Entity A1 and Entity A2 (Entity Inputs sheet) | AI3: Sum of Entity A1 and Entity A2 (Entity Inputs sheet) | AJ3: Sum of Entity A1 and Entity A2 (Entity Inputs sheet) | AK3: Sum of Entity A1 and Entity A2 (Entity Inputs sheet) | AL3: Sum of Entity A1 and Entity A2 (Entity Inputs sheet) | AM3: Sum of Entity A1 and Entity A2 (Entity Inputs sheet) | AN3: Sum of Entity A1 and Entity A2 (Entity Inputs sheet) | AO3: Sum of Entity A1 and Entity A2 (Entity Inputs sheet) | AP3: Sum of Entity A1 and Entity A2 (Entity Inputs sheet) | AQ3: Sum of Entity A1 and Entity A2 (Entity Inputs sheet) | AR3: Lowest of Entity A1 and Entity A2 (Entity Inputs sheet) | AS3: Sum of Entity A1 and Entity A2 (Entity Inputs sheet) | AT3: Sum of Entity A1 and Entity A2 (Entity Inputs sheet) | AU3: Sum of Entity A1 and Entity A2 (Entity Inputs sheet) | AV3: Sum of Entity A1 and Entity A2 (Entity Inputs sheet) | AW3: Sum of Entity A1 and Entity A2 (Entity Inputs sheet) | AX3: Sum of Entity A1 and Entity A2 (Entity Inputs sheet) | AY3: Sum of Entity A1 and Entity A2 (Entity Inputs sheet) | AZ3: Sum of Entity A1 and Entity A2 (Entity Inputs sheet) | BA3: Sum of Entity A1 and Entity A2 (Entity Inputs sheet) | BB3: Sum of Entity A1 and Entity A2 (Entity Inputs sheet) | BC3: Sum of Entity A1 and Entity A2 (Entity Inputs sheet) | BD3: Sum of Entity A1 and Entity A2 (Entity Inputs sheet) | BE3: Sum of Entity A1 and Entity A2 (Entity Inputs sheet) | BF3: Sum of Entity A1 and Entity A2 (Entity Inputs sheet) | BG3: Sum of Entity A1 and Entity A2 (Entity Inputs sheet) | BH3: Sum of Entity A1 and Entity A2 (Entity Inputs sheet) | BI3: Sum of Entity A1 and Entity A2 (Entity Inputs sheet) | BJ3: Sum of Entity A1 and Entity A2 (Entity Inputs sheet) | BK3: Sum of Entity A1 and Entity A2 (Entity Inputs sheet) | BL3: Sum of Entity A1 and Entity A2 (Entity Inputs sheet) | BM3: Sum of Entity A1 and Entity A2 (Entity Inputs sheet) | BN3: Sum of Entity A1 and Entity A2 (Entity Inputs sheet) | BO3: Sum of Entity A1 and Entity A2 (Entity Inputs sheet) | BP3: Sum of Entity A1 and Entity A2 (Entity Inputs sheet) | BQ3: Sum of Entity A1 and Entity A2 (Entity Inputs sheet) | BR3: Sum of Entity A1 and Entity A2 (Entity Inputs sheet) | BS3: Lowest of Entity A1 and Entity A2 (Entity Inputs sheet) | BT3: Sum of Entity A1 and Entity A2 (Entity Inputs sheet) | BU3: Sum of Entity A1 and Entity A2 (Entity Inputs sheet) | BV3: Sum of Entity A1 and Entity A2 (Entity Inputs sheet) | BW3: Sum of Entity A1 and Entity A2 (Entity Inputs sheet) | BX3: Sum of Entity A1 and Entity A2 (Entity Inputs sheet) | BY3: Sum of Entity A1 and Entity A2 (Entity Inputs sheet) | BZ3: Sum of Entity A1 and Entity A2 (Entity Inputs sheet) | CA3: Sum of Entity A1 and Entity A2 (Entity Inputs sheet) | CB3: Sum of Entity A1 and Entity A2 (Entity Inputs sheet) | CC3: Sum of Entity A1 and Entity A2 (Entity Inputs sheet) | CD3: Sum of Entity A1 and Entity A2 (Entity Inputs sheet) | CE3: Sum of Entity A1 and Entity A2 (Entity Inputs sheet) | CF3: Sum of Entity A1 and Entity A2 (Entity Inputs sheet) | CG3: Sum of Entity A1 and Entity A2 (Entity Inputs sheet) | CH3: Sum of Entity A1 and Entity A2 (Entity Inputs sheet) | CI3: Sum of Entity A1 and Entity A2 (Entity Inputs sheet) | CJ3: Sum of Entity A1 and Entity A2 (Entity Inputs sheet) | CK3: Sum of Entity A1 and Entity A2 (Entity Inputs sheet) | CL3: Sum of Entity A1 and Entity A2 (Entity Inputs sheet) | CM3: Sum of Entity A1 and Entity A2 (Entity Inputs sheet) | CN3: Sum of Entity A1 and Entity A2 (Entity Inputs sheet) | CO3: Sum of Entity A1 and Entity A2 (Entity Inputs sheet) | CP3: Sum of Entity A1 and Entity A2 (Entity Inputs sheet) | CQ3: Sum of Entity A1 and Entity A2 (Entity Inputs sheet) | CR3: Sum of Entity A1 and Entity A2 (Entity Inputs sheet) | CS3: Sum of Entity A1 and Entity A2 (Entity Inputs sheet) | CT3: Sum of Entity A1 and Entity A2 (Entity Inputs sheet) | CU3: Sum of Entity A1 and Entity A2 (Entity Inputs sheet) | CV3: Sum of Entity A1 and Entity A2 (Entity Inputs sheet) | CW3: Sum of Entity A1 and Entity A2 (Entity Inputs sheet) | CX3: Sum of Entity A1 and Entity A2 (Entity Inputs sheet) | CY3: Sum of Entity A1 and Entity A2 (Entity Inputs sheet) | CZ3: Sum of Entity A1 and Entity A2 (Entity Inputs sheet) | DA3: Sum of Entity A1 and Entity A2 (Entity Inputs sheet) | DB3: Sum of Entity A1 and Entity A2 (Entity Inputs sheet) | DC3: Sum of Entity A1 and Entity A2 (Entity Inputs sheet) | DD3: Sum of Entity A1 and Entity A2 (Entity Inputs sheet) | DE3: Sum of Entity A1 and Entity A2 (Entity Inputs sheet) | DF3: Sum of Entity A1 and Entity A2 (Entity Inputs sheet) | DG3: Sum of Entity A1 and Entity A2 (Entity Inputs sheet) | DH3: Sum of Entity A1 and Entity A2 (Entity Inputs sheet) | DI3: Sum of Entity A1 and Entity A2 (Entity Inputs sheet) | DJ3: Sum of Entity A1 and Entity A2 (Entity Inputs sheet) | DK3: Sum of Entity A1 and Entity A2 (Entity Inputs sheet) | DL3: Sum of Entity A1 and Entity A2 (Entity Inputs sheet) | DM3: Sum of Entity A1 and Entity A2 (Entity Inputs sheet) | DN3: Sum of Entity A1 and Entity A2 (Entity Inputs sheet) | DO3: Sum of Entity A1 and Entity A2 (Entity Inputs sheet) | DP3: Sum of Entity A1 and Entity A2 (Entity Inputs sheet) | DQ3: Sum of Entity A1 and Entity A2 (Entity Inputs sheet) | DR3: Sum of Entity A1 and Entity A2 (Entity Inputs sheet) | DS3: Sum of Entity A1 and Entity A2 (Entity Inputs sheet) | DT3: Sum of Entity A1 and Entity A2 (Entity Inputs sheet) | DU3: Sum of Entity A1 and Entity A2 (Entity Inputs sheet) | DV3: Sum of Entity A1 and Entity A2 (Entity Inputs sheet) | DW3: Sum of Entity A1 and Entity A2 (Entity Inputs sheet) | DX3: Sum of Entity A1 and Entity A2 (Entity Inputs sheet) | DY3: Sum of Entity A1 and Entity A2 (Entity Inputs sheet) | DZ3: Sum of Entity A1 and Entity A2 (Entity Inputs sheet) | EA3: Sum of Entity A1 and Entity A2 (Entity Inputs sheet) | EB3: Sum of Entity A1 and Entity A2 (Entity Inputs sheet) | EC3: Sum of Entity A1 and Entity A2 (Entity Inputs sheet) | ED3: Sum of Entity A1 and Entity A2 (Entity Inputs sheet) | EE3: Sum of Entity A1 and Entity A2 (Entity Inputs sheet) | EF3: Sum of Entity A1 and Entity A2 (Entity Inputs sheet) | EG3: Sum of Entity A1 and Entity A2 (Entity Inputs sheet) | EH3: Sum of Entity A1 and Entity A2 (Entity Inputs sheet) | EI3: Sum of Entity A1 and Entity A2 (Entity Inputs sheet) | EJ3: Sum of Entity A1 and Entity A2 (Entity Inputs sheet) | EK3: Sum of Entity A1 and Entity A2 (Entity Inputs sheet) | EL3: Sum of Entity A1 and Entity A2 (Entity Inputs sheet) | EM3: Sum of Entity A1 and Entity A2 (Entity Inputs sheet) | EN3: Sum of Entity A1 and Entity A2 (Entity Inputs sheet) | EO3: Sum of Entity A1 and Entity A2 (Entity Inputs sheet) | EP3: Sum of Entity A1 and Entity A2 (Entity Inputs sheet) | EQ3: Sum of Entity A1 and Entity A2 (Entity Inputs sheet) | ER3: Sum of Entity A1 and Entity A2 (Entity Inputs sheet) | ES3: Sum of Entity A1 and Entity A2 (Entity Inputs sheet) | ET3: Sum of Entity A1 and Entity A2 (Entity Inputs sheet) | EU3: Sum of Entity A1 and Entity A2 (Entity Inputs sheet) | EV3: Sum of Entity A1 and Entity A2 (Entity Inputs sheet) | EW3: Sum of Entity A1 and Entity A2 (Entity Inputs sheet) | EX3: Sum of Entity A1 and Entity A2 (Entity Inputs sheet) | EY3: Sum of Entity A1 and Entity A2 (Entity Inputs sheet) | EZ3: Sum of Entity A1 and Entity A2 (Entity Inputs sheet) | FA3: Sum of Entity A1 and Entity A2 (Entity Inputs sheet) | FB3: Sum of Entity A1 and Entity A2 (Entity Inputs sheet) | FC3: Sum of Entity A1 and Entity A2 (Entity Inputs sheet) | FD3: Sum of Entity A1 and Entity A2 (Entity Inputs sheet) | FE3: Sum of Entity A1 and Entity A2 (Entity Inputs sheet) | FF3: Sum of Entity A1 and Entity A2 (Entity Inputs sheet) | FG3: Sum of Entity A1 and Entity A2 (Entity Inputs sheet) | FH3: Sum of Entity A1 and Entity A2 (Entity Inputs sheet) | FI3: Sum of Entity A1 and Entity A2 (Entity Inputs sheet) | FJ3: Sum of Entity A1 and Entity A2 (Entity Inputs sheet) | FK3: Sum of Entity A1 and Entity A2 (Entity Inputs sheet) | FL3: Sum of Entity A1 and Entity A2 (Entity Inputs sheet) | FM3: Sum of Entity A1 and Entity A2 (Entity Inputs sheet) | FN3: Sum of Entity A1 and Entity A2 (Entity Inputs sheet) | FO3: Sum of Entity A1 and Entity A2 (Entity Inputs sheet) | FP3: Sum of Entity A1 and Entity A2 (Entity Inputs sheet) | FQ3: Sum of Entity A1 and Entity A2 (Entity Inputs sheet) | FR3: Sum of Entity A1 and Entity A2 (Entity Inputs sheet) | FS3: Sum of Entity A1 and Entity A2 (Entity Inputs sheet) | FT3: Sum of Entity A1 and Entity A2 (Entity Inputs sheet) | FU3: Sum of Entity A1 and Entity A2 (Entity Inputs sheet) | FV3: Calculated: Revenue − Variable cost − Fixed cost − Overheads | FW3: Calculated: EBITDA − Depreciation and amortisation | FX3: Calculated: Trade receivables + Inventory − Trade payables | FY3: Calculated: Net working capital − last month's net working capital (April uses the 31 March balance on Parameters) | FZ3: Calculated: EBITDA − Tax paid − Change in net working capital | GA3: Calculated: Operating cash flow − Capex spent | GB3: Calculated: Gross debt − Cash | GC3: Calculated: EBITDA since April × 12 ÷ months elapsed | GD3: Calculated: Trade receivables ÷ Revenue × Days in month | GE3: Calculated: Trade payables ÷ Variable cost × Days in month | GF3: Calculated: Inventory ÷ Variable cost × Days in month | GG3: Calculated: (Revenue ÷ Sales volume) ÷ (Planned revenue ÷ Planned sales volume) − 1, as %
A4: Group | B4: 2026-04 | C4: 30 | D4: 1 | E4: =SUM('Entity Inputs'!E4,'Entity Inputs'!E10) | F4: =SUM('Entity Inputs'!F4,'Entity Inputs'!F10) | G4: =SUM('Entity Inputs'!G4,'Entity Inputs'!G10) | H4: =SUM('Entity Inputs'!H4,'Entity Inputs'!H10) | I4: =SUM('Entity Inputs'!I4,'Entity Inputs'!I10) | J4: =SUM('Entity Inputs'!J4,'Entity Inputs'!J10) | K4: =SUM('Entity Inputs'!K4,'Entity Inputs'!K10) | L4: =SUM('Entity Inputs'!L4,'Entity Inputs'!L10) | ... AQ4: =SUM('Entity Inputs'!AQ4,'Entity Inputs'!AQ10) | AR4: =MIN('Entity Inputs'!AR4,'Entity Inputs'!AR10) | AS4: =SUM('Entity Inputs'!AS4,'Entity Inputs'!AS10) | AT4: =SUM('Entity Inputs'!AT4,'Entity Inputs'!AT10) | AU4: =SUM('Entity Inputs'!AU4,'Entity Inputs'!AU10) | AV4: =SUM('Entity Inputs'!AV4,'Entity Inputs'!AV10) | AW4: =SUM('Entity Inputs'!AW4,'Entity Inputs'!AW10) | AX4: =SUM('Entity Inputs'!AX4,'Entity Inputs'!AX10) | AY4: =SUM('Entity Inputs'!AY4,'Entity Inputs'!AY10) | AZ4: =SUM('Entity Inputs'!AZ4,'Entity Inputs'!AZ10) | ... BR4: =SUM('Entity Inputs'!BR4,'Entity Inputs'!BR10) | BS4: =MIN('Entity Inputs'!BS4,'Entity Inputs'!BS10) | BT4: =SUM('Entity Inputs'!BT4,'Entity Inputs'!BT10) | BU4: =SUM('Entity Inputs'!BU4,'Entity Inputs'!BU10) | BV4: =SUM('Entity Inputs'!BV4,'Entity Inputs'!BV10) | BW4: =SUM('Entity Inputs'!BW4,'Entity Inputs'!BW10) | BX4: =SUM('Entity Inputs'!BX4,'Entity Inputs'!BX10) | BY4: =SUM('Entity Inputs'!BY4,'Entity Inputs'!BY10) | BZ4: =SUM('Entity Inputs'!BZ4,'Entity Inputs'!BZ10) | CA4: =SUM('Entity Inputs'!CA4,'Entity Inputs'!CA10) | ... FU4: =SUM('Entity Inputs'!FU4,'Entity Inputs'!FU10) | FV4: =AU4-V4-X4-BY4 | FW4: =FV4-AX4 | FX4: =CJ4+CL4-CK4 | FY4: =FX4-Parameters!$B$7 | FZ4: =FV4-BZ4-FY4 | GA4: =FZ4-DJ4 | GB4: =CB4-CC4 | GC4: =SUM(FV$4:FV4)*12/D4 | GD4: =IF(AU4=0,0,CJ4/AU4*C4) | GE4: =IF(V4=0,0,CK4/V4*C4) | GF4: =IF(V4=0,0,CL4/V4*C4) | GG4: =IF(OR(AS4=0,AT4=0,AV4=0),0,100*((AU4/AS4)/(AV4/AT4)-1))
