Workbook

Sheet Read Me
A1: KPI lineage model: every KPI on the mockups, calculated bottom up
A2: All data is synthetic (mock) data. plant_base.csv is the original plant data; the other inputs were added so every KPI on the mockups can be calculated. Every KPI value in this workbook is a live formula; click any value to see it.
A4: How the numbers flow
A5: 1. Plant Inputs: one row per plant per month (6 plants × Apr–Sep 2026).
A6: 2. Entity Inputs: each plant input is the sum of the entity's 3 plants (Entity A1 = Plants 01–03, A2 = Plants 04–06); days to permit expiry, days to breach and disclosure clock take the lowest. Yellow inputs only exist at entity level (finance, cash, treasury, capex, programmes, controls, governance, data trust, workflow). Blue columns are building blocks (EBITDA, net working capital, DSO …) calculated from the inputs.
A7: 3. Group Inputs: each input is the sum (or lowest) of Entity A1 and Entity A2, with the same building blocks.
A8: 4. Plant KPIs, Entity KPIs, Group KPIs: the same formula applied at each level to that level's own totals. A KPI is never an average of the level below. Plant KPIs exist only where every input exists at plant level.
A10: Sheets
A11: Coverage: every KPI ID on the mockups, whether it is in this workbook, which lenses and screens show it.
A12: KPI Register: one row per KPI with its formula, inputs, where the inputs come from, the bottom-up path, the Sep 2026 value at every plant, entity and the Group, and what the mockups show.
A13: Lineage (Sep 2026): for each KPI, every input traced from the 6 plants to the 2 entities to the Group, then the result at each level.
A14: Screen Values: every KPI on every mockup screen (Owner, Core Group, Entity lenses), the value shown, the calculated value for the same scope, and Same / Different (at the precision the screen shows).
... A18: Formulas are working assumptions until the KPI catalogue definitions are approved. Some IDs on the mockups are the same measure and show the same value: OPS-005 = OPS-003, OPS-006 = PLT-002, OPS-004 = OPS-002, PRG-004 = STR-002, RSK-003 = CMP-005 = REG-010.

Sheet Coverage
A1: Coverage of the mockup KPIs
A2: 160 KPI IDs appear on the mockups, 556 times in total. Covered in this workbook: 160 of 160.
A4: KPI ID | B4: Measure | C4: In this workbook | D4: Calculated at | E4: Owner screens | F4: Core Group screens | G4: Entity screens | H4: Screens | I4: Appearances
A5: CMP-005 | B5: Regulatory breaches YTD (same measure as REG-010) | C5: Yes | D5: Plant, Entity, Group | E5: 1 | G5: 1 | H5: E-01, O-01 | I5: 2
A6: CON-001 | B6: Contracts expiring, next 90 days | C6: Yes | D6: Entity, Group | E6: 1 | F6: 1 | G6: 2 | H6: E-04, E-07, G-07, O-05 | I6: 5
A7: CON-002 | B7: Contract-compliance rate | C7: Yes | D7: Entity, Group | E7: 1 | F7: 1 | G7: 2 | H7: E-04, E-07, G-07, O-05 | I7: 4
A8: CON-003 | B8: Supplier EHS non-compliance | C8: Yes | D8: Entity, Group | E8: 1 | F8: 2 | G8: 2 | H8: E-04, E-07, G-05, G-07, O-05 | I8: 5
A9: CPX-001 | B9: Approved capex budget | C9: Yes | D9: Entity, Group | E9: 1 | F9: 1 | G9: 1 | H9: E-06, G-06, O-04 | I9: 3
A10: CPX-002 | B10: Committed capex | C10: Yes | D10: Entity, Group | E10: 1 | F10: 1 | G10: 1 | H10: E-06, G-06, O-04 | I10: 3
A11: CPX-003 | B11: Capex actual spend YTD | C11: Yes | D11: Entity, Group | E11: 1 | F11: 1 | G11: 1 | H11: E-06, G-06, O-04 | I11: 3
A12: CPX-004 | B12: Capex physical progress, weighted | C12: Yes | D12: Entity, Group | E12: 4 | F12: 3 | G12: 1 | H12: E-06, G-01, G-01 · after T7, G-06, O-01, O-04, STATE GALLERY · O-01 + S-02, O-01 · large display ≥ 1600 | I12: 8
A13: CSH-001 | B13: Cash position | C13: Yes | D13: Entity, Group | E13: 1 | F13: 1 | G13: 1 | H13: E-05, G-04, O-03 | I13: 3
A14: CSH-002 | B14: Cash released YTD | C14: Yes | D14: Entity, Group | E14: 1 | F14: 1 | G14: 1 | H14: E-05, G-04, O-03 | I14: 3
A15: CSH-003 | B15: Daily collections | C15: Yes | D15: Entity, Group | E15: 2 | F15: 1 | G15: 2 | H15: E-01, E-05, G-04, O-03, S-11 | I15: 5
A16: CSH-004 | B16: Cash-conversion cycle | C16: Yes | D16: Entity, Group | E16: 1 | F16: 1 | G16: 1 | H16: E-05, G-04, O-03 | I16: 3
A17: CSH-006 | B17: Cash-upstream exposure | C17: Yes | D17: Entity, Group | E17: 2 | F17: 1 | G17: 2 | H17: E-01, E-05, G-04, O-03, S-11 | I17: 5
... A19: CST-002 | B19: Variable cost | C19: Yes | D19: Plant, Entity, Group | E19: 1 | F19: 1 | G19: 2 | H19: E-02, E-11, G-03, O-09 | I19: 4
A20: CST-003 | B20: Fuel cost | C20: Yes | D20: Plant, Entity, Group | E20: 1 | G20: 1 | H20: E-02, O-09 | I20: 2
A21: CST-004 | B21: Power cost per tonne | C21: Yes | D21: Plant, Entity, Group | E21: 1 | H21: O-09 | I21: 1
A22: CST-005 | B22: Fixed cost YTD | C22: Yes | D22: Plant, Entity, Group | G22: 1 | H22: E-11 | I22: 1
A23: CTL-002 | B23: Control failures YTD | C23: Yes | D23: Entity, Group | E23: 1 | F23: 1 | G23: 1 | H23: E-07, G-07, O-05 | I23: 3
A24: CTL-003 | B24: Assurance reviews completed | C24: Yes | D24: Entity, Group | F24: 1 | H24: G-07 | I24: 1
A25: CTL-004 | B25: High-severity control failures YTD | C25: Yes | D25: Entity, Group | E25: 1 | F25: 1 | H25: G-07, O-05 | I25: 2
A26: CTL-005 | B26: Policy exceptions YTD | C26: Yes | D26: Entity, Group | E26: 1 | F26: 1 | G26: 1 | H26: E-07, G-07, O-05 | I26: 3
A27: CTL-006 | B27: Unauthorised-vendor usage YTD | C27: Yes | D27: Entity, Group | E27: 1 | F27: 1 | G27: 2 | H27: E-04, E-07, G-07, O-05 | I27: 4
A28: CTL-007 | B28: Segregation-of-duties exceptions YTD | C28: Yes | D28: Entity, Group | E28: 1 | F28: 1 | G28: 1 | H28: E-07, G-07, O-05 | I28: 3
A29: CTL-008 | B29: Unauthorised-access events YTD | C29: Yes | D29: Entity, Group | E29: 1 | F29: 1 | G29: 1 | H29: E-07, G-07, O-05 | I29: 3
A30: CTL-009 | B30: Data-sharing exceptions YTD | C30: Yes | D30: Entity, Group | E30: 1 | F30: 1 | G30: 1 | H30: E-07, G-07, O-05 | I30: 3
A31: CTL-010 | B31: Manual overrides YTD | C31: Yes | D31: Entity, Group | E31: 1 | F31: 1 | G31: 1 | H31: E-07, G-07, O-05 | I31: 3
A32: EFF-002 | B32: Open critical alerts | C32: Yes | D32: Entity, Group | E32: 3 | F32: 5 | G32: 2 | H32: E-01, E-09, G-01, G-01 · after T7, G-02, G-07, G-09, O-01, STATE GALLERY · O-01 + S-02, O-01 · large display ≥ 1600 | I32: 10
A33: EFF-006 | B33: Alerts without accepted owners | C33: Yes | D33: Entity, Group | F33: 1 | H33: G-09 | I33: 1
A34: EFF-007 | B34: Overdue actions | C34: Yes | D34: Entity, Group | F34: 1 | G34: 2 | H34: E-01, E-09, G-09 | I34: 3
A35: EFF-008 | B35: Average resolution time | C35: Yes | D35: Entity, Group | E35: 1 | F35: 1 | G35: 1 | H35: E-09, G-09, O-06 | I35: 3
A36: EFF-009 | B36: Closed escalations, last 30 days | C36: Yes | D36: Entity, Group | E36: 1 | F36: 1 | G36: 1 | H36: E-09, G-09, O-06 | I36: 3
A37: EFF-010 | B37: Repeat issues, last 90 days | C37: Yes | D37: Entity, Group | E37: 1 | F37: 1 | G37: 1 | H37: E-09, G-09, O-06 | I37: 3
A38: EFF-011 | B38: Root causes eliminated YTD | C38: Yes | D38: Entity, Group | E38: 1 | F38: 1 | G38: 1 | H38: E-09, G-09, O-06 | I38: 3
A39: EHS-001 | B39: TRIR | C39: Yes | D39: Plant, Entity, Group | E39: 1 | F39: 1 | G39: 1 | H39: E-07, G-07, O-05 | I39: 4
A40: EHS-002 | B40: Severity incidents | C40: Yes | D40: Plant, Entity, Group | E40: 1 | F40: 3 | G40: 1 | H40: E-07, G-01, G-01 · after T7, G-07, O-05 | I40: 5
A41: EHS-003 | B41: Near misses | C41: Yes | D41: Plant, Entity, Group | E41: 1 | F41: 1 | G41: 1 | H41: E-07, G-07, O-05 | I41: 3
A42: EHS-004 | B42: Critical safety incidents | C42: Yes | D42: Plant, Entity, Group | E42: 1 | F42: 1 | G42: 1 | H42: E-07, G-07, O-05 | I42: 3
...

Sheet KPI Register
A1: KPI ID | B1: Measure | C1: Unit | D1: Time basis | E1: How it is calculated | F1: Formula with input names | G1: Inputs used | H1: Where the inputs come from | I1: Calculated at | J1: Bottom-up path | K1: Plant 01, Sep 2026 | L1: Plant 02, Sep 2026 | M1: Plant 03, Sep 2026 | N1: Plant 04, Sep 2026 | O1: Plant 05, Sep 2026 | P1: Plant 06, Sep 2026 | Q1: Entity A1, Sep 2026 | R1: Entity A2, Sep 2026 | S1: Group, Sep 2026 | T1: Shown on the mockups (value · lens · screen) | U1: Screen appearances: same / different
A2: OPS-001 | B2: Production vs plan | C2: % | D2: Month | E2: Good output ÷ Planned production × 100 | F2: IFERROR(100*good_output_t/planned_production_t,0) | G2: planned_production_t, good_output_t | H2: Original plant data (plant_base.csv, synthetic) | I2: Plant, Entity, Group | J2: Plant inputs → each plant's KPI; Plant inputs summed to each entity → entity KPI; entities summed to Group → Group KPI (recalculated from totals, never averaged) | K2: ='Plant KPIs'!K2 -> 96.03 | L2: ='Plant KPIs'!Q2 -> 78.4 | M2: ='Plant KPIs'!W2 -> 99.52 | N2: ='Plant KPIs'!AC2 -> 103.35 | O2: ='Plant KPIs'!AI2 -> 101.46 | P2: ='Plant KPIs'!AO2 -> 96.28 | Q2: ='Entity KPIs'!K2 -> 91.27 | R2: ='Entity KPIs'!Q2 -> 100.29 | S2: ='Group KPIs'!K2 -> 95.51 | T2: 103.2 % of plan (flash) · Entity E-01, Entity E-02, Entity E-05, Core Group S-03, Entity S-03, Owner S-03; 98.1 % of plan · Core Group G-01, Core Group G-02, Core Group G-05, Owner O-01, Owner O-09, Owner STATE GALLERY; 97.8 % of plan · Core Group G-01; 98.1% · Core Group G-03; 100.2 % of plan · Owner S-10 | U2: 0 same / 16 different
A3: OPS-003 | B3: Capacity utilization | C3: % | D3: Month | E3: Good output ÷ Installed capacity × 100 | F3: IFERROR(100*good_output_t/installed_capacity_t,0) | G3: installed_capacity_t, good_output_t | H3: Original plant data (plant_base.csv, synthetic) | I3: Plant, Entity, Group | J3: Plant inputs → each plant's KPI; Plant inputs summed to each entity → entity KPI; entities summed to Group → Group KPI (recalculated from totals, never averaged) | K3: ='Plant KPIs'!K3 -> 82.92 | L3: ='Plant KPIs'!Q3 -> 70.02 | M3: ='Plant KPIs'!W3 -> 86.09 | N3: ='Plant KPIs'!AC3 -> 89.48 | O3: ='Plant KPIs'!AI3 -> 89.96 | P3: ='Plant KPIs'!AO3 -> 82.87 | Q3: ='Entity KPIs'!K3 -> 79.8 | R3: ='Entity KPIs'!Q3 -> 87.55 | S3: ='Group KPIs'!K3 -> 83.44 | T3: 88 % · Entity E-02; 86 % · Core Group G-05; 86% · Owner O-01, Owner STATE GALLERY | U3: 0 same / 5 different
A4: PLT-001 | B4: Asset utilization | C4: % | D4: Month | E4: Run hours ÷ Calendar hours × 100 | F4: IFERROR(100*run_hours/calendar_hours,0) | G4: calendar_hours, run_hours | H4: Original plant data (plant_base.csv, synthetic) | I4: Plant, Entity, Group | J4: Plant inputs → each plant's KPI; Plant inputs summed to each entity → entity KPI; entities summed to Group → Group KPI (recalculated from totals, never averaged) | K4: ='Plant KPIs'!K4 -> 92.29 | L4: ='Plant KPIs'!Q4 -> 86.71 | M4: ='Plant KPIs'!W4 -> 96.58 | N4: ='Plant KPIs'!AC4 -> 95.92 | O4: ='Plant KPIs'!AI4 -> 95.82 | P4: ='Plant KPIs'!AO4 -> 94.54 | Q4: ='Entity KPIs'!K4 -> 91.86 | R4: ='Entity KPIs'!Q4 -> 95.43 | S4: ='Group KPIs'!K4 -> 93.64 | T4: 82 % · Entity E-02 | U4: 0 same / 1 different
A5: PLT-002 | B5: OEE | C5: % | D5: Month | E5: Availability × Performance × Quality = Good output ÷ Ideal output × 100 | F5: IFERROR(100*good_output_t/ideal_output_t,0) | G5: ideal_output_t, good_output_t | H5: Original plant data (plant_base.csv, synthetic) | I5: Plant, Entity, Group | J5: Plant inputs → each plant's KPI; Plant inputs summed to each entity → entity KPI; entities summed to Group → Group KPI (recalculated from totals, never averaged) | K5: ='Plant KPIs'!K5 -> 83.97 | L5: ='Plant KPIs'!Q5 -> 70.31 | M5: ='Plant KPIs'!W5 -> 86.21 | N5: ='Plant KPIs'!AC5 -> 89.73 | O5: ='Plant KPIs'!AI5 -> 91.23 | P5: ='Plant KPIs'!AO5 -> 83.8 | Q5: ='Entity KPIs'!K5 -> 80.21 | R5: ='Entity KPIs'!Q5 -> 88.44 | S5: ='Group KPIs'!K5 -> 84.07 | T5: 74 % · Entity E-02; 78 % · Core Group G-05 | U5: 0 same / 2 different
A6: PLT-004 | B6: Recovery percentage | C6: % | D6: Month | E6: Valuable content recovered ÷ Valuable content in feed × 100 | F6: IFERROR(100*recovered_contained_t/feed_contained_t,0) | G6: feed_contained_t, recovered_contained_t | H6: Original plant data (plant_base.csv, synthetic) | I6: Plant, Entity, Group | J6: Plant inputs → each plant's KPI; Plant inputs summed to each entity → entity KPI; entities summed to Group → Group KPI (recalculated from totals, never averaged) | K6: ='Plant KPIs'!K6 -> 91.69 | L6: ='Plant KPIs'!Q6 -> 86.55 | M6: ='Plant KPIs'!W6 -> 85.7 | N6: ='Plant KPIs'!AC6 -> 88.37 | O6: ='Plant KPIs'!AI6 -> 88.33 | P6: ='Plant KPIs'!AO6 -> 84.57 | Q6: ='Entity KPIs'!K6 -> 87.47 | R6: ='Entity KPIs'!Q6 -> 87.23 | S6: ='Group KPIs'!K6 -> 87.35 | T6: 91.3 % · Entity E-02 | U6: 0 same / 1 different
A7: PLT-005 | B7: Yield | C7: % | D7: Month | E7: Good output ÷ Feed input × 100 | F7: IFERROR(100*good_output_t/feed_input_t,0) | G7: good_output_t, feed_input_t | H7: Original plant data (plant_base.csv, synthetic) | I7: Plant, Entity, Group | J7: Plant inputs → each plant's KPI; Plant inputs summed to each entity → entity KPI; entities summed to Group → Group KPI (recalculated from totals, never averaged) | K7: ='Plant KPIs'!K7 -> 91.48 | L7: ='Plant KPIs'!Q7 -> 93.11 | M7: ='Plant KPIs'!W7 -> 90.37 | N7: ='Plant KPIs'!AC7 -> 90.59 | O7: ='Plant KPIs'!AI7 -> 93.25 | P7: ='Plant KPIs'!AO7 -> 92.87 | Q7: ='Entity KPIs'!K7 -> 91.46 | R7: ='Entity KPIs'!Q7 -> 92.42 | S7: ='Group KPIs'!K7 -> 91.93 | T7: 94.1 % · Entity E-02 | U7: 0 same / 1 different
A8: REL-001 | B8: MTBF | C8: h | D8: Month | E8: Run hours ÷ Breakdowns | F8: IFERROR(run_hours/failures,0) | G8: run_hours, failures | H8: Original plant data (plant_base.csv, synthetic) | I8: Plant, Entity, Group | J8: Plant inputs → each plant's KPI; Plant inputs summed to each entity → entity KPI; entities summed to Group → Group KPI (recalculated from totals, never averaged) | K8: ='Plant KPIs'!K8 -> 166.13 | L8: ='Plant KPIs'!Q8 -> 104.05 | M8: ='Plant KPIs'!W8 -> 347.7 | N8: ='Plant KPIs'!AC8 -> 690.6 | O8: ='Plant KPIs'!AI8 -> 689.9 | P8: ='Plant KPIs'!AO8 -> 680.7 | Q8: ='Entity KPIs'!K8 -> 165.35 | R8: ='Entity KPIs'!Q8 -> 687.07 | S8: ='Group KPIs'!K8 -> 269.69 | T8: 212 h · Entity E-03; 205 h · Core Group G-05, Owner O-09 | U8: 0 same / 4 different
A9: REL-002 | B9: Mean Time to Repair | C9: h | D9: Month | E9: Repair hours ÷ Breakdowns | F9: IFERROR(repair_hours/failures,0) | G9: failures, repair_hours | H9: Original plant data (plant_base.csv, synthetic) | I9: Plant, Entity, Group | J9: Plant inputs → each plant's KPI; Plant inputs summed to each entity → entity KPI; entities summed to Group → Group KPI (recalculated from totals, never averaged) | K9: ='Plant KPIs'!K9 -> 5.4 | L9: ='Plant KPIs'!Q9 -> 11.42 | M9: ='Plant KPIs'!W9 -> 4.4 | N9: ='Plant KPIs'!AC9 -> 6.8 | O9: ='Plant KPIs'!AI9 -> 5.2 | P9: ='Plant KPIs'!AO9 -> 6.5 | Q9: ='Entity KPIs'!K9 -> 8.24 | R9: ='Entity KPIs'!Q9 -> 6.17 | S9: ='Group KPIs'!K9 -> 7.83 | T9: 3.4 h · Entity E-03; 3.6 h · Core Group G-05, Owner O-09 | U9: 0 same / 3 different
A10: REL-003 | B10: Unplanned downtime | C10: h | D10: Month | E10: Unplanned downtime | F10: unplanned_downtime_hours | G10: unplanned_downtime_hours | H10: Original plant data (plant_base.csv, synthetic) | I10: Plant, Entity, Group | J10: Plant inputs → each plant's KPI; Plant inputs summed to each entity → entity KPI; entities summed to Group → Group KPI (recalculated from totals, never averaged) | K10: ='Plant KPIs'!K10 -> 30.2 | L10: ='Plant KPIs'!Q10 -> 78.2 | M10: ='Plant KPIs'!W10 -> 12.3 | N10: ='Plant KPIs'!AC10 -> 10.1 | O10: ='Plant KPIs'!AI10 -> 10.2 | P10: ='Plant KPIs'!AO10 -> 13.4 | Q10: ='Entity KPIs'!K10 -> 120.7 | R10: ='Entity KPIs'!Q10 -> 33.7 | S10: ='Group KPIs'!K10 -> 154.4 | T10: 2.8 % of hours · Entity E-03; 3.1 % of hours · Core Group G-05, Owner O-09 | U10: 0 same / 4 different
A11: REL-004 | B11: Production loss from downtime | C11: t | D11: Month | E11: Production lost to downtime | F11: prod_loss_downtime_t | G11: prod_loss_downtime_t | H11: Original plant data (plant_base.csv, synthetic) | I11: Plant, Entity, Group | J11: Plant inputs → each plant's KPI; Plant inputs summed to each entity → entity KPI; entities summed to Group → Group KPI (recalculated from totals, never averaged) | K11: ='Plant KPIs'!K11 -> 4140 | L11: ='Plant KPIs'!Q11 -> 14772 | M11: ='Plant KPIs'!W11 -> 2772 | N11: ='Plant KPIs'!AC11 -> 1281 | O11: ='Plant KPIs'!AI11 -> 2091 | P11: ='Plant KPIs'!AO11 -> 2120 | Q11: ='Entity KPIs'!K11 -> 21684 | R11: ='Entity KPIs'!Q11 -> 5492 | S11: ='Group KPIs'!K11 -> 27176 | T11: 1.6 kt MTD · Entity E-03; 93% · Core Group G-05 | U11: 0 same / 2 different
A12: REL-005 | B12: Preventive-maintenance compliance | C12: % | D12: Month | E12: Preventive maintenance completed ÷ Preventive maintenance scheduled × 100 | F12: IFERROR(100*pm_completed/pm_scheduled,0) | G12: pm_scheduled, pm_completed | H12: Original plant data (plant_base.csv, synthetic) | I12: Plant, Entity, Group | J12: Plant inputs → each plant's KPI; Plant inputs summed to each entity → entity KPI; entities summed to Group → Group KPI (recalculated from totals, never averaged) | K12: ='Plant KPIs'!K12 -> 93.48 | L12: ='Plant KPIs'!Q12 -> 81.82 | M12: ='Plant KPIs'!W12 -> 100 | N12: ='Plant KPIs'!AC12 -> 100 | O12: ='Plant KPIs'!AI12 -> 97.62 | P12: ='Plant KPIs'!AO12 -> 94.44 | Q12: ='Entity KPIs'!K12 -> 93.43 | R12: ='Entity KPIs'!Q12 -> 97.81 | S12: ='Group KPIs'!K12 -> 95.62 | T12: 93 % · Entity E-03; 93% · Owner O-09 | U12: 1 same / 1 different
A13: CST-001 | B13: Cost per tonne | C13: ₹/t | D13: Month | E13: (Variable cost + Fixed cost) × 1000 ÷ Good output | F13: IFERROR(1000*(variable_cost_k+fixed_cost_k)/good_output_t,0) | G13: good_output_t, variable_cost_k, fixed_cost_k | H13: Original plant data (plant_base.csv, synthetic) | I13: Plant, Entity, Group | J13: Plant inputs → each plant's KPI; Plant inputs summed to each entity → entity KPI; entities summed to Group → Group KPI (recalculated from totals, never averaged) | K13: ='Plant KPIs'!K13 -> 2779.02 | L13: ='Plant KPIs'!Q13 -> 3245.21 | M13: ='Plant KPIs'!W13 -> 2629.1 | N13: ='Plant KPIs'!AC13 -> 3275.49 | O13: ='Plant KPIs'!AI13 -> 3011.79 | P13: ='Plant KPIs'!AO13 -> 2798.98 | Q13: ='Entity KPIs'!K13 -> 2853.05 | R13: ='Entity KPIs'!Q13 -> 3016.5 | S13: ='Group KPIs'!K13 -> 2933.74 | T13: ₹425 /t · Entity E-02, Entity E-11; ₹412 /t · Core Group G-03, Owner O-09; 412 ₹ /t · Core Group G-05, Owner O-09 | U13: 0 same / 7 different
... A37: CST-004 | B37: Power cost per tonne | C37: ₹/t | D37: Month | E37: Power cost × 1000 ÷ Good output | F37: IF(good_output_t=0,0,1000*power_cost_k/good_output_t) | G37: good_output_t, power_cost_k | H37: Original plant data + synthetic inputs added for this model | I37: Plant, Entity, Group | J37: Plant inputs → each plant's KPI; Plant inputs summed to each entity → entity KPI; entities summed to Group → Group KPI (recalculated from totals, never averaged) | K37: ='Plant KPIs'!K37 -> 164.79 | L37: ='Plant KPIs'!Q37 -> 215.86 | M37: ='Plant KPIs'!W37 -> 156.32 | N37: ='Plant KPIs'!AC37 -> 198.06 | O37: ='Plant KPIs'!AI37 -> 168.17 | P37: ='Plant KPIs'!AO37 -> 155.24 | Q37: ='Entity KPIs'!K37 -> 176.41 | R37: ='Entity KPIs'!Q37 -> 172.12 | S37: ='Group KPIs'!K37 -> 174.29 | T37: 6.1 ₹/t · Owner O-09 | U37: 0 same / 1 different
A38: FIN-001 | B38: EBITDA YTD | C38: ₹ m | D38: Year to date | E38: Sum of monthly EBITDA since April ÷ 1000 | F38: SUM(ebitda_k@ytd)/1000 | G38: variable_cost_k, fixed_cost_k, revenue_k, overhead_k | H38: Original plant data + synthetic inputs added for this model | I38: Entity, Group | J38: Plant inputs summed to each entity + entity inputs → entity KPI; entities summed to Group → Group KPI (recalculated from totals, never averaged) | K38: — | L38: — | M38: — | N38: — | O38: — | P38: — | Q38: ='Entity KPIs'!K38 -> 890.55 | R38: ='Entity KPIs'!Q38 -> 869.54 | S38: ='Group KPIs'!K38 -> 1760.09 | T38: 96.2 ₹ m · Entity E-01, Entity E-11; 361.3 ₹ m · Core Group G-01, Core Group G-02, Core Group G-03, Owner O-01, Owner STATE GALLERY | U38: 0 same / 9 different
A39: FIN-002 | B39: EBIT YTD | C39: ₹ m | D39: Year to date | E39: Sum of monthly EBIT since April ÷ 1000 | F39: SUM(ebit_k@ytd)/1000 | G39: variable_cost_k, fixed_cost_k, revenue_k, depreciation_k, overhead_k | H39: Original plant data + synthetic inputs added for this model | I39: Entity, Group | J39: Plant inputs summed to each entity + entity inputs → entity KPI; entities summed to Group → Group KPI (recalculated from totals, never averaged) | K39: — | L39: — | M39: — | N39: — | O39: — | P39: — | Q39: ='Entity KPIs'!K39 -> 610.05 | R39: ='Entity KPIs'!Q39 -> 618.1 | S39: ='Group KPIs'!K39 -> 1228.14 | T39: 68.7 ₹ m · Entity E-01, Entity E-11; ₹68.7 m · Entity E-01; 238.4 ₹ m · Core Group G-01, Core Group G-03, Owner O-01, Owner STATE GALLERY | U39: 0 same / 10 different
A40: FIN-003 | B40: Revenue YTD | C40: ₹ m | D40: Year to date | E40: Sum of monthly Revenue since April ÷ 1000 | F40: SUM(revenue_k@ytd)/1000 | G40: revenue_k | H40: Synthetic inputs added for this model | I40: Plant, Entity, Group | J40: Plant inputs → each plant's KPI; Plant inputs summed to each entity → entity KPI; entities summed to Group → Group KPI (recalculated from totals, never averaged) | K40: ='Plant KPIs'!K38 -> 1892.75 | L40: ='Plant KPIs'!Q38 -> 2089.58 | M40: ='Plant KPIs'!W38 -> 2989.99 | N40: ='Plant KPIs'!AC38 -> 1749.63 | O40: ='Plant KPIs'!AI38 -> 2890.84 | P40: ='Plant KPIs'!AO38 -> 2198.51 | Q40: ='Entity KPIs'!K40 -> 6972.32 | R40: ='Entity KPIs'!Q40 -> 6838.98 | S40: ='Group KPIs'!K40 -> 13811.3 | T40: ₹404.6 m · Entity E-01; 404.6 ₹ m · Entity E-11; 2,410 ₹ m · Core Group G-01, Core Group G-02, Core Group G-03, Owner O-01, Owner STATE GALLERY | U40: 0 same / 11 different
A41: FIN-004 | B41: Free cash flow YTD | C41: ₹ m | D41: Year to date | E41: Sum of monthly Free cash flow since April ÷ 1000 | F41: SUM(fcf_k@ytd)/1000 | G41: variable_cost_k, fixed_cost_k, revenue_k, overhead_k, tax_paid_k, receivables_k, payables_k, inventory_k, capex_spend_k | H41: Original plant data + synthetic inputs added for this model | I41: Entity, Group | J41: Plant inputs summed to each entity + entity inputs → entity KPI; entities summed to Group → Group KPI (recalculated from totals, never averaged) | K41: — | L41: — | M41: — | N41: — | O41: — | P41: — | Q41: ='Entity KPIs'!K41 -> 337.63 | R41: ='Entity KPIs'!Q41 -> 268.55 | S41: ='Group KPIs'!K41 -> 606.18 | T41: ₹19.8 m · Entity E-01; 19.8 ₹ m · Entity E-11; 96.4 ₹ m · Core Group G-01, Core Group G-03, Owner O-01, Owner O-03, Owner STATE GALLERY | U41: 0 same / 9 different
A42: FIN-005 | B42: ROCE, annualised | C42: % | D42: Year to date | E42: EBIT since April × 12 ÷ months elapsed ÷ Capital employed × 100 | F42: IF(capital_employed_k=0,0,100*SUM(ebit_k@ytd)*12/ytd_months/capital_employed_k) | G42: variable_cost_k, fixed_cost_k, revenue_k, depreciation_k, overhead_k, capital_employed_k | H42: Original plant data + synthetic inputs added for this model | I42: Entity, Group | J42: Plant inputs summed to each entity + entity inputs → entity KPI; entities summed to Group → Group KPI (recalculated from totals, never averaged) | K42: — | L42: — | M42: — | N42: — | O42: — | P42: — | Q42: ='Entity KPIs'!K42 -> 11.08 | R42: ='Entity KPIs'!Q42 -> 12.12 | S42: ='Group KPIs'!K42 -> 11.58 | T42: 11.4 % · Entity E-01, Entity E-11; 11.4% · Entity E-01; 11.8% · Core Group G-01, Owner O-01, Owner STATE GALLERY; 11.8 % · Core Group G-03, Owner O-01 | U42: 0 same / 10 different
A43: FIN-006 | B43: Net debt | C43: ₹ m | D43: Month end | E43: (Gross debt − Cash) ÷ 1000 | F43: net_debt_k/1000 | G43: gross_debt_k, cash_k | H43: Synthetic inputs added for this model | I43: Entity, Group | J43: Entity inputs → entity KPI; entities summed to Group → Group KPI (recalculated from totals, never averaged) | K43: — | L43: — | M43: — | N43: — | O43: — | P43: — | Q43: ='Entity KPIs'!K43 -> 3610 | R43: ='Entity KPIs'!Q43 -> 3040 | S43: ='Group KPIs'!K43 -> 6650 | T43: 1,140 ₹ m · Core Group G-01, Core Group G-03, Owner O-01, Owner O-03, Owner STATE GALLERY | U43: 0 same / 7 different
A44: FIN-007 | B44: Shareholder-value indicator (economic profit YTD) | C44: ₹ m | D44: Year to date | E44: (EBIT since April × (1 − Tax rate) − Capital employed × Cost of capital × months elapsed ÷ 12) ÷ 1000 | F44: (SUM(ebit_k@ytd)*(1-TaxRate)-capital_employed_k*WACC*ytd_months/12)/1000 | G44: variable_cost_k, fixed_cost_k, revenue_k, depreciation_k, overhead_k, capital_employed_k | H44: Original plant data + synthetic inputs added for this model | I44: Entity, Group | J44: Plant inputs summed to each entity + entity inputs → entity KPI; entities summed to Group → Group KPI (recalculated from totals, never averaged) | K44: — | L44: — | M44: — | N44: — | O44: — | P44: — | Q44: ='Entity KPIs'!K44 -> -65.72 | R44: ='Entity KPIs'!Q44 -> -20.93 | S44: ='Group KPIs'!K44 -> -86.65 | T44: — · Core Group G-03; [PLACEHOLDER] · Owner O-01, Owner STATE GALLERY | U44: 0 same / 4 different
A45: FIN-008 | B45: FCF conversion (FCF ÷ EBITDA) | C45: % | D45: Year to date | E45: Free cash flow since April ÷ EBITDA since April × 100 | F45: IF(SUM(ebitda_k@ytd)=0,0,100*SUM(fcf_k@ytd)/SUM(ebitda_k@ytd)) | G45: variable_cost_k, fixed_cost_k, revenue_k, overhead_k, tax_paid_k, receivables_k, payables_k, inventory_k, capex_spend_k | H45: Original plant data + synthetic inputs added for this model | I45: Entity, Group | J45: Plant inputs summed to each entity + entity inputs → entity KPI; entities summed to Group → Group KPI (recalculated from totals, never averaged) | K45: — | L45: — | M45: — | N45: — | O45: — | P45: — | Q45: ='Entity KPIs'!K45 -> 37.91 | R45: ='Entity KPIs'!Q45 -> 30.88 | S45: ='Group KPIs'!K45 -> 34.44 | T45: 27% · Core Group G-03 | U45: 0 same / 1 different
A46: CSH-001 | B46: Cash position | C46: ₹ m | D46: Month end | E46: Cash ÷ 1000 | F46: cash_k/1000 | G46: cash_k | H46: Synthetic inputs added for this model | I46: Entity, Group | J46: Entity inputs → entity KPI; entities summed to Group → Group KPI (recalculated from totals, never averaged) | K46: — | L46: — | M46: — | N46: — | O46: — | P46: — | Q46: ='Entity KPIs'!K46 -> 967.08 | R46: ='Entity KPIs'!Q46 -> 1174.74 | S46: ='Group KPIs'!K46 -> 2141.82 | T46: ₹41 m · Entity E-05; 384 ₹ m · Core Group G-04, Owner O-03 | U46: 0 same / 3 different
A47: CSH-002 | B47: Cash released YTD | C47: ₹ m | D47: Year to date | E47: Sum of cash released since April ÷ 1000 | F47: SUM(cash_released_k@ytd)/1000 | G47: cash_released_k | H47: Synthetic inputs added for this model | I47: Entity, Group | J47: Entity inputs → entity KPI; entities summed to Group → Group KPI (recalculated from totals, never averaged) | K47: — | L47: — | M47: — | N47: — | O47: — | P47: — | Q47: ='Entity KPIs'!K47 -> 4.2 | R47: ='Entity KPIs'!Q47 -> 17.83 | S47: ='Group KPIs'!K47 -> 22.03 | T47: ₹4.2 m · Entity E-05; ₹21 m · Core Group G-04, Owner O-03 | U47: 1 same / 2 different
A48: CSH-003 | B48: Daily collections | C48: ₹ m per day | D48: Month | E48: Cash collected ÷ Days in month ÷ 1000 | F48: collections_k/days/1000 | G48: collections_k | H48: Synthetic inputs added for this model | I48: Entity, Group | J48: Entity inputs → entity KPI; entities summed to Group → Group KPI (recalculated from totals, never averaged) | K48: — | L48: — | M48: — | N48: — | O48: — | P48: — | Q48: ='Entity KPIs'!K48 -> 38.6 | R48: ='Entity KPIs'!Q48 -> 38.17 | S48: ='Group KPIs'!K48 -> 76.77 | T48: 4.1 ₹ m · Entity E-01, Entity E-05, Owner S-11; ₹18.6 m · Core Group G-04, Owner O-03 | U48: 0 same / 5 different
A49: CSH-004 | B49: Cash-conversion cycle | C49: days | D49: Month end | E49: DSO + Inventory days − DPO | F49: dso_d+dio_d-dpo_d | G49: variable_cost_k, revenue_k, receivables_k, payables_k, inventory_k | H49: Original plant data + synthetic inputs added for this model | I49: Entity, Group | J49: Plant inputs summed to each entity + entity inputs → entity KPI; entities summed to Group → Group KPI (recalculated from totals, never averaged) | K49: — | L49: — | M49: — | N49: — | O49: — | P49: — | Q49: ='Entity KPIs'!K49 -> 52.3 | R49: ='Entity KPIs'!Q49 -> 13.42 | S49: ='Group KPIs'!K49 -> 32.59 | T49: 55 d · Entity E-05; 33 days · Core Group G-04; 33 d · Owner O-03 | U49: 2 same / 1 different
A50: CSH-006 | B50: Cash-upstream exposure | C50: ₹ m | D50: Next 30 days | E50: (Cash due to be upstreamed − Amount covered by available cash) ÷ 1000 | F50: (upstream_due_k-upstream_covered_k)/1000 | G50: upstream_due_k, upstream_covered_k | H50: Synthetic inputs added for this model | I50: Entity, Group | J50: Entity inputs → entity KPI; entities summed to Group → Group KPI (recalculated from totals, never averaged) | K50: — | L50: — | M50: — | N50: — | O50: — | P50: — | Q50: ='Entity KPIs'!K50 -> 27.21 | R50: ='Entity KPIs'!Q50 -> 0 | S50: ='Group KPIs'!K50 -> 27.21 | T50: ₹26 m at risk (FCST) · Entity E-01; 26 ₹ m · Entity E-05, Core Group G-04, Owner O-03, Owner S-11 | U50: 0 same / 5 different
A51: WCP-001 | B51: DSO | C51: days | D51: Month end | E51: Trade receivables ÷ Revenue × Days in month | F51: dso_d | G51: revenue_k, receivables_k | H51: Synthetic inputs added for this model | I51: Entity, Group | J51: Plant inputs summed to each entity + entity inputs → entity KPI; entities summed to Group → Group KPI (recalculated from totals, never averaged) | K51: — | L51: — | M51: — | N51: — | O51: — | P51: — | Q51: ='Entity KPIs'!K51 -> 52 | R51: ='Entity KPIs'!Q51 -> 42.05 | S51: ='Group KPIs'!K51 -> 46.97 | T51: 52 d · Entity E-01, Entity E-05; 52 days · Entity E-05, Owner S-11; 47 days · Core Group G-02, Core Group G-04; 47 d · Owner O-03 | U51: 7 same / 0 different
A52: WCP-002 | B52: DPO | C52: days | D52: Month end | E52: Trade payables ÷ Variable cost × Days in month | F52: dpo_d | G52: variable_cost_k, payables_k | H52: Original plant data + synthetic inputs added for this model | I52: Entity, Group | J52: Plant inputs summed to each entity + entity inputs → entity KPI; entities summed to Group → Group KPI (recalculated from totals, never averaged) | K52: — | L52: — | M52: — | N52: — | O52: — | P52: — | Q52: ='Entity KPIs'!K52 -> 40.2 | R52: ='Entity KPIs'!Q52 -> 63.74 | S52: ='Group KPIs'!K52 -> 52.15 | T52: 38 d · Entity E-05; 52 days · Core Group G-04; 52 d · Owner O-03 | U52: 2 same / 1 different
... A80: VAL-003 | B80: Cost savings delivered YTD | C80: ₹ m | D80: Year to date | E80: Sum of cost savings since April ÷ 1000 | F80: SUM(cost_savings_k@ytd)/1000 | G80: cost_savings_k | H80: Synthetic inputs added for this model | I80: Entity, Group | J80: Entity inputs → entity KPI; entities summed to Group → Group KPI (recalculated from totals, never averaged) | K80: — | L80: — | M80: — | N80: — | O80: — | P80: — | Q80: ='Entity KPIs'!K80 -> 3.89 | R80: ='Entity KPIs'!Q80 -> 7.35 | S80: ='Group KPIs'!K80 -> 11.25 | T80: ₹3.9 m · Entity E-06; ₹11 m · Core Group G-06, Owner O-04 | U80: 4 same / 0 different
A81: SUP-001 | B81: Supplier on-time delivery | C81: % | D81: Month | E81: Purchase-order lines on time ÷ Lines due × 100 | F81: IF(po_lines_due=0,0,100*po_lines_on_time/po_lines_due) | G81: po_lines_due, po_lines_on_time | H81: Synthetic inputs added for this model | I81: Plant, Entity, Group | J81: Plant inputs → each plant's KPI; Plant inputs summed to each entity → entity KPI; entities summed to Group → Group KPI (recalculated from totals, never averaged) | K81: ='Plant KPIs'!K39 -> 92.72 | L81: ='Plant KPIs'!Q39 -> 84.97 | M81: ='Plant KPIs'!W39 -> 92.41 | N81: ='Plant KPIs'!AC39 -> 93.45 | O81: ='Plant KPIs'!AI39 -> 91.9 | P81: ='Plant KPIs'!AO39 -> 90.73 | Q81: ='Entity KPIs'!K81 -> 90.39 | R81: ='Entity KPIs'!Q81 -> 92.28 | S81: ='Group KPIs'!K81 -> 91.41 | T81: 88 % · Entity E-04; 91% · Core Group G-05, Owner O-09; 91 % · Owner O-09 | U81: 3 same / 1 different
A82: SUP-002 | B82: Supplier fill rate | C82: % | D82: Month | E82: Quantity received ÷ Quantity ordered × 100 | F82: IF(qty_ordered_t=0,0,100*qty_received_t/qty_ordered_t) | G82: qty_ordered_t, qty_received_t | H82: Synthetic inputs added for this model | I82: Plant, Entity, Group | J82: Plant inputs → each plant's KPI; Plant inputs summed to each entity → entity KPI; entities summed to Group → Group KPI (recalculated from totals, never averaged) | K82: ='Plant KPIs'!K40 -> 96.14 | L82: ='Plant KPIs'!Q40 -> 97.38 | M82: ='Plant KPIs'!W40 -> 97.28 | N82: ='Plant KPIs'!AC40 -> 94.71 | O82: ='Plant KPIs'!AI40 -> 98.98 | P82: ='Plant KPIs'!AO40 -> 95.06 | Q82: ='Entity KPIs'!K82 -> 97.01 | R82: ='Entity KPIs'!Q82 -> 96.61 | S82: ='Group KPIs'!K82 -> 96.82 | T82: 94 % · Entity E-04 | U82: 0 same / 1 different
A83: SUP-003 | B83: Supplier quality-rejection rate | C83: % | D83: Month | E83: Quantity rejected ÷ Quantity received × 100 | F83: IF(qty_received_t=0,0,100*qty_rejected_t/qty_received_t) | G83: qty_received_t, qty_rejected_t | H83: Synthetic inputs added for this model | I83: Plant, Entity, Group | J83: Plant inputs → each plant's KPI; Plant inputs summed to each entity → entity KPI; entities summed to Group → Group KPI (recalculated from totals, never averaged) | K83: ='Plant KPIs'!K41 -> 1.4 | L83: ='Plant KPIs'!Q41 -> 1.11 | M83: ='Plant KPIs'!W41 -> 0.62 | N83: ='Plant KPIs'!AC41 -> 1.61 | O83: ='Plant KPIs'!AI41 -> 1.01 | P83: ='Plant KPIs'!AO41 -> 1.37 | Q83: ='Entity KPIs'!K83 -> 0.97 | R83: ='Entity KPIs'!Q83 -> 1.28 | S83: ='Group KPIs'!K83 -> 1.12 | T83: 1.2 % · Entity E-04 | U83: 0 same / 1 different
A84: SUP-004 | B84: Supplier lead-time variance | C84: % | D84: Month | E84: (Actual lead time − Planned lead time) ÷ Planned lead time × 100 | F84: IF(lead_time_planned_days=0,0,100*(lead_time_actual_days-lead_time_planned_days)/lead_time_planned_days) | G84: lead_time_planned_days, lead_time_actual_days | H84: Synthetic inputs added for this model | I84: Plant, Entity, Group | J84: Plant inputs → each plant's KPI; Plant inputs summed to each entity → entity KPI; entities summed to Group → Group KPI (recalculated from totals, never averaged) | K84: ='Plant KPIs'!K42 -> 4.97 | L84: ='Plant KPIs'!Q42 -> 17.33 | M84: ='Plant KPIs'!W42 -> 2.35 | N84: ='Plant KPIs'!AC42 -> 3.92 | O84: ='Plant KPIs'!AI42 -> 6.68 | P84: ='Plant KPIs'!AO42 -> -1.14 | Q84: ='Entity KPIs'!K84 -> 6.91 | R84: ='Entity KPIs'!Q84 -> 3.65 | S84: ='Group KPIs'!K84 -> 5.25 | T84: +6 days · Entity E-04; 38% · Core Group G-05 | U84: 0 same / 2 different
A85: SUP-005 | B85: Critical supplier exposure | C85: count | D85: Month end | E85: Critical single-source suppliers | F85: single_source_suppliers | G85: single_source_suppliers | H85: Synthetic inputs added for this model | I85: Entity, Group | J85: Entity inputs → entity KPI; entities summed to Group → Group KPI (recalculated from totals, never averaged) | K85: — | L85: — | M85: — | N85: — | O85: — | P85: — | Q85: ='Entity KPIs'!K85 -> 2 | R85: ='Entity KPIs'!Q85 -> 1 | S85: ='Group KPIs'!K85 -> 3 | T85: 2 single-source suppliers · Entity E-04; 3 single-source (1 elevated: S-07) · Core Group G-05 | U85: 2 same / 0 different
A86: SUP-007 | B86: Single-source spend share | C86: % | D86: Month | E86: Spend with single-source suppliers ÷ Supplier spend × 100 | F86: IF(supplier_spend_k=0,0,100*single_source_spend_k/supplier_spend_k) | G86: supplier_spend_k, single_source_spend_k | H86: Synthetic inputs added for this model | I86: Plant, Entity, Group | J86: Plant inputs → each plant's KPI; Plant inputs summed to each entity → entity KPI; entities summed to Group → Group KPI (recalculated from totals, never averaged) | K86: ='Plant KPIs'!K43 -> 30.12 | L86: ='Plant KPIs'!Q43 -> 43.02 | M86: ='Plant KPIs'!W43 -> 30.7 | N86: ='Plant KPIs'!AC43 -> 31.2 | O86: ='Plant KPIs'!AI43 -> 35.54 | P86: ='Plant KPIs'!AO43 -> 39.87 | Q86: ='Entity KPIs'!K86 -> 34.81 | R86: ='Entity KPIs'!Q86 -> 35.55 | S86: ='Group KPIs'!K86 -> 35.19 | T86: 38% · Owner O-09 | U86: 0 same / 1 different
A87: SUP-008 | B87: Supplier EHS incidents YTD | C87: count | D87: Year to date | E87: Sum of supplier EHS incidents since April | F87: SUM(supplier_ehs_incidents@ytd) | G87: supplier_ehs_incidents | H87: Synthetic inputs added for this model | I87: Plant, Entity, Group | J87: Plant inputs → each plant's KPI; Plant inputs summed to each entity → entity KPI; entities summed to Group → Group KPI (recalculated from totals, never averaged) | K87: ='Plant KPIs'!K44 -> 2 | L87: ='Plant KPIs'!Q44 -> 0 | M87: ='Plant KPIs'!W44 -> 0 | N87: ='Plant KPIs'!AC44 -> 0 | O87: ='Plant KPIs'!AI44 -> 1 | P87: ='Plant KPIs'!AO44 -> 0 | Q87: ='Entity KPIs'!K87 -> 2 | R87: ='Entity KPIs'!Q87 -> 1 | S87: ='Group KPIs'!K87 -> 3 | T87: 0 · Owner O-09 | U87: 0 same / 1 different
A88: CON-001 | B88: Contracts expiring, next 90 days | C88: count | D88: Month end | E88: Contracts expiring in next 90 days | F88: contracts_expiring_90d | G88: contracts_expiring_90d | H88: Synthetic inputs added for this model | I88: Entity, Group | J88: Entity inputs → entity KPI; entities summed to Group → Group KPI (recalculated from totals, never averaged) | K88: — | L88: — | M88: — | N88: — | O88: — | P88: — | Q88: ='Entity KPIs'!K88 -> 2 | R88: ='Entity KPIs'!Q88 -> 2 | S88: ='Group KPIs'!K88 -> 4 | T88: 1 (S-07) · Entity E-04, Entity E-07; 4 · Core Group G-07, Owner O-05 | U88: 3 same / 2 different
A89: CON-002 | B89: Contract-compliance rate | C89: % | D89: Month end | E89: Contracts fully compliant ÷ Active contracts × 100 | F89: IF(contracts_total=0,0,100*contracts_compliant/contracts_total) | G89: contracts_total, contracts_compliant | H89: Synthetic inputs added for this model | I89: Entity, Group | J89: Entity inputs → entity KPI; entities summed to Group → Group KPI (recalculated from totals, never averaged) | K89: — | L89: — | M89: — | N89: — | O89: — | P89: — | Q89: ='Entity KPIs'!K89 -> 95.83 | R89: ='Entity KPIs'!Q89 -> 95.59 | S89: ='Group KPIs'!K89 -> 95.71 | T89: 95% · Entity E-04, Entity E-07; 96% · Core Group G-07, Owner O-05 | U89: 2 same / 2 different
A90: CON-003 | B90: Supplier EHS non-compliance | C90: count | D90: Month end | E90: Suppliers not meeting EHS requirements | F90: supplier_ehs_noncompliance | G90: supplier_ehs_noncompliance | H90: Synthetic inputs added for this model | I90: Entity, Group | J90: Entity inputs → entity KPI; entities summed to Group → Group KPI (recalculated from totals, never averaged) | K90: — | L90: — | M90: — | N90: — | O90: — | P90: — | Q90: ='Entity KPIs'!K90 -> 0 | R90: ='Entity KPIs'!Q90 -> 0 | S90: ='Group KPIs'!K90 -> 0 | T90: 0 · Entity E-04, Entity E-07; 1 · Core Group G-05, Core Group G-07, Owner O-05 | U90: 2 same / 3 different
...

Sheet Lineage (Sep 2026)
A1: KPI ID | B1: Step | C1: Item | D1: Field | E1: Used in the formula as | F1: Plant 01 | G1: Plant 02 | H1: Plant 03 | I1: Plant 04 | J1: Plant 05 | K1: Plant 06 | L1: Entity A1 | M1: Entity A2 | N1: Group | O1: How it rolls up
A2: OPS-001 Production vs plan (%) = Good output ÷ Planned production × 100
A3: OPS-001 | B3: Input | C3: Good output (t) | D3: good_output_t | E3: This month | F3: ='Plant Inputs'!P9 -> 81854 | G3: ='Plant Inputs'!P15 -> 95233 | H3: ='Plant Inputs'!P21 -> 139711 | I3: ='Plant Inputs'!P27 -> 81694 | J3: ='Plant Inputs'!P33 -> 132787 | K3: ='Plant Inputs'!P39 -> 94388 | L3: ='Entity Inputs'!N9 -> 316798 | M3: ='Entity Inputs'!N15 -> 308869 | N3: ='Group Inputs'!M9 -> 625667 | O3: Sum of 3 plants → sum of 2 entities
A4: OPS-001 | B4: Input | C4: Planned production (t) | D4: planned_production_t | E4: This month | F4: ='Plant Inputs'!N9 -> 85234 | G4: ='Plant Inputs'!N15 -> 121475 | H4: ='Plant Inputs'!N21 -> 140379 | I4: ='Plant Inputs'!N27 -> 79048 | J4: ='Plant Inputs'!N33 -> 130881 | K4: ='Plant Inputs'!N39 -> 98037 | L4: ='Entity Inputs'!L9 -> 347088 | M4: ='Entity Inputs'!L15 -> 307966 | N4: ='Group Inputs'!K9 -> 655054 | O4: Sum of 3 plants → sum of 2 entities
A5: OPS-001 | B5: KPI result | C5: Production vs plan | E5: Month | F5: ='Plant KPIs'!K2 -> 96.03 | G5: ='Plant KPIs'!Q2 -> 78.4 | H5: ='Plant KPIs'!W2 -> 99.52 | I5: ='Plant KPIs'!AC2 -> 103.35 | J5: ='Plant KPIs'!AI2 -> 101.46 | K5: ='Plant KPIs'!AO2 -> 96.28 | L5: ='Entity KPIs'!K2 -> 91.27 | M5: ='Entity KPIs'!Q2 -> 100.29 | N5: ='Group KPIs'!K2 -> 95.51 | O5: Same formula applied at each level to that level's inputs
A7: OPS-003 Capacity utilization (%) = Good output ÷ Installed capacity × 100
A8: OPS-003 | B8: Input | C8: Good output (t) | D8: good_output_t | E8: This month | F8: ='Plant Inputs'!P9 -> 81854 | G8: ='Plant Inputs'!P15 -> 95233 | H8: ='Plant Inputs'!P21 -> 139711 | I8: ='Plant Inputs'!P27 -> 81694 | J8: ='Plant Inputs'!P33 -> 132787 | K8: ='Plant Inputs'!P39 -> 94388 | L8: ='Entity Inputs'!N9 -> 316798 | M8: ='Entity Inputs'!N15 -> 308869 | N8: ='Group Inputs'!M9 -> 625667 | O8: Sum of 3 plants → sum of 2 entities
A9: OPS-003 | B9: Input | C9: Installed capacity (t) | D9: installed_capacity_t | E9: This month | F9: ='Plant Inputs'!M9 -> 98712 | G9: ='Plant Inputs'!M15 -> 136008 | H9: ='Plant Inputs'!M21 -> 162288 | I9: ='Plant Inputs'!M27 -> 91296 | J9: ='Plant Inputs'!M33 -> 147600 | K9: ='Plant Inputs'!M39 -> 113904 | L9: ='Entity Inputs'!K9 -> 397008 | M9: ='Entity Inputs'!K15 -> 352800 | N9: ='Group Inputs'!J9 -> 749808 | O9: Sum of 3 plants → sum of 2 entities
A10: OPS-003 | B10: KPI result | C10: Capacity utilization | E10: Month | F10: ='Plant KPIs'!K3 -> 82.92 | G10: ='Plant KPIs'!Q3 -> 70.02 | H10: ='Plant KPIs'!W3 -> 86.09 | I10: ='Plant KPIs'!AC3 -> 89.48 | J10: ='Plant KPIs'!AI3 -> 89.96 | K10: ='Plant KPIs'!AO3 -> 82.87 | L10: ='Entity KPIs'!K3 -> 79.8 | M10: ='Entity KPIs'!Q3 -> 87.55 | N10: ='Group KPIs'!K3 -> 83.44 | O10: Same formula applied at each level to that level's inputs
A12: PLT-001 Asset utilization (%) = Run hours ÷ Calendar hours × 100
A13: PLT-001 | B13: Input | C13: Run hours (h) | D13: run_hours | E13: This month | F13: ='Plant Inputs'!J9 -> 664.5 | G13: ='Plant Inputs'!J15 -> 624.3 | H13: ='Plant Inputs'!J21 -> 695.4 | I13: ='Plant Inputs'!J27 -> 690.6 | J13: ='Plant Inputs'!J33 -> 689.9 | K13: ='Plant Inputs'!J39 -> 680.7 | L13: ='Entity Inputs'!H9 -> 1984.2 | M13: ='Entity Inputs'!H15 -> 2061.2 | N13: ='Group Inputs'!G9 -> 4045.4 | O13: Sum of 3 plants → sum of 2 entities
A14: PLT-001 | B14: Input | C14: Calendar hours (h) | D14: calendar_hours | E14: This month | F14: ='Plant Inputs'!H9 -> 720 | G14: ='Plant Inputs'!H15 -> 720 | H14: ='Plant Inputs'!H21 -> 720 | I14: ='Plant Inputs'!H27 -> 720 | J14: ='Plant Inputs'!H33 -> 720 | K14: ='Plant Inputs'!H39 -> 720 | L14: ='Entity Inputs'!F9 -> 2160 | M14: ='Entity Inputs'!F15 -> 2160 | N14: ='Group Inputs'!E9 -> 4320 | O14: Sum of 3 plants → sum of 2 entities
A15: PLT-001 | B15: KPI result | C15: Asset utilization | E15: Month | F15: ='Plant KPIs'!K4 -> 92.29 | G15: ='Plant KPIs'!Q4 -> 86.71 | H15: ='Plant KPIs'!W4 -> 96.58 | I15: ='Plant KPIs'!AC4 -> 95.92 | J15: ='Plant KPIs'!AI4 -> 95.82 | K15: ='Plant KPIs'!AO4 -> 94.54 | L15: ='Entity KPIs'!K4 -> 91.86 | M15: ='Entity KPIs'!Q4 -> 95.43 | N15: ='Group KPIs'!K4 -> 93.64 | O15: Same formula applied at each level to that level's inputs
A17: PLT-002 OEE (%) = Availability × Performance × Quality = Good output ÷ Ideal output × 100
A18: PLT-002 | B18: Input | C18: Good output (t) | D18: good_output_t | E18: This month | F18: ='Plant Inputs'!P9 -> 81854 | G18: ='Plant Inputs'!P15 -> 95233 | H18: ='Plant Inputs'!P21 -> 139711 | I18: ='Plant Inputs'!P27 -> 81694 | J18: ='Plant Inputs'!P33 -> 132787 | K18: ='Plant Inputs'!P39 -> 94388 | L18: ='Entity Inputs'!N9 -> 316798 | M18: ='Entity Inputs'!N15 -> 308869 | N18: ='Group Inputs'!M9 -> 625667 | O18: Sum of 3 plants → sum of 2 entities
A19: PLT-002 | B19: Input | C19: Ideal output (t) | D19: ideal_output_t | E19: This month | F19: ='Plant Inputs'!L9 -> 97478 | G19: ='Plant Inputs'!L15 -> 135441 | H19: ='Plant Inputs'!L21 -> 162063 | I19: ='Plant Inputs'!L27 -> 91042 | J19: ='Plant Inputs'!L33 -> 145550 | K19: ='Plant Inputs'!L39 -> 112638 | L19: ='Entity Inputs'!J9 -> 394982 | M19: ='Entity Inputs'!J15 -> 349230 | N19: ='Group Inputs'!I9 -> 744212 | O19: Sum of 3 plants → sum of 2 entities
A20: PLT-002 | B20: KPI result | C20: OEE | E20: Month | F20: ='Plant KPIs'!K5 -> 83.97 | G20: ='Plant KPIs'!Q5 -> 70.31 | H20: ='Plant KPIs'!W5 -> 86.21 | I20: ='Plant KPIs'!AC5 -> 89.73 | J20: ='Plant KPIs'!AI5 -> 91.23 | K20: ='Plant KPIs'!AO5 -> 83.8 | L20: ='Entity KPIs'!K5 -> 80.21 | M20: ='Entity KPIs'!Q5 -> 88.44 | N20: ='Group KPIs'!K5 -> 84.07 | O20: Same formula applied at each level to that level's inputs
A22: PLT-004 Recovery percentage (%) = Valuable content recovered ÷ Valuable content in feed × 100
A23: PLT-004 | B23: Input | C23: Valuable content recovered (t) | D23: recovered_contained_t | E23: This month | F23: ='Plant Inputs'!S9 -> 18334 | G23: ='Plant Inputs'!S15 -> 17994 | H23: ='Plant Inputs'!S21 -> 31527 | I23: ='Plant Inputs'!S27 -> 18005 | J23: ='Plant Inputs'!S33 -> 25111 | K23: ='Plant Inputs'!S39 -> 17410 | L23: ='Entity Inputs'!Q9 -> 67855 | M23: ='Entity Inputs'!Q15 -> 60526 | N23: ='Group Inputs'!P9 -> 128381 | O23: Sum of 3 plants → sum of 2 entities
A24: PLT-004 | B24: Input | C24: Valuable content in feed (t) | D24: feed_contained_t | E24: This month | F24: ='Plant Inputs'!R9 -> 19996 | G24: ='Plant Inputs'!R15 -> 20791 | H24: ='Plant Inputs'!R21 -> 36789 | I24: ='Plant Inputs'!R27 -> 20374 | J24: ='Plant Inputs'!R33 -> 28428 | K24: ='Plant Inputs'!R39 -> 20587 | L24: ='Entity Inputs'!P9 -> 77576 | M24: ='Entity Inputs'!P15 -> 69389 | N24: ='Group Inputs'!O9 -> 146965 | O24: Sum of 3 plants → sum of 2 entities
A25: PLT-004 | B25: KPI result | C25: Recovery percentage | E25: Month | F25: ='Plant KPIs'!K6 -> 91.69 | G25: ='Plant KPIs'!Q6 -> 86.55 | H25: ='Plant KPIs'!W6 -> 85.7 | I25: ='Plant KPIs'!AC6 -> 88.37 | J25: ='Plant KPIs'!AI6 -> 88.33 | K25: ='Plant KPIs'!AO6 -> 84.57 | L25: ='Entity KPIs'!K6 -> 87.47 | M25: ='Entity KPIs'!Q6 -> 87.23 | N25: ='Group KPIs'!K6 -> 87.35 | O25: Same formula applied at each level to that level's inputs
A27: PLT-005 Yield (%) = Good output ÷ Feed input × 100
A28: PLT-005 | B28: Input | C28: Good output (t) | D28: good_output_t | E28: This month | F28: ='Plant Inputs'!P9 -> 81854 | G28: ='Plant Inputs'!P15 -> 95233 | H28: ='Plant Inputs'!P21 -> 139711 | I28: ='Plant Inputs'!P27 -> 81694 | J28: ='Plant Inputs'!P33 -> 132787 | K28: ='Plant Inputs'!P39 -> 94388 | L28: ='Entity Inputs'!N9 -> 316798 | M28: ='Entity Inputs'!N15 -> 308869 | N28: ='Group Inputs'!M9 -> 625667 | O28: Sum of 3 plants → sum of 2 entities
A29: PLT-005 | B29: Input | C29: Feed input (t) | D29: feed_input_t | E29: This month | F29: ='Plant Inputs'!Q9 -> 89479 | G29: ='Plant Inputs'!Q15 -> 102279 | H29: ='Plant Inputs'!Q21 -> 154604 | I29: ='Plant Inputs'!Q27 -> 90180 | J29: ='Plant Inputs'!Q33 -> 142400 | K29: ='Plant Inputs'!Q39 -> 101633 | L29: ='Entity Inputs'!O9 -> 346362 | M29: ='Entity Inputs'!O15 -> 334213 | N29: ='Group Inputs'!N9 -> 680575 | O29: Sum of 3 plants → sum of 2 entities
A30: PLT-005 | B30: KPI result | C30: Yield | E30: Month | F30: ='Plant KPIs'!K7 -> 91.48 | G30: ='Plant KPIs'!Q7 -> 93.11 | H30: ='Plant KPIs'!W7 -> 90.37 | I30: ='Plant KPIs'!AC7 -> 90.59 | J30: ='Plant KPIs'!AI7 -> 93.25 | K30: ='Plant KPIs'!AO7 -> 92.87 | L30: ='Entity KPIs'!K7 -> 91.46 | M30: ='Entity KPIs'!Q7 -> 92.42 | N30: ='Group KPIs'!K7 -> 91.93 | O30: Same formula applied at each level to that level's inputs
A32: REL-001 MTBF (h) = Run hours ÷ Breakdowns
A33: REL-001 | B33: Input | C33: Run hours (h) | D33: run_hours | E33: This month | F33: ='Plant Inputs'!J9 -> 664.5 | G33: ='Plant Inputs'!J15 -> 624.3 | H33: ='Plant Inputs'!J21 -> 695.4 | I33: ='Plant Inputs'!J27 -> 690.6 | J33: ='Plant Inputs'!J33 -> 689.9 | K33: ='Plant Inputs'!J39 -> 680.7 | L33: ='Entity Inputs'!H9 -> 1984.2 | M33: ='Entity Inputs'!H15 -> 2061.2 | N33: ='Group Inputs'!G9 -> 4045.4 | O33: Sum of 3 plants → sum of 2 entities
A34: REL-001 | B34: Input | C34: Breakdowns (count) | D34: failures | E34: This month | F34: ='Plant Inputs'!U9 -> 4 | G34: ='Plant Inputs'!U15 -> 6 | H34: ='Plant Inputs'!U21 -> 2 | I34: ='Plant Inputs'!U27 -> 1 | J34: ='Plant Inputs'!U33 -> 1 | K34: ='Plant Inputs'!U39 -> 1 | L34: ='Entity Inputs'!S9 -> 12 | M34: ='Entity Inputs'!S15 -> 3 | N34: ='Group Inputs'!R9 -> 15 | O34: Sum of 3 plants → sum of 2 entities
A35: REL-001 | B35: KPI result | C35: MTBF | E35: Month | F35: ='Plant KPIs'!K8 -> 166.13 | G35: ='Plant KPIs'!Q8 -> 104.05 | H35: ='Plant KPIs'!W8 -> 347.7 | I35: ='Plant KPIs'!AC8 -> 690.6 | J35: ='Plant KPIs'!AI8 -> 689.9 | K35: ='Plant KPIs'!AO8 -> 680.7 | L35: ='Entity KPIs'!K8 -> 165.35 | M35: ='Entity KPIs'!Q8 -> 687.07 | N35: ='Group KPIs'!K8 -> 269.69 | O35: Same formula applied at each level to that level's inputs
A37: REL-002 Mean Time to Repair (h) = Repair hours ÷ Breakdowns
A38: REL-002 | B38: Input | C38: Repair hours (h) | D38: repair_hours | E38: This month | F38: ='Plant Inputs'!V9 -> 21.6 | G38: ='Plant Inputs'!V15 -> 68.5 | H38: ='Plant Inputs'!V21 -> 8.8 | I38: ='Plant Inputs'!V27 -> 6.8 | J38: ='Plant Inputs'!V33 -> 5.2 | K38: ='Plant Inputs'!V39 -> 6.5 | L38: ='Entity Inputs'!T9 -> 98.9 | M38: ='Entity Inputs'!T15 -> 18.5 | N38: ='Group Inputs'!S9 -> 117.4 | O38: Sum of 3 plants → sum of 2 entities
A39: REL-002 | B39: Input | C39: Breakdowns (count) | D39: failures | E39: This month | F39: ='Plant Inputs'!U9 -> 4 | G39: ='Plant Inputs'!U15 -> 6 | H39: ='Plant Inputs'!U21 -> 2 | I39: ='Plant Inputs'!U27 -> 1 | J39: ='Plant Inputs'!U33 -> 1 | K39: ='Plant Inputs'!U39 -> 1 | L39: ='Entity Inputs'!S9 -> 12 | M39: ='Entity Inputs'!S15 -> 3 | N39: ='Group Inputs'!R9 -> 15 | O39: Sum of 3 plants → sum of 2 entities
A40: REL-002 | B40: KPI result | C40: Mean Time to Repair | E40: Month | F40: ='Plant KPIs'!K9 -> 5.4 | G40: ='Plant KPIs'!Q9 -> 11.42 | H40: ='Plant KPIs'!W9 -> 4.4 | I40: ='Plant KPIs'!AC9 -> 6.8 | J40: ='Plant KPIs'!AI9 -> 5.2 | K40: ='Plant KPIs'!AO9 -> 6.5 | L40: ='Entity KPIs'!K9 -> 8.24 | M40: ='Entity KPIs'!Q9 -> 6.17 | N40: ='Group KPIs'!K9 -> 7.83 | O40: Same formula applied at each level to that level's inputs
A42: REL-003 Unplanned downtime (h) = Unplanned downtime
A43: REL-003 | B43: Input | C43: Unplanned downtime (h) | D43: unplanned_downtime_hours | E43: This month | F43: ='Plant Inputs'!K9 -> 30.2 | G43: ='Plant Inputs'!K15 -> 78.2 | H43: ='Plant Inputs'!K21 -> 12.3 | I43: ='Plant Inputs'!K27 -> 10.1 | J43: ='Plant Inputs'!K33 -> 10.2 | K43: ='Plant Inputs'!K39 -> 13.4 | L43: ='Entity Inputs'!I9 -> 120.7 | M43: ='Entity Inputs'!I15 -> 33.7 | N43: ='Group Inputs'!H9 -> 154.4 | O43: Sum of 3 plants → sum of 2 entities
A44: REL-003 | B44: KPI result | C44: Unplanned downtime | E44: Month | F44: ='Plant KPIs'!K10 -> 30.2 | G44: ='Plant KPIs'!Q10 -> 78.2 | H44: ='Plant KPIs'!W10 -> 12.3 | I44: ='Plant KPIs'!AC10 -> 10.1 | J44: ='Plant KPIs'!AI10 -> 10.2 | K44: ='Plant KPIs'!AO10 -> 13.4 | L44: ='Entity KPIs'!K10 -> 120.7 | M44: ='Entity KPIs'!Q10 -> 33.7 | N44: ='Group KPIs'!K10 -> 154.4 | O44: Same formula applied at each level to that level's inputs
A46: REL-004 Production loss from downtime (t) = Production lost to downtime
A47: REL-004 | B47: Input | C47: Production lost to downtime (t) | D47: prod_loss_downtime_t | E47: This month | F47: ='Plant Inputs'!T9 -> 4140 | G47: ='Plant Inputs'!T15 -> 14772 | H47: ='Plant Inputs'!T21 -> 2772 | I47: ='Plant Inputs'!T27 -> 1281 | J47: ='Plant Inputs'!T33 -> 2091 | K47: ='Plant Inputs'!T39 -> 2120 | L47: ='Entity Inputs'!R9 -> 21684 | M47: ='Entity Inputs'!R15 -> 5492 | N47: ='Group Inputs'!Q9 -> 27176 | O47: Sum of 3 plants → sum of 2 entities
A48: REL-004 | B48: KPI result | C48: Production loss from downtime | E48: Month | F48: ='Plant KPIs'!K11 -> 4140 | G48: ='Plant KPIs'!Q11 -> 14772 | H48: ='Plant KPIs'!W11 -> 2772 | I48: ='Plant KPIs'!AC11 -> 1281 | J48: ='Plant KPIs'!AI11 -> 2091 | K48: ='Plant KPIs'!AO11 -> 2120 | L48: ='Entity KPIs'!K11 -> 21684 | M48: ='Entity KPIs'!Q11 -> 5492 | N48: ='Group KPIs'!K11 -> 27176 | O48: Same formula applied at each level to that level's inputs
A50: REL-005 Preventive-maintenance compliance (%) = Preventive maintenance completed ÷ Preventive maintenance scheduled × 100
...

Sheet Screen Values
A1: Lens | B1: Screen | C1: Screen title | D1: Element | E1: Label on the screen | F1: KPI ID | G1: Scope | H1: Shown on the screen | I1: Calculated, Sep 2026 (P06) | J1: Same or different
A2: Owner | B2: G-08 · Owner depth | C2: Trust Summary (Owner depth) | D2: Card | E2: Leadership KPIs affected by findings | F2: GOV-007 | G2: Group | H2: 1 | I2: ='Group KPIs'!K119 -> 1 | J2: Same
A3: Owner | B3: G-08 · Owner depth | C3: Trust Summary (Owner depth) | D3: Card | E3: Certified KPI percentage | F3: TRU-001 | G3: Group | H3: 84 % of leadership KPIs | I3: ='Group KPIs'!K125 -> 83.93 | J3: Same
A4: Owner | B4: G-08 · Owner depth | C4: Trust Summary (Owner depth) | D4: Card | E4: Uncertified KPI count | F4: TRU-002 | G4: Group | H4: 9 | I4: ='Group KPIs'!K126 -> 9 | J4: Same
A5: Owner | B5: G-08 · Owner depth | C5: Trust Summary (Owner depth) | D5: Card | E5: Material reconciliation breaks | F5: TRU-007 | G5: Group | H5: 1 | I5: ='Group KPIs'!K122 -> 1 | J5: Same
A6: Owner | B6: G-08 · Owner depth | C6: Trust Summary (Owner depth) | D6: Card | E6: Flash-to-Close variance (P06) | F6: TRU-010 | G6: Group | H6: 0.6 % | I6: ='Group KPIs'!K130 -> 0.38 | J6: Different
A7: Owner | B7: G-08 · Owner depth | C7: Trust Summary (Owner depth) | D7: Card | E7: Variance against Board numbers | F7: TRU-011 | G7: Group | H7: 0.3 % (max abs) | I7: ='Group KPIs'!K132 -> 0.27 | J7: Same
A8: Owner | B8: G-08 · Owner depth | C8: Trust Summary (Owner depth) | D8: Table | E8: Ageing certification approvals | F8: GOV-001 | G8: Group | H8: 2 > [PH] d | I8: ='Group KPIs'!K113 -> 2 | J8: Same
A9: Owner | B9: G-08 · Owner depth | C9: Trust Summary (Owner depth) | D9: Table | E9: Override count (KPI) | F9: GOV-002 | G9: Group | H9: 0 | I9: ='Group KPIs'!K114 -> 0 | J9: Same
A10: Owner | B10: G-08 · Owner depth | C10: Trust Summary (Owner depth) | D10: Table | E10: Recurring data-quality issues | F10: GOV-003 | G10: Group | H10: 1 | I10: ='Group KPIs'!K115 -> 1 | J10: Same
A11: Owner | B11: G-08 · Owner depth | C11: Trust Summary (Owner depth) | D11: Table | E11: Open audit findings | F11: GOV-004 | G11: Group | H11: 7 | I11: ='Group KPIs'!K116 -> 7 | J11: Same
A12: Owner | B12: G-08 · Owner depth | C12: Trust Summary (Owner depth) | D12: Table | E12: Overdue assurance actions | F12: GOV-005 | G12: Group | H12: 0 | I12: ='Group KPIs'!K117 -> 0 | J12: Same
A13: Owner | B13: G-08 · Owner depth | C13: Trust Summary (Owner depth) | D13: Table | E13: Repeat findings | F13: GOV-006 | G13: Group | H13: 1 | I13: ='Group KPIs'!K118 -> 1 | J13: Same
A14: Owner | B14: G-08 · Owner depth | C14: Trust Summary (Owner depth) | D14: Table | E14: Leadership KPIs affected by findings | F14: GOV-007 | G14: Group | H14: 1 | I14: ='Group KPIs'!K119 -> 1 | J14: Same
A15: Owner | B15: G-08 · Owner depth | C15: Trust Summary (Owner depth) | D15: Table | E15: Evidence completeness rate | F15: GOV-008 | G15: Group | H15: 88% | I15: ='Group KPIs'!K123 -> 87.96 | J15: Same
A16: Owner | B16: G-08 · Owner depth | C16: Trust Summary (Owner depth) | D16: Table | E16: Average finding-closure time | F16: GOV-009 | G16: Group | H16: 34 d | I16: ='Group KPIs'!K124 -> 32.81 | J16: Different
A17: Owner | B17: G-08 · Owner depth | C17: Trust Summary (Owner depth) | D17: Table | E17: KPI certification coverage | F17: TRU-001 | G17: Group | H17: 84 % of leadership KPIs | I17: ='Group KPIs'!K125 -> 83.93 | J17: Same
A18: Owner | B18: G-08 · Owner depth | C18: Trust Summary (Owner depth) | D18: Table | E18: Source-to-Lake reconciliation rate | F18: TRU-008 | G18: Group | H18: 99.2% | I18: ='Group KPIs'!K128 -> 99.02 | J18: Different
A19: Owner | B19: G-08 · Owner depth | C19: Trust Summary (Owner depth) | D19: Table | E19: Flash-to-MIS reconciliation rate | F19: TRU-009 | G19: Group | H19: 96.8% | I19: ='Group KPIs'!K129 -> 95.98 | J19: Different
A20: Owner | B20: G-08 · Owner depth | C20: Trust Summary (Owner depth) | D20: Table | E20: Flash-to-Close variance (P06) | F20: TRU-010 | G20: Group | H20: 0.6 % | I20: ='Group KPIs'!K130 -> 0.38 | J20: Different
A21: Owner | B21: G-08 · Owner depth | C21: Trust Summary (Owner depth) | D21: Table | E21: Variance against Board numbers | F21: TRU-011 | G21: Group | H21: 0.3% max abs · Entity B2 | I21: ='Group KPIs'!K132 -> 0.27 | J21: Same
A22: Owner | B22: O-01 | C22: Enterprise Health | D22: Card | E22: Capex physical progress | F22: CPX-004 | G22: Group | H22: 61 % weighted | I22: ='Group KPIs'!K69 -> 60.85 | J22: Same
A23: Owner | B23: O-01 | C23: Enterprise Health | D23: Card | E23: Open critical alerts | F23: EFF-002 | G23: Group | H23: 1 alert | I23: ='Group KPIs'!K133 -> 1 | J23: Same
A24: Owner | B24: O-01 | C24: Enterprise Health | D24: Card | E24: EBITDA YTD (to P06) | F24: FIN-001 | G24: Group | H24: 361.3 ₹ m | I24: ='Group KPIs'!K38 -> 1760.09 | J24: Different
A25: Owner | B25: O-01 | C25: Enterprise Health | D25: Card | E25: EBIT YTD (to P06) | F25: FIN-002 | G25: Group | H25: 238.4 ₹ m | I25: ='Group KPIs'!K39 -> 1228.14 | J25: Different
A26: Owner | B26: O-01 | C26: Enterprise Health | D26: Card | E26: Free Cash Flow YTD | F26: FIN-004 | G26: Group | H26: 96.4 ₹ m | I26: ='Group KPIs'!K41 -> 606.18 | J26: Different
A27: Owner | B27: O-01 | C27: Enterprise Health | D27: Card | E27: ROCE · rolling 12 m | F27: FIN-005 | G27: Group | H27: 11.8 % | I27: ='Group KPIs'!K42 -> 11.58 | J27: Different
A28: Owner | B28: O-01 | C28: Enterprise Health | D28: Card | E28: Net Debt | F28: FIN-006 | G28: Group | H28: 1,140 ₹ m | I28: ='Group KPIs'!K43 -> 6650 | J28: Different
A29: Owner | B29: O-01 | C29: Enterprise Health | D29: Card | E29: Production vs plan · Group MTD | F29: OPS-001 | G29: Group | H29: 98.1 % of plan | I29: ='Group KPIs'!K2 -> 95.51 | J29: Different
A30: Owner | B30: O-01 | C30: Enterprise Health | D30: Tile | E30: Days to breach · Plant 02 plan | F30: PRD-001 | G30: Plant 02 | H30: 4 days | I30: ='Plant KPIs'!Q59 -> 4 | J30: Same
A31: Owner | B31: O-01 | C31: Enterprise Health | D31: Tile | E31: Probability of plan miss · P07 | F31: PRD-002 | G31: Group | H31: 64% | I31: ='Group KPIs'!K145 -> 69.69 | J31: Different
A32: Owner | B32: O-01 | C32: Enterprise Health | D32: Tile | E32: Projected EBITDA gap · P07–P12 | F32: PRD-003 | G32: Group | H32: −₹9.2 m | I32: ='Group KPIs'!K146 -> -56.18 | J32: Different
A33: Owner | B33: O-01 | C33: Enterprise Health | D33: Table | E33: Regulatory breaches · YTD | F33: CMP-005 | G33: Group | H33: 0 | I33: ='Group KPIs'!K101 -> 0 | J33: Same
A34: Owner | B34: O-01 | C34: Enterprise Health | D34: Table | E34: EBIT YTD | F34: FIN-002 | G34: Group | H34: 238.4 ₹ m | I34: ='Group KPIs'!K39 -> 1228.14 | J34: Different
A35: Owner | B35: O-01 | C35: Enterprise Health | D35: Table | E35: Revenue YTD | F35: FIN-003 | G35: Group | H35: 2,410 ₹ m | I35: ='Group KPIs'!K40 -> 13811.3 | J35: Different
A36: Owner | B36: O-01 | C36: Enterprise Health | D36: Table | E36: ROCE (rolling 12 m) | F36: FIN-005 | G36: Group | H36: 11.8% | I36: ='Group KPIs'!K42 -> 11.58 | J36: Different
A37: Owner | B37: O-01 | C37: Enterprise Health | D37: Table | E37: Shareholder-value indicator | F37: FIN-007 | G37: Group | H37: [PLACEHOLDER] | I37: ='Group KPIs'!K44 -> -86.65 | J37: Different
A38: Owner | B38: O-01 | C38: Enterprise Health | D38: Table | E38: Sales vs plan · MTD | F38: OPS-002 | G38: Group | H38: 97.6% | I38: ='Group KPIs'!K35 -> 95.23 | J38: Different
A39: Owner | B39: O-01 | C39: Enterprise Health | D39: Table | E39: Capacity utilization | F39: OPS-003 | G39: Group | H39: 86% | I39: ='Group KPIs'!K3 -> 83.44 | J39: Different
A40: Owner | B40: O-01 | C40: Enterprise Health | D40: Table | E40: Sales vs plan · Group MTD | F40: OPS-004 | G40: Group | H40: 97.6% | I40: ='Group KPIs'!K36 -> 95.23 | J40: Different
...

Sheet Group KPIs
A1: KPI ID | B1: Measure | C1: Unit | D1: Time basis | E1: How it is calculated | F1: 2026-04 (P01) | G1: 2026-05 (P02) | H1: 2026-06 (P03) | I1: 2026-07 (P04) | J1: 2026-08 (P05) | K1: 2026-09 (P06)
